Workbook

Sheet SCPR2022
A2: SIDLAK CHRISTIAN CHILDREN FUND SAVINGS AND CREDIT COOPERATIVE
A3: CDA Registration No. 9520-1080000000036399 Dated: November 16, 2016
A4: P-2, Brgy. Linao, Ormoc City
A6: COMPUTATION OF SHARES AND PATRONAGE REFUND
A7: As of FY 2023
A9: Members | C9: From 2022 | D9: Jan | E9: Feb | F9: Mar | G9: Apr | H9: May | I9: Jun | J9: Jul | K9: Aug | L9: Sep | M9: Oct | N9: Nov | O9: Dec | P9: TSM | Q9: ASM | R9: IOSC | S9: Int. on Loans | T9: Patronage Refund | U9: Total (IOSC+PR) | V9: Signature
A11: 1 | B11: Allen L. Gubalane | C11: =2154.73+13.01 -> 2167.74 | P11: =C11+D11+E11+F11+G11+H11+I11+J11+K11+L11+M11+N11+O11 -> 2167.74 | Q11: =P11/12 -> 180.645
A12: 2 | B12: April A. Hubahib | C12: 1300 | P12: =C12+D12+E12+F12+G12+H12+I12+J12+K12+L12+M12+N12+O12 -> 1300 | Q12: =P12/12 -> 108.33333
A13: 3 | B13: Arnold C. Gonzales | C13: =2238.34+13.51 -> 2251.85 | P13: =C13+D13+E13+F13+G13+H13+I13+J13+K13+L13+M13+N13+O13 -> 2251.85 | Q13: =P13/12 -> 187.65417
A14: 4 | B14: Elina Empimo | C14: 750 | P14: =C14+D14+E14+F14+G14+H14+I14+J14+K14+L14+M14+N14+O14 -> 750 | Q14: =P14/12 -> 62.5
A15: 5 | B15: Crisencia R. Ruiz | C15: 7000 | P15: =C15+D15+E15+F15+G15+H15+I15+J15+K15+L15+M15+N15+O15 -> 7000 | Q15: =P15/12 -> 583.33333
A16: 6 | B16: Dennis M. Tolibao | C16: 150 | P16: =C16+D16+E16+F16+G16+H16+I16+J16+K16+L16+M16+N16+O16 -> 150 | Q16: =P16/12 -> 12.5
A17: 7 | B17: Dexter B. Jumao-as | C17: 7000 | P17: =C17+D17+E17+F17+G17+H17+I17+J17+K17+L17+M17+N17+O17 -> 7000 | Q17: =P17/12 -> 583.33333
A18: 8 | B18: Dorotea Jumao-as | C18: 7000 | P18: =C18+D18+E18+F18+G18+H18+I18+#REF!+J18+L18+M18+N18+O18 -> #REF! | Q18: =P18/12 -> #REF!
A19: 9 | B19: Edgardo P. Nodalo | C19: =2021.27+12.03 -> 2033.3 | P19: =C19+D19+E19+F19+G19+H19+I19+J19+K19+L19+M19+N19+O19 -> 2033.3 | Q19: =P19/12 -> 169.44167
A20: 10 | B20: Eloisa E. Williams | C20: =2728.71+16.24 -> 2744.95 | P20: =C20+D20+E20+F20+G20+H20+I20+J20+K20+L20+M20+N20+O20 -> 2744.95 | Q20: =P20/12 -> 228.74583
A21: 11 | B21: Emmanuel C. Orellano | C21: 700 | P21: =C21+D21+E21+F21+G21+H21+I21+J21+K21+L21+M21+N21+O21 -> 700 | Q21: =P21/12 -> 58.333333
A22: 12 | B22: Emmanuel S. Quilantang | C22: =2081.27+12.39 -> 2093.66 | P22: =C22+D22+E22+F22+G22+H22+I22+J22+K22+L22+M22+N22+O22 -> 2093.66 | Q22: =P22/12 -> 174.47167
A23: 13 | B23: Erlinda E. Quilantang | C23: =2122.33+12.63 -> 2134.96 | P23: =C23+D23+E23+F23+G23+H23+I23+J23+K23+L23+M23+N23+O23 -> 2134.96 | Q23: =P23/12 -> 177.91333
A24: 14 | B24: Eunicelle S. Samson | C24: =5560+33.09 -> 5593.09 | P24: =C24+D24+E24+F24+G24+H24+I24+J24+K24+L24+M24+N24+O24 -> 5593.09 | Q24: =P24/12 -> 466.09083
A25: 15 | B25: Genelyn N. Ymas | C25: 150 | P25: =C25+D25+E25+F25+G25+H25+I25+J25+K25+L25+M25+N25+O25 -> 150 | Q25: =P25/12 -> 12.5
A26: 16 | B26: Junel A. Pagay | C26: 1200 | P26: =C26+D26+E26+F26+G26+H26+I26+J26+K26+L26+M26+N26+O26 -> 1200 | Q26: =P26/12 -> 100
A27: 17 | B27: Limuel P. Omega | C27: 200 | P27: =C27+D27+E27+F27+G27+H27+I27+J27+K27+L27+M27+N27+O27 -> 200 | Q27: =P27/12 -> 16.666667
A28: 18 | B28: Ma. Ella P. Solano | C28: =2420+14.4 -> 2434.4 | P28: =C28+D28+E28+F28+G28+H28+I28+J28+K28+L28+M28+N28+O28 -> 2434.4 | Q28: =P28/12 -> 202.86667
A29: 19 | B29: Maria Genia C. Seguido | C29: 7000 | P29: =C29+D29+E29+F29+G29+H29+I29+J29+K29+L29+M29+N29+O29 -> 7000 | Q29: =P29/12 -> 583.33333
A30: 20 | B30: Mario G. Bañez Jr. | C30: 1300 | P30: =C30+D30+E30+F30+G30+H30+I30+J30+K30+L30+M30+N30+O30 -> 1300 | Q30: =P30/12 -> 108.33333
A31: 21 | B31: Marissa B. Ligutan | C31: 750 | P31: =C31+D31+E31+F31+G31+H31+I31+J31+K31+L31+M31+N31+O31 -> 750 | Q31: =P31/12 -> 62.5
A32: 22 | B32: Maristela A. Mandras | C32: 1200 | P32: =C32+D32+E32+F32+G32+H32+I32+J32+K32+L32+M32+N32+O32 -> 1200 | Q32: =P32/12 -> 100
A33: 23 | B33: Mark Gil M. Catingub | C33: 100 | P33: =C33+D33+E33+F33+G33+H33+I33+J33+K33+L33+M33+N33+O33 -> 100 | Q33: =P33/12 -> 8.3333333
A34: 24 | B34: Mary Grace C. Perol | C34: =2009+11.96 -> 2020.96 | P34: =C34+D34+E34+F34+G34+H34+I34+J34+K34+L34+M34+N34+O34 -> 2020.96 | Q34: =P34/12 -> 168.41333
A35: 25 | B35: Maricris Montemor | C35: 600 | P35: =C35+D35+E35+F35+G35+H35+I35+J35+K35+L35+M35+N35+O35 -> 600 | Q35: =P35/12 -> 50
A36: 26 | B36: Analyn Cabahug | C36: =2885+17.17 -> 2902.17 | P36: =C36+D36+E36+F36+G36+H36+I36+J36+K36+L36+M36+N36+O36 -> 2902.17 | Q36: =P36/12 -> 241.8475
A37: 27 | B37: Nenita S. Fay | C37: =2120+12.62 -> 2132.62 | P37: =C37+D37+E37+F37+G37+H37+I37+J37+K37+L37+M37+N37+O37 -> 2132.62 | Q37: =P37/12 -> 177.71833
A38: 28 | B38: Paul C. Espinosa | C38: =2581.27+102.65 -> 2683.92 | P38: =C38+D38+E38+F38+G38+H38+I38+J38+K38+L38+M38+N38+O38 -> 2683.92 | Q38: =P38/12 -> 223.66
P40: =SUM(P11:P39) -> #REF! | U40: Page 1 of 4
A42: SIDLAK CHRISTIAN CHILDREN FUND SAVINGS AND CREDIT COOPERATIVE
A43: CDA Registration No. 9520-1080000000036399 Dated: November 16, 2016
A44: P-2, Brgy. Linao, Ormoc City
A46: COMPUTATION OF SHARES AND PATRONAGE REFUND
A47: As of FY 2022
...

Sheet SCPR2023
A2: SIDLAK CHRISTIAN CHILDREN FUND SAVINGS AND CREDIT COOPERATIVE
A3: CDA Registration No. 9520-1080000000036399 Dated: November 16, 2016
A4: P-2, Brgy. Linao, Ormoc City
A6: COMPUTATION OF SHARES AND PATRONAGE REFUND
A7: As of FY 2022
A9: Members | C9: From 2021 | D9: Jan | E9: Feb | G9: Mar | H9: Apr | I9: May | J9: Jun | K9: Jul | M9: Aug | N9: Sep | O9: Oct | P9: Nov | Q9: Dec | R9: TSM | S9: ASM | T9: IOSC | U9: Int. on Loans | V9: Patronage Refund | W9: Total (IOSC+PR) | X9: Signature
F10: withdrawal
A11: 1 | B11: Allen L. Gubalane | C11: =2154.73+13.01 -> 2167.74 | R11: =C11+D11+E11+G11+H11+I11+J11+K11+M11+N11+O11+P11+Q11 -> 2167.74 | S11: =R11/12 -> 180.645
A12: 2 | B12: April A. Hubahib | C12: 1300 | R12: =C12+D12+E12+G12+H12+I12+J12+K12+M12+N12+O12+P12+Q12 -> 1300 | S12: =R12/12 -> 108.33333
A13: 3 | B13: Arnold C. Gonzales | C13: =2238.34+13.51 -> 2251.85 | R13: =C13+D13+E13+G13+H13+I13+J13+K13+M13+N13+O13+P13+Q13 -> 2251.85 | S13: =R13/12 -> 187.65417
A14: 4 | B14: Elina Empimo | C14: 750 | R14: =C14+D14+E14+G14+H14+I14+J14+K14+M14+N14+O14+P14+Q14 -> 750 | S14: =R14/12 -> 62.5
A15: 5 | B15: Crisencia R. Ruiz | C15: 7000 | R15: =C15+D15+E15+G15+H15+I15+J15+K15+M15+N15+O15+P15+Q15 -> 7000 | S15: =R15/12 -> 583.33333
A16: 6 | B16: Dennis M. Tolibao | C16: 150 | R16: =C16+D16+E16+G16+H16+I16+J16+K16+M16+N16+O16+P16+Q16 -> 150 | S16: =R16/12 -> 12.5
A17: 7 | B17: Dexter B. Jumao-as | C17: 7000 | R17: =C17+D17+E17+G17+H17+I17+J17+K17+M17+N17+O17+P17+Q17 -> 7000 | S17: =R17/12 -> 583.33333
A18: 8 | B18: Dorotea Jumao-as | C18: 7000 | R18: =C18+D18+E18+G18+H18+I18+J18+K18+M18+N18+O18+P18+Q18 -> 7000 | S18: =R18/12 -> 583.33333
A19: 9 | B19: Edgardo P. Nodalo | C19: =2033.3+12.27 -> 2045.57 | R19: =C19+D19+E19+G19+H19+I19+J19+K19+M19+N19+O19+P19+Q19 -> 2045.57 | S19: =R19/12 -> 170.46417
A20: 10 | B20: Eloisa E. Williams | C20: =2744.95+16.57 -> 2761.52 | R20: =C20+D20+E20+G20+H20+I20+J20+K20+M20+N20+O20+P20+Q20 -> 2761.52 | S20: =R20/12 -> 230.12667
A21: 11 | B21: Emmanuel C. Orellano | C21: 700 | R21: =C21+D21+E21+G21+H21+I21+J21+K21+M21+N21+O21+P21+Q21 -> 700 | S21: =R21/12 -> 58.333333
A22: 12 | B22: Emmanuel S. Quilantang | C22: =2093.66+12.64 -> 2106.3 | R22: =C22+D22+E22+G22+H22+I22+J22+K22+M22+N22+O22+P22+Q22 -> 2106.3 | S22: =R22/12 -> 175.525
A23: 13 | B23: Erlinda E. Quilantang | C23: =2134.96+12.89 -> 2147.85 | R23: =C23+D23+E23+G23+H23+I23+J23+K23+M23+N23+O23+P23+Q23 -> 2147.85 | S23: =R23/12 -> 178.9875
A24: 14 | B24: Eunicelle S. Samson | C24: =5593.09+33.76 -> 5626.85 | R24: =C24+D24+E24+G24+H24+I24+J24+K24+M24+N24+O24+P24+Q24 -> 5626.85 | S24: =R24/12 -> 468.90417
A25: 15 | B25: Genelyn N. Ymas | C25: 150 | R25: =C25+D25+E25+G25+H25+I25+J25+K25+M25+N25+O25+P25+Q25 -> 150 | S25: =R25/12 -> 12.5
A26: 16 | B26: Junel A. Pagay | C26: 1200 | R26: =C26+D26+E26+G26+H26+I26+J26+K26+M26+N26+O26+P26+Q26 -> 1200 | S26: =R26/12 -> 100
A27: 17 | B27: Limuel P. Omega | C27: 200 | R27: =C27+D27+E27+G27+H27+I27+J27+K27+M27+N27+O27+P27+Q27 -> 200 | S27: =R27/12 -> 16.666667
A28: 18 | B28: Ma. Ella P. Solano | C28: =2420+14.4+14.7 -> 2449.1 | R28: =C28+D28+E28+G28+H28+I28+J28+K28+M28+N28+O28+P28+Q28 -> 2449.1 | S28: =R28/12 -> 204.09167
A29: 19 | B29: Maria Genia C. Seguido | C29: 7000 | R29: =C29+D29+E29+G29+H29+I29+J29+K29+M29+N29+O29+P29+Q29 -> 7000 | S29: =R29/12 -> 583.33333
A30: 20 | B30: Mario G. Bañez Jr. | C30: 1300 | R30: =C30+D30+E30+G30+H30+I30+J30+K30+M30+N30+O30+P30+Q30 -> 1300 | S30: =R30/12 -> 108.33333
A31: 21 | B31: Marissa B. Ligutan | C31: 750 | R31: =C31+D31+E31+G31+H31+I31+J31+K31+M31+N31+O31+P31+Q31 -> 750 | S31: =R31/12 -> 62.5
A32: 22 | B32: Maristela A. Mandras | C32: 1200 | R32: =C32+D32+E32+G32+H32+I32+J32+K32+M32+N32+O32+P32+Q32 -> 1200 | S32: =R32/12 -> 100
A33: 23 | B33: Mark Gil M. Catingub | C33: 100 | R33: =C33+D33+E33+G33+H33+I33+J33+K33+M33+N33+O33+P33+Q33 -> 100 | S33: =R33/12 -> 8.3333333
A34: 24 | B34: Mary Grace C. Perol | C34: =2020.96+12.2 -> 2033.16 | R34: =C34+D34+E34+G34+H34+I34+J34+K34+M34+N34+O34+P34+Q34 -> 2033.16 | S34: =R34/12 -> 169.43
A35: 25 | B35: Maricris Montemor | C35: 600 | R35: =C35+D35+E35+G35+H35+I35+J35+K35+M35+N35+O35+P35+Q35 -> 600 | S35: =R35/12 -> 50
A36: 26 | B36: Analyn Cabahug | C36: =2902.17+17.52 -> 2919.69 | R36: =C36+D36+E36+G36+H36+I36+J36+K36+M36+N36+O36+P36+Q36 -> 2919.69 | S36: =R36/12 -> 243.3075
A37: 27 | B37: Nenita S. Fay | C37: =2132.62+12.87 -> 2145.49 | R37: =C37+D37+E37+G37+H37+I37+J37+K37+M37+N37+O37+P37+Q37 -> 2145.49 | S37: =R37/12 -> 178.79083
A38: 28 | B38: Paul C. Espinosa | C38: =2683.92+16.2 -> 2700.12 | R38: =C38+D38+E38+G38+H38+I38+J38+K38+M38+N38+O38+P38+Q38 -> 2700.12 | S38: =R38/12 -> 225.01
R40: =SUM(R11:R39) -> 67755.24 | W40: Page 1 of 4
A42: SIDLAK CHRISTIAN CHILDREN FUND SAVINGS AND CREDIT COOPERATIVE
A43: CDA Registration No. 9520-1080000000036399 Dated: November 16, 2016
A44: P-2, Brgy. Linao, Ormoc City
A46: COMPUTATION OF SHARES AND PATRONAGE REFUND
...

Sheet SCPR2025
B2: SIDLAK CHRISTIAN CHILDREN FUND SAVINGS AND CREDIT COOPERATIVE
B3: CDA Registration No. 9520-1080000000036399 Dated: November 16, 2016
B4: P-2, Brgy. Linao, Ormoc City
B6: COMPUTATION OF SHARES AND PATRONAGE REFUND
B7: As of FY 2025
B9: Members | D9: Account No. | E9: From 2024 | F9: Jan | G9: Feb | H9: Mar | I9: Apr | J9: May | K9: Jun | L9: Jul | M9: Aug | N9: Sept | O9: Oct | P9: Nov | Q9: Dec | R9: TSM | S9: ASM | T9: IOSC | U9: Int. on Loans | V9: Patronage Refund | W9: Total (IOSC+PR) | X9: Signature
B12: 1 | C12: Allen L. Gubalane | D12: ='[2]2025'!$D$5 -> AN-16-0001 | E12: =2163.78+16.47+2.4 -> 2182.65 | R12: =E12+F12+G12+H12+I12+J12+K12+L12+M12+N12+O12+P12+Q12 -> 2182.65 | S12: =R12/12 -> 181.8875 | W12: =T12+V12 -> 0
B13: 2 | C13: April A. Hubahib | D13: ='[2]2025'!$D$6 -> AN-16-0002 | E13: 1300 | R13: =E13+F13+G13+H13+I13+J13+K13+L13+M13+N13+O13+P13+Q13 -> 1300 | S13: =R13/12 -> 108.33333 | W13: =T13+V13 -> 0
B14: 3 | C14: Arnold C. Gonzales | D14: ='[2]2025'!$D$7 -> AN-16-0003 | E14: =2247.74+17.11+2.49 -> 2267.34 | R14: =E14+F14+G14+H14+I14+J14+K14+L14+M14+N14+O14+P14+Q14 -> 2267.34 | S14: =R14/12 -> 188.945 | W14: =T14+V14 -> 0
B15: 4 | C15: Elina Empimo | D15: ='[2]2025'!$D$8 -> AN-16-0004 | E15: 750 | R15: =E15+F15+G15+H15+I15+J15+K15+L15+M15+N15+O15+P15+Q15 -> 750 | S15: =R15/12 -> 62.5 | W15: =T15+V15 -> 0
B16: 5 | C16: Crisencia R. Ruiz | D16: ='[2]2025'!$D$9 -> AN-16-0005 | E16: =7.75+7053.28 -> 7061.03 | R16: =E16+F16+G16+H16+I16+J16+K16+L16+M16+N16+O16+P16+Q16 -> 7061.03 | S16: =R16/12 -> 588.41917 | W16: =T16+V16 -> 0
B17: 6 | C17: Dennis M. Tolibao | D17: ='[2]2025'!$D$10 -> AN-16-0006 | E17: 150 | R17: =E17+F17+G17+H17+I17+J17+K17+L17+M17+N17+O17+P17+Q17 -> 150 | S17: =R17/12 -> 12.5 | W17: =T17+V17 -> 0
B18: 7 | C18: Dexter B. Jumao-as | D18: ='[2]2025'!$D$11 -> AN-16-0007 | E18: =7455.7+45.01 -> 7500.71 | R18: =E18+F18+G18+H18+I18+J18+K18+L18+M18+N18+O18+P18+Q18 -> 7500.71 | S18: =R18/12 -> 625.05917 | W18: =T18+V18 -> 0
B19: 8 | C19: Dorotea Jumao-as | D19: ='[2]2025'!$D$12 -> AN-16-0008 | E19: =8133.18+31.95 -> 8165.13 | F19: 0 | R19: =E19+F19+G19+H19+I19+J19+K19+L19+M19+N19+O19+P19+Q19 -> 8165.13 | S19: =R19/12 -> 680.4275 | W19: =T19+V19 -> 0
B20: 9 | C20: Edgardo P. Nodalo | D20: ='[2]2025'!$D$13 -> AN-16-0009 | E20: =15.54+2041.84+2.26 -> 2059.64 | R20: =E20+F20+G20+H20+I20+J20+K20+L20+M20+N20+O20+P20+Q20 -> 2059.64 | S20: =R20/12 -> 171.63667 | W20: =T20+V20 -> 0
B21: 10 | C21: Eloisa E. Williams | D21: ='[2]2025'!$D$14 -> AN-16-0010 | E21: =128.45+2756.48+3.17 -> 2888.1 | R21: =E21+F21+G21+H21+I21+J21+K21+L21+M21+N21+O21+P21+Q21 -> 2888.1 | S21: =R21/12 -> 240.675 | W21: =T21+V21 -> 0
B22: 11 | C22: Emmanuel C. Orellano | D22: ='[2]2025'!$D$15 -> AN-16-0011 | E22: 700 | R22: =E22+F22+G22+H22+I22+J22+K22+L22+M22+N22+O22+P22+Q22 -> 700 | S22: =R22/12 -> 58.333333 | W22: =T22+V22 -> 0
B23: 12 | C23: Emmanuel S. Quilantang | D23: ='[2]2025'!$D$16 -> AN-16-0012 | E23: =16+2102.46+2.33 -> 2120.79 | R23: =E23+F23+G23+H23+I23+J23+K23+L23+M23+N23+O23+P23+Q23 -> 2120.79 | S23: =R23/12 -> 176.7325 | W23: =T23+V23 -> 0
B24: 13 | C24: Erlinda E. Quilantang | D24: ='[2]2025'!$D$17 -> AN-16-0013 | E24: =16.32+2143.93+2.37 -> 2162.62 | R24: =E24+F24+G24+H24+I24+J24+K24+L24+M24+N24+O24+P24+Q24 -> 2162.62 | S24: =R24/12 -> 180.21833 | W24: =T24+V24 -> 0
B25: 14 | C25: Eunicelle S. Samson | D25: ='[2]2025'!$D$18 -> AN-16-0014 | E25: =42.75+5616.59+6.22 -> 5665.56 | R25: =E25+F25+G25+H25+I25+J25+K25+L25+M25+N25+O25+P25+Q25 -> 5665.56 | S25: =R25/12 -> 472.13 | W25: =T25+V25 -> 0
B26: 15 | C26: Genelyn N. Ymas | D26: ='[2]2025'!$D$19 -> AN-16-0015 | E26: 150 | R26: =E26+F26+G26+H26+I26+J26+K26+L26+M26+N26+O26+P26+Q26 -> 150 | S26: =R26/12 -> 12.5 | W26: =T26+V26 -> 0
B27: 16 | C27: Junel A. Pagay | D27: ='[2]2025'!$D$20 -> AN-16-0016 | E27: 1200 | R27: =E27+F27+G27+H27+I27+J27+K27+L27+M27+N27+O27+P27+Q27 -> 1200 | S27: =R27/12 -> 100 | W27: =T27+V27 -> 0
B28: 17 | C28: Limuel P. Omega | D28: ='[2]2025'!$D$21 -> AN-16-0017 | E28: 200 | R28: =E28+F28+G28+H28+I28+J28+K28+L28+M28+N28+O28+P28+Q28 -> 200 | S28: =R28/12 -> 16.666667 | W28: =T28+V28 -> 0
B29: 18 | C29: Ma. Ella P. Solano | D29: ='[2]2025'!$D$22 -> AN-16-0018 | E29: =18.61+2444.63+2.71 -> 2465.95 | R29: =E29+F29+G29+H29+I29+J29+K29+L29+M29+N29+O29+P29+Q29 -> 2465.95 | S29: =R29/12 -> 205.49583 | W29: =T29+V29 -> 0
B30: 19 | C30: Maria Genia C. Seguido | D30: ='[2]2025'!$D$23 -> AN-16-0019 | E30: =160.76+7000+12.51 -> 7173.27 | R30: =E30+F30+G30+H30+I30+J30+K30+L30+M30+N30+O30+P30+Q30 -> 7173.27 | S30: =R30/12 -> 597.7725 | W30: =T30+V30 -> 0
B31: 20 | C31: Mario G. Bañez Jr. | D31: ='[2]2025'!$D$24 -> AN-16-0020 | E31: 1300 | R31: =E31+F31+G31+H31+I31+J31+K31+L31+M31+N31+O31+P31+Q31 -> 1300 | S31: =R31/12 -> 108.33333 | W31: =T31+V31 -> 0
B32: 21 | C32: Marissa B. Ligutan | D32: ='[2]2025'!$D$25 -> AN-16-0021 | E32: 750 | R32: =E32+F32+G32+H32+I32+J32+K32+L32+M32+N32+O32+P32+Q32 -> 750 | S32: =R32/12 -> 62.5 | W32: =T32+V32 -> 0
B33: 22 | C33: Maristela A. Mandras | D33: ='[2]2025'!$D$26 -> AN-16-0022 | E33: 1200 | R33: =E33+F33+G33+H33+I33+J33+K33+L33+M33+N33+O33+P33+Q33 -> 1200 | S33: =R33/12 -> 100 | W33: =T33+V33 -> 0
B34: 23 | C34: Mark Gil M. Catingub | D34: ='[2]2025'!$D$27 -> AN-16-0023 | E34: 100 | R34: =E34+F34+G34+H34+I34+J34+K34+L34+M34+N34+O34+P34+Q34 -> 100 | S34: =R34/12 -> 8.3333333 | W34: =T34+V34 -> 0
B35: 24 | C35: Mary Grace C. Perol | D35: ='[2]2025'!$D$28 -> AN-16-0024 | E35: =15.45+2029.45+2.25 -> 2047.15 | R35: =E35+F35+G35+H35+I35+J35+K35+L35+M35+N35+O35+P35+Q35 -> 2047.15 | S35: =R35/12 -> 170.59583 | W35: =T35+V35 -> 0
B36: 25 | C36: Maricris Montemor | D36: ='[2]2025'!$D$29 -> AN-16-0025 | E36: 600 | R36: =E36+F36+G36+H36+I36+J36+K36+L36+M36+N36+O36+P36+Q36 -> 600 | S36: =R36/12 -> 50 | W36: =T36+V36 -> 0
B37: 26 | C37: Analyn Cabahug | D37: ='[2]2025'!$D$30 -> AN-16-0026 | E37: =22.18+2914.36+3.23 -> 2939.77 | R37: =E37+F37+G37+H37+I37+J37+K37+L37+M37+N37+O37+P37+Q37 -> 2939.77 | S37: =R37/12 -> 244.98083 | W37: =T37+V37 -> 0
B38: 27 | C38: Nenita S. Fay | D38: ='[2]2025'!$D$31 -> AN-16-0027 | E38: =16.3+2141.58+2.37 -> 2160.25 | R38: =E38+F38+G38+H38+I38+J38+K38+L38+M38+N38+O38+P38+Q38 -> 2160.25 | S38: =R38/12 -> 180.02083 | W38: =T38+V38 -> 0
B39: 28 | C39: Paul C. Espinosa | D39: ='[2]2025'!$D$32 -> AN-16-0028 | E39: =20.52+2695.2+2.98 -> 2718.7 | R39: =E39+F39+G39+H39+I39+J39+K39+L39+M39+N39+O39+P39+Q39 -> 2718.7 | S39: =R39/12 -> 226.55833 | W39: =T39+V39 -> 0
R41: =SUM(R12:R40) -> 69978.66
X42: Page 1 of 4
B44: SIDLAK CHRISTIAN CHILDREN FUND SAVINGS AND CREDIT COOPERATIVE
B45: CDA Registration No. 9520-1080000000036399 Dated: November 16, 2016
B46: P-2, Brgy. Linao, Ormoc City
B48: COMPUTATION OF SHARES AND PATRONAGE REFUND
...

Sheet kiddy2020
A2: SIDLAK CHRISTIAN CHILDREN FUND SAVINGS AND CREDIT COOPERATIVE
A3: CDA Registration No. 9520-1080000000036399 Dated: November 16, 2016
A4: P-2, Brgy. Linao, Ormoc City
A6: COMPUTATION OF SAVINGS DEPOSITS
A7: As of FY 2020
A9: Members | C9: 2019 Savings | D9: Jan | E9: Feb | F9: Mar | G9: Apr | H9: May | I9: Jun | J9: Jul | K9: Aug | L9: Sep | M9: Oct | N9: Nov | O9: Dec | P9: TSAD | Q9: ASAD | R9: Int. on TSAD | S9: Total (SAD + Interest)
A10: 1 | B10: Cort Wensley J. Balao | C10: =1075+64.5 -> 1139.5 | D10: 160 | O10: 300 | P10: =C10+D10+E10+F10+G10+H10+I10+J10+K10+L10+M10+N10+O10 -> 1599.5 | Q10: =P10/12 -> 133.29167 | R10: =D11+E11+F11+G11+H11+I11+J11+K11+L11+M11+N11+O11 -> 79.47 | S10: =P10+R10 -> 1678.97
C11: Interest per mo. | D11: =(C10+D10)*0.005 -> 6.4975 | E11: =(C10+D10+E10)*0.005 -> 6.4975 | F11: =(+C10+D10+E10+F10)*0.005 -> 6.4975 | G11: =(C10+D10+E10+F10+G10)*0.005 -> 6.4975 | H11: =(C10+D10+E10+F10+G10+H10)*0.005 -> 6.4975 | I11: =(C10+D10+E10+F10+G10+H10+I10)*0.005 -> 6.4975 | J11: =(C10+D10+E10+F10+G10+H10+I10+J10)*0.005 -> 6.4975 | K11: =(C10+D10+E10+F10+G10+H10+I10+J10+K10)*0.005 -> 6.4975 | L11: =(C10+D10+E10+F10+G10+H10+I10+J10+K10+L10)*0.005 -> 6.4975 | M11: =(C10+D10+E10+F10+G10+H10+I10+J10+K10+L10+M10)*0.005 -> 6.4975 | N11: =(C10+D10+E10+F10+G10+H10+I10+J10+K10+L10+M10+N10)*0.005 -> 6.4975 | O11: =(C10+D10+E10+F10+G10+H10+I10+J10+K10+L10+M10+N10+O10)*0.005 -> 7.9975
A12: 2 | B12: Brett Colin J. Balao | C12: =1100+66 -> 1166 | D12: 70 | N12: 545 | O12: 300 | P12: =C12+D12+E12+F12+G12+H12+I12+J12+K12+L12+M12+N12+O12 -> 2081 | Q12: =P12/12 -> 173.41667 | R12: =D13+E13+F13+G13+H13+I13+J13+K13+L13+M13+N13+O13 -> 81.11 | S12: =P12+R12 -> 2162.11
C13: Interest per mo. | D13: =(C12+D12)*0.005 -> 6.18 | E13: =(C12+D12+E12)*0.005 -> 6.18 | F13: =(+C12+D12+E12+F12)*0.005 -> 6.18 | G13: =(C12+D12+E12+F12+G12)*0.005 -> 6.18 | H13: =(C12+D12+E12+F12+G12+H12)*0.005 -> 6.18 | I13: =(C12+D12+E12+F12+G12+H12+I12)*0.005 -> 6.18 | J13: =(C12+D12+E12+F12+G12+H12+I12+J12)*0.005 -> 6.18 | K13: =(C12+D12+E12+F12+G12+H12+I12+J12+K12)*0.005 -> 6.18 | L13: =(C12+D12+E12+F12+G12+H12+I12+J12+K12+L12)*0.005 -> 6.18 | M13: =(C12+D12+E12+F12+G12+H12+I12+J12+K12+L12+M12)*0.005 -> 6.18 | N13: =(C12+D12+E12+F12+G12+H12+I12+J12+K12+L12+M12+N12)*0.005 -> 8.905 | O13: =(C12+D12+E12+F12+G12+H12+I12+J12+K12+L12+M12+N12+O12)*0.005 -> 10.405
A14: 3 | B14: Demian Sabin C. Jumao-as | C14: =2400+144 -> 2544 | D14: 200 | E14: 340 | I14: 1000 | N14: 700 | P14: =C14+D14+E14+F14+G14+H14+I14+J14+K14+L14+M14+N14+O14 -> 4784 | Q14: =P14/12 -> 398.66667 | R14: =D15+E15+F15+G15+H15+I15+J15+K15+L15+M15+N15+O15 -> 225.34 | S14: =P14+R14 -> 5009.34
C15: Interest per mo. | D15: =(C14+D14)*0.005 -> 13.72 | E15: =(C14+D14+E14)*0.005 -> 15.42 | F15: =(+C14+D14+E14+F14)*0.005 -> 15.42 | G15: =(C14+D14+E14+F14+G14)*0.005 -> 15.42 | H15: =(C14+D14+E14+F14+G14+H14)*0.005 -> 15.42 | I15: =(C14+D14+E14+F14+G14+H14+I14)*0.005 -> 20.42 | J15: =(C14+D14+E14+F14+G14+H14+I14+J14)*0.005 -> 20.42 | K15: =(C14+D14+E14+F14+G14+H14+I14+J14+K14)*0.005 -> 20.42 | L15: =(C14+D14+E14+F14+G14+H14+I14+J14+K14+L14)*0.005 -> 20.42 | M15: =(C14+D14+E14+F14+G14+H14+I14+J14+K14+L14+M14)*0.005 -> 20.42 | N15: =(C14+D14+E14+F14+G14+H14+I14+J14+K14+L14+M14+N14)*0.005 -> 23.92 | O15: =(C14+D14+E14+F14+G14+H14+I14+J14+K14+L14+M14+N14+O14)*0.005 -> 23.92
A16: 4 | B16: Izy Kaizer J. Balao | C16: =1688+101.28 -> 1789.28 | D16: 280 | E16: 0 | F16: 0 | G16: 0 | H16: 0 | J16: 0 | K16: 0 | L16: 0 | M16: 0 | N16: 0 | O16: 600 | P16: =C16+D16+E16+F16+G16+H16+I16+J16+K16+L16+M16+N16+O16 -> 2669.28 | Q16: =P16/12 -> 222.44 | R16: =D17+E17+F17+G17+H17+I17+J17+K17+L17+M17+N17+O17 -> 127.1568 | S16: =P16+R16 -> 2796.4368
C17: Interest per mo. | D17: =(C16+D16)*0.005 -> 10.3464 | E17: =(C16+D16+E16)*0.005 -> 10.3464 | F17: =(+C16+D16+E16+F16)*0.005 -> 10.3464 | G17: =(C16+D16+E16+F16+G16)*0.005 -> 10.3464 | H17: =(C16+D16+E16+F16+G16+H16)*0.005 -> 10.3464 | I17: =(C16+D16+E16+F16+G16+H16+I16)*0.005 -> 10.3464 | J17: =(C16+D16+E16+F16+G16+H16+I16+J16)*0.005 -> 10.3464 | K17: =(C16+D16+E16+F16+G16+H16+I16+J16+K16)*0.005 -> 10.3464 | L17: =(C16+D16+E16+F16+G16+H16+I16+J16+K16+L16)*0.005 -> 10.3464 | M17: =(C16+D16+E16+F16+G16+H16+I16+J16+K16+L16+M16)*0.005 -> 10.3464 | N17: =(C16+D16+E16+F16+G16+H16+I16+J16+K16+L16+M16+N16)*0.005 -> 10.3464 | O17: =(C16+D16+E16+F16+G16+H16+I16+J16+K16+L16+M16+N16+O16)*0.005 -> 13.3464
A18: 5 | B18: Alerc Finlay J. Balao | C18: =1583+94.98 -> 1677.98 | D18: 238 | E18: 60 | F18: 0 | G18: 0 | I18: 0 | J18: 0 | K18: 0 | N18: 0 | P18: =C18+D18+E18+F18+G18+H18+I18+J18+K18+L18+M18+N18+O18 -> 1975.98 | Q18: =P18/12 -> 164.665 | R18: =D19+E19+F19+G19+H19+I19+J19+K19+L19+M19+N19+O19 -> 118.2588 | S18: =P18+R18 -> 2094.2388
C19: Interest per mo. | D19: =(C18+D18)*0.005 -> 9.5799 | E19: =(C18+D18+E18)*0.005 -> 9.8799 | F19: =(+C18+D18+E18+F18)*0.005 -> 9.8799 | G19: =(C18+D18+E18+F18+G18)*0.005 -> 9.8799 | H19: =(C18+D18+E18+F18+G18+H18)*0.005 -> 9.8799 | I19: =(C18+D18+E18+F18+G18+H18+I18)*0.005 -> 9.8799 | J19: =(C18+D18+E18+F18+G18+H18+I18+J18)*0.005 -> 9.8799 | K19: =(C18+D18+E18+F18+G18+H18+I18+J18+K18)*0.005 -> 9.8799 | L19: =(C18+D18+E18+F18+G18+H18+I18+J18+K18+L18)*0.005 -> 9.8799 | M19: =(C18+D18+E18+F18+G18+H18+I18+J18+K18+L18+M18)*0.005 -> 9.8799 | N19: =(C18+D18+E18+F18+G18+H18+I18+J18+K18+L18+M18+N18)*0.005 -> 9.8799 | O19: =(C18+D18+E18+F18+G18+H18+I18+J18+K18+L18+M18+N18+O18)*0.005 -> 9.8799
A20: 6 | B20: Georgette Ann Cabahug | C20: 50 | P20: 50 | Q20: =P20/12 -> 4.1666667 | S20: =P20+R20 -> 50
C21: Interest per mo. | D21: =(C20+D20)*0.005 -> 0.25 | E21: =(C20+D20+E20)*0.005 -> 0.25 | F21: =(+C20+D20+E20+F20)*0.005 -> 0.25 | G21: =(C20+D20+E20+F20+G20)*0.005 -> 0.25 | H21: =(C20+D20+E20+F20+G20+H20)*0.005 -> 0.25 | I21: =(C20+D20+E20+F20+G20+H20+I20)*0.005 -> 0.25 | J21: =(C20+D20+E20+F20+G20+H20+I20+J20)*0.005 -> 0.25 | K21: =(C20+D20+E20+F20+G20+H20+I20+J20+K20)*0.005 -> 0.25 | L21: =(C20+D20+E20+F20+G20+H20+I20+J20+K20+L20)*0.005 -> 0.25 | M21: =(C20+D20+E20+F20+G20+H20+I20+J20+K20+L20+M20)*0.005 -> 0.25 | N21: =(C20+D20+E20+F20+G20+H20+I20+J20+K20+L20+M20+N20)*0.005 -> 0.25 | O21: =(C20+D20+E20+F20+G20+H20+I20+J20+K20+L20+M20+N20+O20)*0.005 -> 0.25
A22: 7 | B22: Luna Mikaela C. Apay | C22: 50 | P22: =C22+D22+E22+F22+G22+H22+I22+J22+K22+L22+M22+N22+O22 -> 50 | Q22: =P22/12 -> 4.1666667 | S22: =P22+R22 -> 50
C23: Interest per mo. | D23: =(C22+D22)*0.005 -> 0.25 | E23: =(C22+D22+E22)*0.005 -> 0.25 | F23: =(+C22+D22+E22+F22)*0.005 -> 0.25 | G23: =(C22+D22+E22+F22+G22)*0.005 -> 0.25 | H23: =(C22+D22+E22+F22+G22+H22)*0.005 -> 0.25 | I23: =(C22+D22+E22+F22+G22+H22+I22)*0.005 -> 0.25 | J23: =(C22+D22+E22+F22+G22+H22+I22+J22)*0.005 -> 0.25 | K23: =(C22+D22+E22+F22+G22+H22+I22+J22+K22)*0.005 -> 0.25 | L23: =(C22+D22+E22+F22+G22+H22+I22+J22+K22+L22)*0.005 -> 0.25 | M23: =(C22+D22+E22+F22+G22+H22+I22+J22+K22+L22+M22)*0.005 -> 0.25 | N23: =(C22+D22+E22+F22+G22+H22+I22+J22+K22+L22+M22+N22)*0.005 -> 0.25 | O23: =(C22+D22+E22+F22+G22+H22+I22+J22+K22+L22+M22+N22+O22)*0.005 -> 0.25
A24: 8 | B24: Mikko Angelo C. Apay | C24: 50 | P24: =C24+D24+E24+F24+G24+H24+I24+J24+K24+L24+M24+N24+O24 -> 50 | Q24: =P24/12 -> 4.1666667 | S24: =P24+R24 -> 50
C25: Interest per mo. | D25: =(C24+D24)*0.005 -> 0.25 | E25: =(C24+D24+E24)*0.005 -> 0.25 | F25: =(+C24+D24+E24+F24)*0.005 -> 0.25 | G25: =(C24+D24+E24+F24+G24)*0.005 -> 0.25 | H25: =(C24+D24+E24+F24+G24+H24)*0.005 -> 0.25 | I25: =(C24+D24+E24+F24+G24+H24+I24)*0.005 -> 0.25 | J25: =(C24+D24+E24+F24+G24+H24+I24+J24)*0.005 -> 0.25 | K25: =(C24+D24+E24+F24+G24+H24+I24+J24+K24)*0.005 -> 0.25 | L25: =(C24+D24+E24+F24+G24+H24+I24+J24+K24+L24)*0.005 -> 0.25 | M25: =(C24+D24+E24+F24+G24+H24+I24+J24+K24+L24+M24)*0.005 -> 0.25 | N25: =(C24+D24+E24+F24+G24+H24+I24+J24+K24+L24+M24+N24)*0.005 -> 0.25 | O25: =(C24+D24+E24+F24+G24+H24+I24+J24+K24+L24+M24+N24+O24)*0.005 -> 0.25
A26: 9 | B26: Casy Marie D. Cruz | C26: 250 | I26: 0 | K26: =100+150 -> 250 | N26: 50 | P26: =C26+D26+E26+F26+G26+H26+I26+J26+K26+L26+M26+N26+O26 -> 550 | Q26: =P26/12 -> 45.833333 | R26: =D27+E27+F27+G27+H27+I27+J27+K27+L27+M27+N27+O27 -> 13 | S26: =P26+R26 -> 563
C27: Interest per mo. | K27: =(C26+D26+E26+F26+G26+H26+I26+J26+K26)*0.005 -> 2.5 | L27: =(C26+D26+E26+F26+G26+H26+I26+J26+K26+L26)*0.005 -> 2.5 | M27: =(C26+D26+E26+F26+G26+H26+I26+J26+K26+L26+M26)*0.005 -> 2.5 | N27: =(C26+D26+E26+F26+G26+H26+I26+J26+K26+L26+M26+N26)*0.005 -> 2.75 | O27: =(C26+D26+E26+F26+G26+H26+I26+J26+K26+L26+M26+N26+O26)*0.005 -> 2.75
A28: 10 | B28: Marissa alvarado | C28: 50 | J28: 0 | M28: 0 | P28: =C28+D28+E28+F28+G28+H28+I28+J28+K28+L28+M28+N28+O28 -> 50 | Q28: =P28/12 -> 4.1666667 | S28: =P28+R28 -> 50
C29: Interest per mo. | D29: =(C28+D28)*0.005 -> 0.25 | E29: =(C28+D28+E28)*0.005 -> 0.25 | F29: =(+C28+D28+E28+F28)*0.005 -> 0.25 | G29: =(C28+D28+E28+F28+G28)*0.005 -> 0.25 | H29: =(C28+D28+E28+F28+G28+H28)*0.005 -> 0.25 | I29: =(C28+D28+E28+F28+G28+H28+I28)*0.005 -> 0.25 | J29: =(C28+D28+E28+F28+G28+H28+I28+J28)*0.005 -> 0.25 | K29: =(C28+D28+E28+F28+G28+H28+I28+J28+K28)*0.005 -> 0.25 | L29: =(C28+D28+E28+F28+G28+H28+I28+J28+K28+L28)*0.005 -> 0.25 | M29: =(C28+D28+E28+F28+G28+H28+I28+J28+K28+L28+M28)*0.005 -> 0.25 | N29: =(C28+D28+E28+F28+G28+H28+I28+J28+K28+L28+M28+N28)*0.005 -> 0.25 | O29: =(C28+D28+E28+F28+G28+H28+I28+J28+K28+L28+M28+N28+O28)*0.005 -> 0.25
A30: 11 | B30: Krissel Alvarado | C30: 50 | D30: 0 | P30: =C30+D30+E30+F30+G30+H30+I30+J30+K30+L30+M30+N30+O30 -> 50 | Q30: =P30/12 -> 4.1666667 | S30: =P30+R30 -> 50
C31: Interest per mo. | D31: =(C30+D30)*0.005 -> 0.25 | E31: =(C30+D30+E30)*0.005 -> 0.25 | F31: =(+C30+D30+E30+F30)*0.005 -> 0.25 | G31: =(C30+D30+E30+F30+G30)*0.005 -> 0.25 | H31: =(C30+D30+E30+F30+G30+H30)*0.005 -> 0.25 | I31: =(C30+D30+E30+F30+G30+H30+I30)*0.005 -> 0.25 | J31: =(C30+D30+E30+F30+G30+H30+I30+J30)*0.005 -> 0.25 | K31: =(C30+D30+E30+F30+G30+H30+I30+J30+K30)*0.005 -> 0.25 | L31: =(C30+D30+E30+F30+G30+H30+I30+J30+K30+L30)*0.005 -> 0.25 | M31: =(C30+D30+E30+F30+G30+H30+I30+J30+K30+L30+M30)*0.005 -> 0.25 | N31: =(C30+D30+E30+F30+G30+H30+I30+J30+K30+L30+M30+N30)*0.005 -> 0.25 | O31: =(C30+D30+E30+F30+G30+H30+I30+J30+K30+L30+M30+N30+O30)*0.005 -> 0.25
A32: 12 | B32: Serg Mateo M. Villamor | C32: 450 | D32: 0 | E32: 500 | F32: 500 | J32: 300 | K32: 300 | L32: 0 | M32: 347 | N32: 300 | P32: =C32+D32+E32+F32+G32+H32+I32+J32+K32+L32+M32+N32+O32 -> 2697 | Q32: =P32/12 -> 224.75 | R32: =D33+E33+F33+G33+H33+I33+J33+K33+L33+M33+N33+O33 -> 101.955 | S32: =P32+R32 -> 2798.955
C33: Interest per mo. | E33: =(C32+D32+E32)*0.005 -> 4.75 | F33: =(+C32+D32+E32+F32)*0.005 -> 7.25 | G33: =(C32+D32+E32+F32+G32)*0.005 -> 7.25 | H33: =(C32+D32+E32+F32+G32+H32)*0.005 -> 7.25 | I33: =(C32+D32+E32+F32+G32+H32+I32)*0.005 -> 7.25 | J33: =(C32+D32+E32+F32+G32+H32+I32+J32)*0.005 -> 8.75 | K33: =(C32+D32+E32+F32+G32+H32+I32+J32+K32)*0.005 -> 10.25 | L33: =(C32+D32+E32+F32+G32+H32+I32+J32+K32+L32)*0.005 -> 10.25 | M33: =(C32+D32+E32+F32+G32+H32+I32+J32+K32+L32+M32)*0.005 -> 11.985 | N33: =(C32+D32+E32+F32+G32+H32+I32+J32+K32+L32+M32+N32)*0.005 -> 13.485 | O33: =(C32+D32+E32+F32+G32+H32+I32+J32+K32+L32+M32+N32+O32)*0.005 -> 13.485
A34: 13 | B34: Rica M. Cruz | C34: 200 | D34: 0 | E34: 0 | F34: 0 | L34: 0 | P34: =C34+D34+E34+F34+G34+H34+I34+J34+K34+L34+M34+N34+O34 -> 200 | Q34: =P34/12 -> 16.666667 | S34: =P34+R34 -> 200
C35: Interest per mo. | D35: =(C34+D34)*0.005 -> 1 | E35: =(C34+D34+E34)*0.005 -> 1 | F35: =(+C34+D34+E34+F34)*0.005 -> 1 | G35: =(C34+D34+E34+F34+G34)*0.005 -> 1 | H35: =(C34+D34+E34+F34+G34+H34)*0.005 -> 1 | I35: =(C34+D34+E34+F34+G34+H34+I34)*0.005 -> 1 | J35: =(C34+D34+E34+F34+G34+H34+I34+J34)*0.005 -> 1 | K35: =(C34+D34+E34+F34+G34+H34+I34+J34+K34)*0.005 -> 1 | L35: =(C34+D34+E34+F34+G34+H34+I34+J34+K34+L34)*0.005 -> 1 | M35: =(C34+D34+E34+F34+G34+H34+I34+J34+K34+L34+M34)*0.005 -> 1 | N35: =(C34+D34+E34+F34+G34+H34+I34+J34+K34+L34+M34+N34)*0.005 -> 1 | O35: =(C34+D34+E34+F34+G34+H34+I34+J34+K34+L34+M34+N34+O34)*0.005 -> 1
A36: 14 | B36: Yvo Rafiel Samson | C36: 200 | D36: =600+100 -> 700 | E36: 280 | F36: 0 | G36: 0 | L36: 0 | P36: =C36+D36+E36+F36+G36+H36+I36+J36+K36+L36+M36+N36+O36 -> 1180 | Q36: =P36/12 -> 98.333333 | R36: =D37+E37+F37+G37+H37+I37+J37+K37+L37+M37+N37+O37 -> 69.4 | S36: =P36+R36 -> 1249.4
C37: Interest per mo. | D37: =(C36+D36)*0.005 -> 4.5 | E37: =(C36+D36+E36)*0.005 -> 5.9 | F37: =(+C36+D36+E36+F36)*0.005 -> 5.9 | G37: =(C36+D36+E36+F36+G36)*0.005 -> 5.9 | H37: =(C36+D36+E36+F36+G36+H36)*0.005 -> 5.9 | I37: =(C36+D36+E36+F36+G36+H36+I36)*0.005 -> 5.9 | J37: =(C36+D36+E36+F36+G36+H36+I36+J36)*0.005 -> 5.9 | K37: =(C36+D36+E36+F36+G36+H36+I36+J36+K36)*0.005 -> 5.9 | L37: =(C36+D36+E36+F36+G36+H36+I36+J36+K36+L36)*0.005 -> 5.9 | M37: =(C36+D36+E36+F36+G36+H36+I36+J36+K36+L36+M36)*0.005 -> 5.9 | N37: =(C36+D36+E36+F36+G36+H36+I36+J36+K36+L36+M36+N36)*0.005 -> 5.9 | O37: =(C36+D36+E36+F36+G36+H36+I36+J36+K36+L36+M36+N36+O36)*0.005 -> 5.9
S38: Page 1 of 2
B42: TOTAL | C42: =SUM(C10:C41) -> 9666.76 | D42: =SUM(D10:D41) -> 1701.0738 | E42: =SUM(E10:E41) -> 1241.2238 | F42: =SUM(F10:F41) -> 563.7238 | G42: =SUM(G10:G41) -> 63.7238 | H42: =SUM(H10:H41) -> 63.7238 | I42: =SUM(I10:I41) -> 1068.7238 | J42: =SUM(J10:J41) -> 370.2238 | ... S42: =SUM(S10:S41) -> 18802.451
A44: Prepared by: | E44: Checked by: | K44: Noted by: | P44: Approved by:
B47: SHALOU J. BALAO | F47: MARIA GENIA C. SEGUIDO | L47: ARNOLD C. GONZALES | Q47: DEXTER B. JUMAO-AS
B48: SCSCC Secretary | F48: SCSCC Treasurer | L48: General Manager, SCSCC | Q48: Chairman, SCSCC BOD
S51: Page 2 of 2
...

Sheet kiddy2021
A2: SIDLAK CHRISTIAN CHILDREN FUND SAVINGS AND CREDIT COOPERATIVE
A3: CDA Registration No. 9520-1080000000036399 Dated: November 16, 2016
A4: P-2, Brgy. Linao, Ormoc City
A6: COMPUTATION OF SAVINGS DEPOSITS
A7: As of FY 2021
C9: 2020 Savings | D9: Jan | E9: Feb | F9: Mar | G9: Apr | H9: May | I9: Jun | J9: Jul | K9: Aug | L9: Sep | M9: Oct | N9: Nov | O9: Dec | P9: TSAD | Q9: ASAD | R9: Int. on TSAD | S9: Total (SAD + Interest)
A10: 1 | B10: Cort Wensley J. Balao | C10: 1678.97 | D10: 200 | E10: 0 | F10: 0 | G10: 0 | H10: 0 | I10: 0 | J10: 0 | K10: 0 | L10: 0 | M10: 0 | N10: 0 | O10: 400 | P10: =C10+D10+E10+F10+G10+H10+I10+J10+K10+L10+M10+N10+O10 -> 2278.97 | Q10: =P10/12 -> 189.91417 | R10: =D11+E11+F11+G11+H11+I11+J11+K11+L11+M11+N11+O11 -> 113.73335 | S10: =P10+R10 -> 2392.7033
C11: Interest per mo. | D11: 8.39 | E11: =(C10+D10+E10)*0.005 -> 9.39485 | F11: =(+C10+D10+E10+F10)*0.005 -> 9.39485 | G11: =(C10+D10+E10+F10+G10)*0.005 -> 9.39485 | H11: =(C10+D10+E10+F10+G10+H10)*0.005 -> 9.39485 | I11: =(C10+D10+E10+F10+G10+H10+I10)*0.005 -> 9.39485 | J11: =(C10+D10+E10+F10+G10+H10+I10+J10)*0.005 -> 9.39485 | K11: =(C10+D10+E10+F10+G10+H10+I10+J10+K10)*0.005 -> 9.39485 | L11: =(C10+D10+E10+F10+G10+H10+I10+J10+K10+L10)*0.005 -> 9.39485 | M11: =(C10+D10+E10+F10+G10+H10+I10+J10+K10+L10+M10)*0.005 -> 9.39485 | N11: =(C10+D10+E10+F10+G10+H10+I10+J10+K10+L10+M10+N10)*0.005 -> 9.39485 | O11: =(C10+D10+E10+F10+G10+H10+I10+J10+K10+L10+M10+N10+O10)*0.005 -> 11.39485
A12: 2 | B12: Brett Colin J. Balao | C12: 2162.11 | D12: 200 | N12: 0 | O12: 0 | P12: =C12+D12+E12+F12+G12+H12+I12+J12+K12+L12+M12+N12+O12 -> 2362.11 | Q12: =P12/12 -> 196.8425 | R12: =D13+E13+F13+G13+H13+I13+J13+K13+L13+M13+N13+O13 -> 140.72605 | S12: =P12+R12 -> 2502.836
C13: Interest per mo. | D13: 10.81 | E13: =(C12+D12+E12)*0.005 -> 11.81055 | F13: =(+C12+D12+E12+F12)*0.005 -> 11.81055 | G13: =(C12+D12+E12+F12+G12)*0.005 -> 11.81055 | H13: =(C12+D12+E12+F12+G12+H12)*0.005 -> 11.81055 | I13: =(C12+D12+E12+F12+G12+H12+I12)*0.005 -> 11.81055 | J13: =(C12+D12+E12+F12+G12+H12+I12+J12)*0.005 -> 11.81055 | K13: =(C12+D12+E12+F12+G12+H12+I12+J12+K12)*0.005 -> 11.81055 | L13: =(C12+D12+E12+F12+G12+H12+I12+J12+K12+L12)*0.005 -> 11.81055 | M13: =(C12+D12+E12+F12+G12+H12+I12+J12+K12+L12+M12)*0.005 -> 11.81055 | N13: =(C12+D12+E12+F12+G12+H12+I12+J12+K12+L12+M12+N12)*0.005 -> 11.81055 | O13: =(C12+D12+E12+F12+G12+H12+I12+J12+K12+L12+M12+N12+O12)*0.005 -> 11.81055
A14: 3 | B14: Demian Sabin C. Jumao-as | C14: 5009.34 | D14: 0 | E14: 0 | F14: 0 | G14: 0 | H14: 0 | I14: 0 | J14: 0 | K14: 0 | L14: 0 | M14: 0 | N14: 0 | O14: 1600 | P14: =C14+D14+E14+F14+G14+H14+I14+J14+K14+L14+M14+N14+O14 -> 6609.34 | Q14: =P14/12 -> 550.77833 | R14: =D15+E15+F15+G15+H15+I15+J15+K15+L15+M15+N15+O15 -> 308.5637 | S14: =P14+R14 -> 6917.9037
C15: Interest per mo. | D15: 25.05 | E15: =(C14+D14+E14)*0.005 -> 25.0467 | F15: =(+C14+D14+E14+F14)*0.005 -> 25.0467 | G15: =(C14+D14+E14+F14+G14)*0.005 -> 25.0467 | H15: =(C14+D14+E14+F14+G14+H14)*0.005 -> 25.0467 | I15: =(C14+D14+E14+F14+G14+H14+I14)*0.005 -> 25.0467 | J15: =(C14+D14+E14+F14+G14+H14+I14+J14)*0.005 -> 25.0467 | K15: =(C14+D14+E14+F14+G14+H14+I14+J14+K14)*0.005 -> 25.0467 | L15: =(C14+D14+E14+F14+G14+H14+I14+J14+K14+L14)*0.005 -> 25.0467 | M15: =(C14+D14+E14+F14+G14+H14+I14+J14+K14+L14+M14)*0.005 -> 25.0467 | N15: =(C14+D14+E14+F14+G14+H14+I14+J14+K14+L14+M14+N14)*0.005 -> 25.0467 | O15: =(C14+D14+E14+F14+G14+H14+I14+J14+K14+L14+M14+N14+O14)*0.005 -> 33.0467
A16: 4 | B16: Izy Kaizer J. Balao | C16: 2796.44 | D16: 600 | E16: 0 | F16: 0 | G16: 0 | H16: 0 | I16: 0 | J16: 0 | K16: 0 | L16: 0 | M16: 0 | N16: 0 | O16: 0 | P16: =C16+D16+E16+F16+G16+H16+I16+J16+K16+L16+M16+N16+O16 -> 3396.44 | Q16: =P16/12 -> 283.03667 | R16: =D17+E17+F17+G17+H17+I17+J17+K17+L17+M17+N17+O17 -> 200.1542 | S16: =P16+R16 -> 3596.5942
C17: Interest per mo. | D17: 13.35 | E17: =(C16+D16+E16)*0.005 -> 16.9822 | F17: =(+C16+D16+E16+F16)*0.005 -> 16.9822 | G17: =(C16+D16+E16+F16+G16)*0.005 -> 16.9822 | H17: =(C16+D16+E16+F16+G16+H16)*0.005 -> 16.9822 | I17: =(C16+D16+E16+F16+G16+H16+I16)*0.005 -> 16.9822 | J17: =(C16+D16+E16+F16+G16+H16+I16+J16)*0.005 -> 16.9822 | K17: =(C16+D16+E16+F16+G16+H16+I16+J16+K16)*0.005 -> 16.9822 | L17: =(C16+D16+E16+F16+G16+H16+I16+J16+K16+L16)*0.005 -> 16.9822 | M17: =(C16+D16+E16+F16+G16+H16+I16+J16+K16+L16+M16)*0.005 -> 16.9822 | N17: =(C16+D16+E16+F16+G16+H16+I16+J16+K16+L16+M16+N16)*0.005 -> 16.9822 | O17: =(C16+D16+E16+F16+G16+H16+I16+J16+K16+L16+M16+N16+O16)*0.005 -> 16.9822
A18: 5 | B18: Alerc Finlay J. Balao | C18: 2094.24 | D18: 200 | E18: 0 | F18: 0 | G18: 0 | H18: 0 | I18: 0 | J18: 0 | K18: 0 | L18: 0 | M18: 0 | N18: 0 | O18: 0 | P18: =C18+D18+E18+F18+G18+H18+I18+J18+K18+L18+M18+N18+O18 -> 2294.24 | Q18: =P18/12 -> 191.18667 | R18: =D19+E19+F19+G19+H19+I19+J19+K19+L19+M19+N19+O19 -> 126.1832 | S18: =P18+R18 -> 2420.4232
C19: Interest per mo. | E19: =(C18+D18+E18)*0.005 -> 11.4712 | F19: =(+C18+D18+E18+F18)*0.005 -> 11.4712 | G19: =(C18+D18+E18+F18+G18)*0.005 -> 11.4712 | H19: =(C18+D18+E18+F18+G18+H18)*0.005 -> 11.4712 | I19: =(C18+D18+E18+F18+G18+H18+I18)*0.005 -> 11.4712 | J19: =(C18+D18+E18+F18+G18+H18+I18+J18)*0.005 -> 11.4712 | K19: =(C18+D18+E18+F18+G18+H18+I18+J18+K18)*0.005 -> 11.4712 | L19: =(C18+D18+E18+F18+G18+H18+I18+J18+K18+L18)*0.005 -> 11.4712 | M19: =(C18+D18+E18+F18+G18+H18+I18+J18+K18+L18+M18)*0.005 -> 11.4712 | N19: =(C18+D18+E18+F18+G18+H18+I18+J18+K18+L18+M18+N18)*0.005 -> 11.4712 | O19: =(C18+D18+E18+F18+G18+H18+I18+J18+K18+L18+M18+N18+O18)*0.005 -> 11.4712
A20: 6 | B20: Georgette Ann Cabahug | C20: 50 | D20: 0 | P20: 50 | Q20: =P20/12 -> 4.1666667 | S20: =P20+R20 -> 50
C21: Interest per mo. | D21: =(C20+D20)*0.005 -> 0.25 | E21: =(C20+D20+E20)*0.005 -> 0.25 | F21: =(+C20+D20+E20+F20)*0.005 -> 0.25 | G21: =(C20+D20+E20+F20+G20)*0.005 -> 0.25 | H21: =(C20+D20+E20+F20+G20+H20)*0.005 -> 0.25 | I21: =(C20+D20+E20+F20+G20+H20+I20)*0.005 -> 0.25 | J21: =(C20+D20+E20+F20+G20+H20+I20+J20)*0.005 -> 0.25 | K21: =(C20+D20+E20+F20+G20+H20+I20+J20+K20)*0.005 -> 0.25 | L21: =(C20+D20+E20+F20+G20+H20+I20+J20+K20+L20)*0.005 -> 0.25 | M21: =(C20+D20+E20+F20+G20+H20+I20+J20+K20+L20+M20)*0.005 -> 0.25 | N21: =(C20+D20+E20+F20+G20+H20+I20+J20+K20+L20+M20+N20)*0.005 -> 0.25 | O21: =(C20+D20+E20+F20+G20+H20+I20+J20+K20+L20+M20+N20+O20)*0.005 -> 0.25
A22: 7 | B22: Luna Mikaela C. Apay | C22: 50 | D22: 0 | P22: =C22+D22+E22+F22+G22+H22+I22+J22+K22+L22+M22+N22+O22 -> 50 | Q22: =P22/12 -> 4.1666667 | S22: =P22+R22 -> 50
C23: Interest per mo. | D23: =(C22+D22)*0.005 -> 0.25 | E23: =(C22+D22+E22)*0.005 -> 0.25 | F23: =(+C22+D22+E22+F22)*0.005 -> 0.25 | G23: =(C22+D22+E22+F22+G22)*0.005 -> 0.25 | H23: =(C22+D22+E22+F22+G22+H22)*0.005 -> 0.25 | I23: =(C22+D22+E22+F22+G22+H22+I22)*0.005 -> 0.25 | J23: =(C22+D22+E22+F22+G22+H22+I22+J22)*0.005 -> 0.25 | K23: =(C22+D22+E22+F22+G22+H22+I22+J22+K22)*0.005 -> 0.25 | L23: =(C22+D22+E22+F22+G22+H22+I22+J22+K22+L22)*0.005 -> 0.25 | M23: =(C22+D22+E22+F22+G22+H22+I22+J22+K22+L22+M22)*0.005 -> 0.25 | N23: =(C22+D22+E22+F22+G22+H22+I22+J22+K22+L22+M22+N22)*0.005 -> 0.25 | O23: =(C22+D22+E22+F22+G22+H22+I22+J22+K22+L22+M22+N22+O22)*0.005 -> 0.25
A24: 8 | B24: Mikko Angelo C. Apay | C24: 50 | D24: 0 | P24: =C24+D24+E24+F24+G24+H24+I24+J24+K24+L24+M24+N24+O24 -> 50 | Q24: =P24/12 -> 4.1666667 | S24: =P24+R24 -> 50
C25: Interest per mo. | D25: =(C24+D24)*0.005 -> 0.25 | E25: =(C24+D24+E24)*0.005 -> 0.25 | F25: =(+C24+D24+E24+F24)*0.005 -> 0.25 | G25: =(C24+D24+E24+F24+G24)*0.005 -> 0.25 | H25: =(C24+D24+E24+F24+G24+H24)*0.005 -> 0.25 | I25: =(C24+D24+E24+F24+G24+H24+I24)*0.005 -> 0.25 | J25: =(C24+D24+E24+F24+G24+H24+I24+J24)*0.005 -> 0.25 | K25: =(C24+D24+E24+F24+G24+H24+I24+J24+K24)*0.005 -> 0.25 | L25: =(C24+D24+E24+F24+G24+H24+I24+J24+K24+L24)*0.005 -> 0.25 | M25: =(C24+D24+E24+F24+G24+H24+I24+J24+K24+L24+M24)*0.005 -> 0.25 | N25: =(C24+D24+E24+F24+G24+H24+I24+J24+K24+L24+M24+N24)*0.005 -> 0.25 | O25: =(C24+D24+E24+F24+G24+H24+I24+J24+K24+L24+M24+N24+O24)*0.005 -> 0.25
A26: 9 | B26: Casy Marie D. Cruz | C26: 563 | D26: 50 | I26: 0 | K26: 100 | N26: 0 | P26: =C26+D26+E26+F26+G26+H26+I26+J26+K26+L26+M26+N26+O26 -> 713 | Q26: =P26/12 -> 59.416667 | R26: =D27+E27+F27+G27+H27+I27+J27+K27+L27+M27+N27+O27 -> 17.825 | S26: =P26+R26 -> 730.825
C27: Interest per mo. | K27: =(C26+D26+E26+F26+G26+H26+I26+J26+K26)*0.005 -> 3.565 | L27: =(C26+D26+E26+F26+G26+H26+I26+J26+K26+L26)*0.005 -> 3.565 | M27: =(C26+D26+E26+F26+G26+H26+I26+J26+K26+L26+M26)*0.005 -> 3.565 | N27: =(C26+D26+E26+F26+G26+H26+I26+J26+K26+L26+M26+N26)*0.005 -> 3.565 | O27: =(C26+D26+E26+F26+G26+H26+I26+J26+K26+L26+M26+N26+O26)*0.005 -> 3.565
A28: 10 | B28: Marissa alvarado | C28: 50 | D28: 0 | J28: 0 | M28: 0 | P28: =C28+D28+E28+F28+G28+H28+I28+J28+K28+L28+M28+N28+O28 -> 50 | Q28: =P28/12 -> 4.1666667 | S28: =P28+R28 -> 50
C29: Interest per mo. | D29: =(C28+D28)*0.005 -> 0.25 | E29: =(C28+D28+E28)*0.005 -> 0.25 | F29: =(+C28+D28+E28+F28)*0.005 -> 0.25 | G29: =(C28+D28+E28+F28+G28)*0.005 -> 0.25 | H29: =(C28+D28+E28+F28+G28+H28)*0.005 -> 0.25 | I29: =(C28+D28+E28+F28+G28+H28+I28)*0.005 -> 0.25 | J29: =(C28+D28+E28+F28+G28+H28+I28+J28)*0.005 -> 0.25 | K29: =(C28+D28+E28+F28+G28+H28+I28+J28+K28)*0.005 -> 0.25 | L29: =(C28+D28+E28+F28+G28+H28+I28+J28+K28+L28)*0.005 -> 0.25 | M29: =(C28+D28+E28+F28+G28+H28+I28+J28+K28+L28+M28)*0.005 -> 0.25 | N29: =(C28+D28+E28+F28+G28+H28+I28+J28+K28+L28+M28+N28)*0.005 -> 0.25 | O29: =(C28+D28+E28+F28+G28+H28+I28+J28+K28+L28+M28+N28+O28)*0.005 -> 0.25
A30: 11 | B30: Krissel Alvarado | C30: 50 | D30: 0 | P30: =C30+D30+E30+F30+G30+H30+I30+J30+K30+L30+M30+N30+O30 -> 50 | Q30: =P30/12 -> 4.1666667 | S30: =P30+R30 -> 50
C31: Interest per mo. | D31: =(C30+D30)*0.005 -> 0.25 | E31: =(C30+D30+E30)*0.005 -> 0.25 | F31: =(+C30+D30+E30+F30)*0.005 -> 0.25 | G31: =(C30+D30+E30+F30+G30)*0.005 -> 0.25 | H31: =(C30+D30+E30+F30+G30+H30)*0.005 -> 0.25 | I31: =(C30+D30+E30+F30+G30+H30+I30)*0.005 -> 0.25 | J31: =(C30+D30+E30+F30+G30+H30+I30+J30)*0.005 -> 0.25 | K31: =(C30+D30+E30+F30+G30+H30+I30+J30+K30)*0.005 -> 0.25 | L31: =(C30+D30+E30+F30+G30+H30+I30+J30+K30+L30)*0.005 -> 0.25 | M31: =(C30+D30+E30+F30+G30+H30+I30+J30+K30+L30+M30)*0.005 -> 0.25 | N31: =(C30+D30+E30+F30+G30+H30+I30+J30+K30+L30+M30+N30)*0.005 -> 0.25 | O31: =(C30+D30+E30+F30+G30+H30+I30+J30+K30+L30+M30+N30+O30)*0.005 -> 0.25
A32: 12 | B32: Serg Mateo M. Villamor | C32: 2798.96 | D32: 0 | E32: 0 | F32: 0 | J32: 0 | K32: 0 | L32: 0 | M32: 0 | N32: 0 | O32: 0 | P32: =C32+D32+E32+F32+G32+H32+I32+J32+K32+L32+M32+N32+O32 -> 2798.96 | Q32: =P32/12 -> 233.24667 | R32: =D33+E33+F33+G33+H33+I33+J33+K33+L33+M33+N33+O33 -> 153.9428 | S32: =P32+R32 -> 2952.9028
C33: Interest per mo. | E33: =(C32+D32+E32)*0.005 -> 13.9948 | F33: =(+C32+D32+E32+F32)*0.005 -> 13.9948 | G33: =(C32+D32+E32+F32+G32)*0.005 -> 13.9948 | H33: =(C32+D32+E32+F32+G32+H32)*0.005 -> 13.9948 | I33: =(C32+D32+E32+F32+G32+H32+I32)*0.005 -> 13.9948 | J33: =(C32+D32+E32+F32+G32+H32+I32+J32)*0.005 -> 13.9948 | K33: =(C32+D32+E32+F32+G32+H32+I32+J32+K32)*0.005 -> 13.9948 | L33: =(C32+D32+E32+F32+G32+H32+I32+J32+K32+L32)*0.005 -> 13.9948 | M33: =(C32+D32+E32+F32+G32+H32+I32+J32+K32+L32+M32)*0.005 -> 13.9948 | N33: =(C32+D32+E32+F32+G32+H32+I32+J32+K32+L32+M32+N32)*0.005 -> 13.9948 | O33: =(C32+D32+E32+F32+G32+H32+I32+J32+K32+L32+M32+N32+O32)*0.005 -> 13.9948
A34: 13 | B34: Rica M. Cruz | C34: 200 | D34: 0 | E34: 0 | F34: 0 | L34: 0 | P34: =C34+D34+E34+F34+G34+H34+I34+J34+K34+L34+M34+N34+O34 -> 200 | Q34: =P34/12 -> 16.666667 | S34: =P34+R34 -> 200
C35: Interest per mo. | D35: =(C34+D34)*0.005 -> 1 | E35: =(C34+D34+E34)*0.005 -> 1 | F35: =(+C34+D34+E34+F34)*0.005 -> 1 | G35: =(C34+D34+E34+F34+G34)*0.005 -> 1 | H35: =(C34+D34+E34+F34+G34+H34)*0.005 -> 1 | I35: =(C34+D34+E34+F34+G34+H34+I34)*0.005 -> 1 | J35: =(C34+D34+E34+F34+G34+H34+I34+J34)*0.005 -> 1 | K35: =(C34+D34+E34+F34+G34+H34+I34+J34+K34)*0.005 -> 1 | L35: =(C34+D34+E34+F34+G34+H34+I34+J34+K34+L34)*0.005 -> 1 | M35: =(C34+D34+E34+F34+G34+H34+I34+J34+K34+L34+M34)*0.005 -> 1 | N35: =(C34+D34+E34+F34+G34+H34+I34+J34+K34+L34+M34+N34)*0.005 -> 1 | O35: =(C34+D34+E34+F34+G34+H34+I34+J34+K34+L34+M34+N34+O34)*0.005 -> 1
A36: 14 | B36: Yvo Rafiel Samson | C36: 1249.4 | D36: 300 | E36: 0 | F36: 0 | G36: 0 | H36: 0 | I36: 0 | J36: 0 | K36: 0 | L36: 0 | M36: 0 | N36: 0 | O36: 0 | P36: =C36+D36+E36+F36+G36+H36+I36+J36+K36+L36+M36+N36+O36 -> 1549.4 | Q36: =P36/12 -> 129.11667 | R36: =D37+E37+F37+G37+H37+I37+J37+K37+L37+M37+N37+O37 -> 92.964 | S36: =P36+R36 -> 1642.364
C37: Interest per mo. | D37: =(C36+D36)*0.005 -> 7.747 | E37: =(C36+D36+E36)*0.005 -> 7.747 | F37: =(+C36+D36+E36+F36)*0.005 -> 7.747 | G37: =(C36+D36+E36+F36+G36)*0.005 -> 7.747 | H37: =(C36+D36+E36+F36+G36+H36)*0.005 -> 7.747 | I37: =(C36+D36+E36+F36+G36+H36+I36)*0.005 -> 7.747 | J37: =(C36+D36+E36+F36+G36+H36+I36+J36)*0.005 -> 7.747 | K37: =(C36+D36+E36+F36+G36+H36+I36+J36+K36)*0.005 -> 7.747 | L37: =(C36+D36+E36+F36+G36+H36+I36+J36+K36+L36)*0.005 -> 7.747 | M37: =(C36+D36+E36+F36+G36+H36+I36+J36+K36+L36+M36)*0.005 -> 7.747 | N37: =(C36+D36+E36+F36+G36+H36+I36+J36+K36+L36+M36+N36)*0.005 -> 7.747 | O37: =(C36+D36+E36+F36+G36+H36+I36+J36+K36+L36+M36+N36+O36)*0.005 -> 7.747
S38: Page 1 of 2
B42: TOTAL | C42: =SUM(C10:C41) -> 18802.46 | D42: =SUM(D10:D41) -> 1617.597 | E42: =SUM(E10:E41) -> 98.6973 | F42: =SUM(F10:F41) -> 98.6973 | G42: =SUM(G10:G41) -> 98.6973 | H42: =SUM(H10:H41) -> 98.6973 | I42: =SUM(I10:I41) -> 98.6973 | J42: =SUM(J10:J41) -> 98.6973 | ... S42: =SUM(S10:S41) -> 23606.552
A44: Prepared by: | E44: Checked by: | K44: Noted by: | P44: Approved by:
B47: SHALOU J. BALAO | F47: MARIA GENIA C. SEGUIDO | L47: ARNOLD C. GONZALES | Q47: DEXTER B. JUMAO-AS
B48: SCSCC Secretary | F48: SCSCC Treasurer | L48: General Manager, SCSCC | Q48: Chairman, SCSCC BOD
S51: Page 2 of 2
...

Sheet kiddy2022
A2: SIDLAK CHRISTIAN CHILDREN FUND SAVINGS AND CREDIT COOPERATIVE
A3: CDA Registration No. 9520-1080000000036399 Dated: November 16, 2016
A4: P-2, Brgy. Linao, Ormoc City
A6: COMPUTATION OF SAVINGS DEPOSITS
A7: As of FY 2021
C9: 2021 Savings | D9: Jan | E9: Feb | F9: Mar | G9: Apr | H9: May | I9: Jun | J9: Jul | K9: Aug | L9: Sep | M9: Oct | N9: Nov | O9: Dec | P9: TSAD | Q9: ASAD | R9: Int. on TSAD | S9: Total (SAD + Interest)
A10: 1 | B10: Cort Wensley J. Balao | C10: 2392.7 | E10: 0 | F10: 0 | G10: 0 | H10: 0 | I10: 0 | J10: 0 | K10: 0 | L10: 0 | M10: 0 | N10: 0 | P10: =C10+D10+E10+F10+G10+H10+I10+J10+K10+L10+M10+N10+O10 -> 2392.7 | Q10: =P10/12 -> 199.39167 | R10: =D11+E11+F11+G11+H11+I11+J11+K11+L11+M11+N11+O11 -> 139.9885 | S10: =P10+R10 -> 2532.6885
C11: Interest per mo. | D11: 8.39 | E11: =(C10+D10+E10)*0.005 -> 11.9635 | F11: =(+C10+D10+E10+F10)*0.005 -> 11.9635 | G11: =(C10+D10+E10+F10+G10)*0.005 -> 11.9635 | H11: =(C10+D10+E10+F10+G10+H10)*0.005 -> 11.9635 | I11: =(C10+D10+E10+F10+G10+H10+I10)*0.005 -> 11.9635 | J11: =(C10+D10+E10+F10+G10+H10+I10+J10)*0.005 -> 11.9635 | K11: =(C10+D10+E10+F10+G10+H10+I10+J10+K10)*0.005 -> 11.9635 | L11: =(C10+D10+E10+F10+G10+H10+I10+J10+K10+L10)*0.005 -> 11.9635 | M11: =(C10+D10+E10+F10+G10+H10+I10+J10+K10+L10+M10)*0.005 -> 11.9635 | N11: =(C10+D10+E10+F10+G10+H10+I10+J10+K10+L10+M10+N10)*0.005 -> 11.9635 | O11: =(C10+D10+E10+F10+G10+H10+I10+J10+K10+L10+M10+N10+O10)*0.005 -> 11.9635
C12: `` | D12: 10.81 | E12: =(#REF!+#REF!+#REF!)*0.005 -> #REF! | F12: =(+#REF!+#REF!+#REF!+#REF!)*0.005 -> #REF! | G12: =(#REF!+#REF!+#REF!+#REF!+#REF!)*0.005 -> #REF! | H12: =(#REF!+#REF!+#REF!+#REF!+#REF!+#REF!)*0.005 -> #REF! | I12: =(#REF!+#REF!+#REF!+#REF!+#REF!+#REF!+#REF!)*0.005 -> #REF! | J12: =(#REF!+#REF!+#REF!+#REF!+#REF!+#REF!+#REF!+#REF!)*0.005 -> #REF! | K12: =(#REF!+#REF!+#REF!+#REF!+#REF!+#REF!+#REF!+#REF!+#REF!)*0.005 -> #REF! | L12: =(#REF!+#REF!+#REF!+#REF!+#REF!+#REF!+#REF!+#REF!+#REF!+#REF!)*0.005 -> #REF! | M12: =(#REF!+#REF!+#REF!+#REF!+#REF!+#REF!+#REF!+#REF!+#REF!+#REF!+#REF!)*0.005 -> #REF! | N12: =(#REF!+#REF!+#REF!+#REF!+#REF!+#REF!+#REF!+#REF!+#REF!+#REF!+#REF!+#REF!)*0.005 -> #REF! | O12: =(#REF!+#REF!+#REF!+#REF!+#REF!+#REF!+#REF!+#REF!+#REF!+#REF!+#REF!+#REF!+#REF!)*0.005 -> #REF!
A13: 3 | B13: Demian Sabin C. Jumao-as | C13: 6917.9 | D13: 0 | E13: 0 | F13: 0 | G13: 0 | H13: 0 | I13: 0 | J13: 0 | K13: 0 | L13: 0 | M13: 0 | N13: 0 | P13: =C13+D13+E13+F13+G13+H13+I13+J13+K13+L13+M13+N13+O13 -> 6917.9 | Q13: =P13/12 -> 576.49167 | R13: =D14+E14+F14+G14+H14+I14+J14+K14+L14+M14+N14+O14 -> 405.5345 | S13: =P13+R13 -> 7323.4345
C14: Interest per mo. | D14: 25.05 | E14: =(C13+D13+E13)*0.005 -> 34.5895 | F14: =(+C13+D13+E13+F13)*0.005 -> 34.5895 | G14: =(C13+D13+E13+F13+G13)*0.005 -> 34.5895 | H14: =(C13+D13+E13+F13+G13+H13)*0.005 -> 34.5895 | I14: =(C13+D13+E13+F13+G13+H13+I13)*0.005 -> 34.5895 | J14: =(C13+D13+E13+F13+G13+H13+I13+J13)*0.005 -> 34.5895 | K14: =(C13+D13+E13+F13+G13+H13+I13+J13+K13)*0.005 -> 34.5895 | L14: =(C13+D13+E13+F13+G13+H13+I13+J13+K13+L13)*0.005 -> 34.5895 | M14: =(C13+D13+E13+F13+G13+H13+I13+J13+K13+L13+M13)*0.005 -> 34.5895 | N14: =(C13+D13+E13+F13+G13+H13+I13+J13+K13+L13+M13+N13)*0.005 -> 34.5895 | O14: =(C13+D13+E13+F13+G13+H13+I13+J13+K13+L13+M13+N13+O13)*0.005 -> 34.5895
A15: 4 | B15: Izy Kaizer J. Balao | C15: 3596.59 | E15: 0 | F15: 0 | G15: 0 | H15: 0 | I15: 0 | J15: 0 | K15: 0 | L15: 0 | M15: 0 | N15: 0 | O15: 0 | P15: =C15+D15+E15+F15+G15+H15+I15+J15+K15+L15+M15+N15+O15 -> 3596.59 | Q15: =P15/12 -> 299.71583 | R15: =D16+E16+F16+G16+H16+I16+J16+K16+L16+M16+N16+O16 -> 211.16245 | S15: =P15+R15 -> 3807.7524
C16: Interest per mo. | D16: 13.35 | E16: =(C15+D15+E15)*0.005 -> 17.98295 | F16: =(+C15+D15+E15+F15)*0.005 -> 17.98295 | G16: =(C15+D15+E15+F15+G15)*0.005 -> 17.98295 | H16: =(C15+D15+E15+F15+G15+H15)*0.005 -> 17.98295 | I16: =(C15+D15+E15+F15+G15+H15+I15)*0.005 -> 17.98295 | J16: =(C15+D15+E15+F15+G15+H15+I15+J15)*0.005 -> 17.98295 | K16: =(C15+D15+E15+F15+G15+H15+I15+J15+K15)*0.005 -> 17.98295 | L16: =(C15+D15+E15+F15+G15+H15+I15+J15+K15+L15)*0.005 -> 17.98295 | M16: =(C15+D15+E15+F15+G15+H15+I15+J15+K15+L15+M15)*0.005 -> 17.98295 | N16: =(C15+D15+E15+F15+G15+H15+I15+J15+K15+L15+M15+N15)*0.005 -> 17.98295 | O16: =(C15+D15+E15+F15+G15+H15+I15+J15+K15+L15+M15+N15+O15)*0.005 -> 17.98295
A17: 5 | B17: Alerc Finlay J. Balao | C17: 2420.42 | E17: 0 | F17: 500 | G17: 0 | H17: 0 | I17: 0 | J17: 0 | K17: 0 | L17: 0 | M17: 0 | N17: 0 | O17: 0 | P17: =C17+D17+E17+F17+G17+H17+I17+J17+K17+L17+M17+N17+O17 -> 2920.42 | Q17: =P17/12 -> 243.36833 | R17: =D18+E18+F18+G18+H18+I18+J18+K18+L18+M18+N18+O18 -> 158.1231 | S17: =P17+R17 -> 3078.5431
C18: Interest per mo. | E18: =(C17+D17+E17)*0.005 -> 12.1021 | F18: =(+C17+D17+E17+F17)*0.005 -> 14.6021 | G18: =(C17+D17+E17+F17+G17)*0.005 -> 14.6021 | H18: =(C17+D17+E17+F17+G17+H17)*0.005 -> 14.6021 | I18: =(C17+D17+E17+F17+G17+H17+I17)*0.005 -> 14.6021 | J18: =(C17+D17+E17+F17+G17+H17+I17+J17)*0.005 -> 14.6021 | K18: =(C17+D17+E17+F17+G17+H17+I17+J17+K17)*0.005 -> 14.6021 | L18: =(C17+D17+E17+F17+G17+H17+I17+J17+K17+L17)*0.005 -> 14.6021 | M18: =(C17+D17+E17+F17+G17+H17+I17+J17+K17+L17+M17)*0.005 -> 14.6021 | N18: =(C17+D17+E17+F17+G17+H17+I17+J17+K17+L17+M17+N17)*0.005 -> 14.6021 | O18: =(C17+D17+E17+F17+G17+H17+I17+J17+K17+L17+M17+N17+O17)*0.005 -> 14.6021
A19: 6 | B19: Georgette Ann Cabahug | C19: 50 | D19: 0 | P19: 50 | Q19: =P19/12 -> 4.1666667 | S19: =P19+R19 -> 50
C20: Interest per mo. | D20: =(C19+D19)*0.005 -> 0.25 | E20: =(C19+D19+E19)*0.005 -> 0.25 | F20: =(+C19+D19+E19+F19)*0.005 -> 0.25 | G20: =(C19+D19+E19+F19+G19)*0.005 -> 0.25 | H20: =(C19+D19+E19+F19+G19+H19)*0.005 -> 0.25 | I20: =(C19+D19+E19+F19+G19+H19+I19)*0.005 -> 0.25 | J20: =(C19+D19+E19+F19+G19+H19+I19+J19)*0.005 -> 0.25 | K20: =(C19+D19+E19+F19+G19+H19+I19+J19+K19)*0.005 -> 0.25 | L20: =(C19+D19+E19+F19+G19+H19+I19+J19+K19+L19)*0.005 -> 0.25 | M20: =(C19+D19+E19+F19+G19+H19+I19+J19+K19+L19+M19)*0.005 -> 0.25 | N20: =(C19+D19+E19+F19+G19+H19+I19+J19+K19+L19+M19+N19)*0.005 -> 0.25 | O20: =(C19+D19+E19+F19+G19+H19+I19+J19+K19+L19+M19+N19+O19)*0.005 -> 0.25
A21: 7 | B21: Luna Mikaela C. Apay | C21: 50 | D21: 0 | P21: =C21+D21+E21+F21+G21+H21+I21+J21+K21+L21+M21+N21+O21 -> 50 | Q21: =P21/12 -> 4.1666667 | S21: =P21+R21 -> 50
C22: Interest per mo. | D22: =(C21+D21)*0.005 -> 0.25 | E22: =(C21+D21+E21)*0.005 -> 0.25 | F22: =(+C21+D21+E21+F21)*0.005 -> 0.25 | G22: =(C21+D21+E21+F21+G21)*0.005 -> 0.25 | H22: =(C21+D21+E21+F21+G21+H21)*0.005 -> 0.25 | I22: =(C21+D21+E21+F21+G21+H21+I21)*0.005 -> 0.25 | J22: =(C21+D21+E21+F21+G21+H21+I21+J21)*0.005 -> 0.25 | K22: =(C21+D21+E21+F21+G21+H21+I21+J21+K21)*0.005 -> 0.25 | L22: =(C21+D21+E21+F21+G21+H21+I21+J21+K21+L21)*0.005 -> 0.25 | M22: =(C21+D21+E21+F21+G21+H21+I21+J21+K21+L21+M21)*0.005 -> 0.25 | N22: =(C21+D21+E21+F21+G21+H21+I21+J21+K21+L21+M21+N21)*0.005 -> 0.25 | O22: =(C21+D21+E21+F21+G21+H21+I21+J21+K21+L21+M21+N21+O21)*0.005 -> 0.25
A23: 8 | B23: Mikko Angelo C. Apay | C23: 50 | D23: 0 | P23: =C23+D23+E23+F23+G23+H23+I23+J23+K23+L23+M23+N23+O23 -> 50 | Q23: =P23/12 -> 4.1666667 | S23: =P23+R23 -> 50
C24: Interest per mo. | D24: =(C23+D23)*0.005 -> 0.25 | E24: =(C23+D23+E23)*0.005 -> 0.25 | F24: =(+C23+D23+E23+F23)*0.005 -> 0.25 | G24: =(C23+D23+E23+F23+G23)*0.005 -> 0.25 | H24: =(C23+D23+E23+F23+G23+H23)*0.005 -> 0.25 | I24: =(C23+D23+E23+F23+G23+H23+I23)*0.005 -> 0.25 | J24: =(C23+D23+E23+F23+G23+H23+I23+J23)*0.005 -> 0.25 | K24: =(C23+D23+E23+F23+G23+H23+I23+J23+K23)*0.005 -> 0.25 | L24: =(C23+D23+E23+F23+G23+H23+I23+J23+K23+L23)*0.005 -> 0.25 | M24: =(C23+D23+E23+F23+G23+H23+I23+J23+K23+L23+M23)*0.005 -> 0.25 | N24: =(C23+D23+E23+F23+G23+H23+I23+J23+K23+L23+M23+N23)*0.005 -> 0.25 | O24: =(C23+D23+E23+F23+G23+H23+I23+J23+K23+L23+M23+N23+O23)*0.005 -> 0.25
A25: 9 | B25: Casy Marie D. Cruz | C25: 730.83 | I25: 0 | N25: 0 | P25: =C25+D25+E25+F25+G25+H25+I25+J25+K25+L25+M25+N25+O25 -> 730.83 | Q25: =P25/12 -> 60.9025 | R25: =D26+E26+F26+G26+H26+I26+J26+K26+L26+M26+N26+O26 -> 18.27075 | S25: =P25+R25 -> 749.10075
C26: Interest per mo. | K26: =(C25+D25+E25+F25+G25+H25+I25+J25+K25)*0.005 -> 3.65415 | L26: =(C25+D25+E25+F25+G25+H25+I25+J25+K25+L25)*0.005 -> 3.65415 | M26: =(C25+D25+E25+F25+G25+H25+I25+J25+K25+L25+M25)*0.005 -> 3.65415 | N26: =(C25+D25+E25+F25+G25+H25+I25+J25+K25+L25+M25+N25)*0.005 -> 3.65415 | O26: =(C25+D25+E25+F25+G25+H25+I25+J25+K25+L25+M25+N25+O25)*0.005 -> 3.65415
A27: 10 | B27: Marissa alvarado | C27: 50 | D27: 0 | J27: 0 | M27: 0 | P27: =C27+D27+E27+F27+G27+H27+I27+J27+K27+L27+M27+N27+O27 -> 50 | Q27: =P27/12 -> 4.1666667 | S27: =P27+R27 -> 50
C28: Interest per mo. | D28: =(C27+D27)*0.005 -> 0.25 | E28: =(C27+D27+E27)*0.005 -> 0.25 | F28: =(+C27+D27+E27+F27)*0.005 -> 0.25 | G28: =(C27+D27+E27+F27+G27)*0.005 -> 0.25 | H28: =(C27+D27+E27+F27+G27+H27)*0.005 -> 0.25 | I28: =(C27+D27+E27+F27+G27+H27+I27)*0.005 -> 0.25 | J28: =(C27+D27+E27+F27+G27+H27+I27+J27)*0.005 -> 0.25 | K28: =(C27+D27+E27+F27+G27+H27+I27+J27+K27)*0.005 -> 0.25 | L28: =(C27+D27+E27+F27+G27+H27+I27+J27+K27+L27)*0.005 -> 0.25 | M28: =(C27+D27+E27+F27+G27+H27+I27+J27+K27+L27+M27)*0.005 -> 0.25 | N28: =(C27+D27+E27+F27+G27+H27+I27+J27+K27+L27+M27+N27)*0.005 -> 0.25 | O28: =(C27+D27+E27+F27+G27+H27+I27+J27+K27+L27+M27+N27+O27)*0.005 -> 0.25
A29: 11 | B29: Krissel Alvarado | C29: 50 | D29: 0 | P29: =C29+D29+E29+F29+G29+H29+I29+J29+K29+L29+M29+N29+O29 -> 50 | Q29: =P29/12 -> 4.1666667 | S29: =P29+R29 -> 50
C30: Interest per mo. | D30: =(C29+D29)*0.005 -> 0.25 | E30: =(C29+D29+E29)*0.005 -> 0.25 | F30: =(+C29+D29+E29+F29)*0.005 -> 0.25 | G30: =(C29+D29+E29+F29+G29)*0.005 -> 0.25 | H30: =(C29+D29+E29+F29+G29+H29)*0.005 -> 0.25 | I30: =(C29+D29+E29+F29+G29+H29+I29)*0.005 -> 0.25 | J30: =(C29+D29+E29+F29+G29+H29+I29+J29)*0.005 -> 0.25 | K30: =(C29+D29+E29+F29+G29+H29+I29+J29+K29)*0.005 -> 0.25 | L30: =(C29+D29+E29+F29+G29+H29+I29+J29+K29+L29)*0.005 -> 0.25 | M30: =(C29+D29+E29+F29+G29+H29+I29+J29+K29+L29+M29)*0.005 -> 0.25 | N30: =(C29+D29+E29+F29+G29+H29+I29+J29+K29+L29+M29+N29)*0.005 -> 0.25 | O30: =(C29+D29+E29+F29+G29+H29+I29+J29+K29+L29+M29+N29+O29)*0.005 -> 0.25
A31: 12 | B31: Serg Mateo M. Villamor | C31: 2952.9 | D31: 0 | E31: 0 | F31: 0 | J31: 0 | K31: 0 | L31: 0 | M31: 0 | N31: 0 | O31: 0 | P31: =C31+D31+E31+F31+G31+H31+I31+J31+K31+L31+M31+N31+O31 -> 2952.9 | Q31: =P31/12 -> 246.075 | R31: =D32+E32+F32+G32+H32+I32+J32+K32+L32+M32+N32+O32 -> 162.4095 | S31: =P31+R31 -> 3115.3095
C32: Interest per mo. | E32: =(C31+D31+E31)*0.005 -> 14.7645 | F32: =(+C31+D31+E31+F31)*0.005 -> 14.7645 | G32: =(C31+D31+E31+F31+G31)*0.005 -> 14.7645 | H32: =(C31+D31+E31+F31+G31+H31)*0.005 -> 14.7645 | I32: =(C31+D31+E31+F31+G31+H31+I31)*0.005 -> 14.7645 | J32: =(C31+D31+E31+F31+G31+H31+I31+J31)*0.005 -> 14.7645 | K32: =(C31+D31+E31+F31+G31+H31+I31+J31+K31)*0.005 -> 14.7645 | L32: =(C31+D31+E31+F31+G31+H31+I31+J31+K31+L31)*0.005 -> 14.7645 | M32: =(C31+D31+E31+F31+G31+H31+I31+J31+K31+L31+M31)*0.005 -> 14.7645 | N32: =(C31+D31+E31+F31+G31+H31+I31+J31+K31+L31+M31+N31)*0.005 -> 14.7645 | O32: =(C31+D31+E31+F31+G31+H31+I31+J31+K31+L31+M31+N31+O31)*0.005 -> 14.7645
A33: 13 | B33: Rica M. Cruz | C33: 200 | D33: 0 | E33: 0 | F33: 0 | L33: 0 | P33: =C33+D33+E33+F33+G33+H33+I33+J33+K33+L33+M33+N33+O33 -> 200 | Q33: =P33/12 -> 16.666667 | S33: =P33+R33 -> 200
C34: Interest per mo. | D34: =(C33+D33)*0.005 -> 1 | E34: =(C33+D33+E33)*0.005 -> 1 | F34: =(+C33+D33+E33+F33)*0.005 -> 1 | G34: =(C33+D33+E33+F33+G33)*0.005 -> 1 | H34: =(C33+D33+E33+F33+G33+H33)*0.005 -> 1 | I34: =(C33+D33+E33+F33+G33+H33+I33)*0.005 -> 1 | J34: =(C33+D33+E33+F33+G33+H33+I33+J33)*0.005 -> 1 | K34: =(C33+D33+E33+F33+G33+H33+I33+J33+K33)*0.005 -> 1 | L34: =(C33+D33+E33+F33+G33+H33+I33+J33+K33+L33)*0.005 -> 1 | M34: =(C33+D33+E33+F33+G33+H33+I33+J33+K33+L33+M33)*0.005 -> 1 | N34: =(C33+D33+E33+F33+G33+H33+I33+J33+K33+L33+M33+N33)*0.005 -> 1 | O34: =(C33+D33+E33+F33+G33+H33+I33+J33+K33+L33+M33+N33+O33)*0.005 -> 1
A35: 14 | B35: Yvo Rafiel Samson | C35: 1642.36 | E35: 0 | F35: 255 | G35: 250 | H35: 0 | I35: 0 | J35: 0 | K35: 0 | L35: 0 | M35: 0 | N35: 0 | O35: 0 | P35: =C35+D35+E35+F35+G35+H35+I35+J35+K35+L35+M35+N35+O35 -> 2147.36 | Q35: =P35/12 -> 178.94667 | R35: =D36+E36+F36+G36+H36+I36+J36+K36+L36+M36+N36+O36 -> 122.5416 | S35: =P35+R35 -> 2269.9016
C36: Interest per mo. | D36: =(C35+D35)*0.005 -> 8.2118 | E36: =(C35+D35+E35)*0.005 -> 8.2118 | F36: =(+C35+D35+E35+F35)*0.005 -> 9.4868 | G36: =(C35+D35+E35+F35+G35)*0.005 -> 10.7368 | H36: =(C35+D35+E35+F35+G35+H35)*0.005 -> 10.7368 | I36: =(C35+D35+E35+F35+G35+H35+I35)*0.005 -> 10.7368 | J36: =(C35+D35+E35+F35+G35+H35+I35+J35)*0.005 -> 10.7368 | K36: =(C35+D35+E35+F35+G35+H35+I35+J35+K35)*0.005 -> 10.7368 | L36: =(C35+D35+E35+F35+G35+H35+I35+J35+K35+L35)*0.005 -> 10.7368 | M36: =(C35+D35+E35+F35+G35+H35+I35+J35+K35+L35+M35)*0.005 -> 10.7368 | N36: =(C35+D35+E35+F35+G35+H35+I35+J35+K35+L35+M35+N35)*0.005 -> 10.7368 | O36: =(C35+D35+E35+F35+G35+H35+I35+J35+K35+L35+M35+N35+O35)*0.005 -> 10.7368
S37: Page 1 of 2
B41: TOTAL | C41: =SUM(C10:C40) -> 21103.7 | D41: =SUM(D10:D40) -> 68.0618 | E41: =SUM(E10:E40) -> #REF! | F41: =SUM(F10:F40) -> #REF! | G41: =SUM(G10:G40) -> #REF! | H41: =SUM(H10:H40) -> #REF! | I41: =SUM(I10:I40) -> #REF! | J41: =SUM(J10:J40) -> #REF! | ... S41: =SUM(S10:S40) -> 23326.73
A43: Prepared by: | E43: Checked by: | K43: Noted by: | P43: Approved by:
B46: SHALOU J. BALAO | F46: MARIA GENIA C. SEGUIDO | L46: ARNOLD C. GONZALES | Q46: DEXTER B. JUMAO-AS
B47: SCSCC Secretary | F47: SCSCC Treasurer | L47: General Manager, SCSCC | Q47: Chairman, SCSCC BOD
S50: Page 2 of 2
P54: Regular | Q54: =18 -> 18 | R54: =S10+S13+S15+S17+S19+S21+S23+S25+S27+S29+S31+S33+#REF!+#REF!+#REF!+#REF!+#REF!+S35 -> #REF!
...

Sheet KIDDY2023
A2: SIDLAK CHRISTIAN CHILDREN FUND SAVINGS AND CREDIT COOPERATIVE
A3: CDA Registration No. 9520-1080000000036399 Dated: November 16, 2016
A4: P-2, Brgy. Linao, Ormoc City
A6: COMPUTATION OF SAVINGS DEPOSITS
A7: As of FY 2021
C9: 2022 Savings | D9: Jan | E9: Feb | F9: Mar | G9: Apr | H9: May | I9: Jun | J9: withdrawal | K9: Jul | L9: Aug | M9: Sep | N9: Oct | O9: Nov | P9: Dec | Q9: TSAD | R9: ASAD | S9: Int. on TSAD | T9: Total (SAD + Interest)
A10: 1 | B10: Cort Wensley J. Balao | C10: =2392.7+139.99 -> 2532.69 | E10: 0 | F10: 0 | G10: 0 | H10: 0 | I10: 0 | K10: 0 | L10: 0 | M10: 0 | N10: 0 | O10: 0 | Q10: =C10+D10+E10+F10+G10+H10+I10+K10+L10+M10+N10+O10+P10 -> 2532.69 | R10: =Q10/12 -> 211.0575 | S10: =D11+E11+F11+G11+H11+I11+K11+L11+M11+N11+O11+P11 -> 147.68795 | T10: =Q10+S10 -> 2680.378
C11: Interest per mo. | D11: 8.39 | E11: =(C10+D10+E10)*0.005 -> 12.66345 | F11: =(+C10+D10+E10+F10)*0.005 -> 12.66345 | G11: =(C10+D10+E10+F10+G10)*0.005 -> 12.66345 | H11: =(C10+D10+E10+F10+G10+H10)*0.005 -> 12.66345 | I11: =(C10+D10+E10+F10+G10+H10+I10)*0.005 -> 12.66345 | K11: =(C10+D10+E10+F10+G10+H10+I10+K10)*0.005 -> 12.66345 | L11: =(C10+D10+E10+F10+G10+H10+I10+K10+L10)*0.005 -> 12.66345 | M11: =(C10+D10+E10+F10+G10+H10+I10+K10+L10+M10)*0.005 -> 12.66345 | N11: =(C10+D10+E10+F10+G10+H10+I10+K10+L10+M10+N10)*0.005 -> 12.66345 | O11: =(C10+D10+E10+F10+G10+H10+I10+K10+L10+M10+N10+O10)*0.005 -> 12.66345 | P11: =(C10+D10+E10+F10+G10+H10+I10+K10+L10+M10+N10+O10+P10)*0.005 -> 12.66345
A12: 2 | B12: Brett Colin J. Balao | C12: 2502.84
C13: Interest per mo.
A14: 3 | B14: Demian Sabin C. Jumao-as | C14: =6917.9+405.53 -> 7323.43 | D14: 0 | E14: 0 | F14: 500 | G14: 0 | H14: 0 | I14: 0 | K14: 0 | L14: 0 | M14: 0 | N14: 0 | O14: 0 | Q14: =C14+D14+E14+F14+G14+H14+I14+K14+L14+M14+N14+O14+P14 -> 7823.43 | R14: =Q14/12 -> 651.9525 | S14: =D15+E15+F15+G15+H15+I15+K15+L15+M15+N15+O15+P15 -> 452.83865 | T14: =Q14+S14 -> 8276.2686
