Workbook

Sheet SUMMARY
A2: BRANCH NAME:
A3: FOR THE MONTH OF: JULY
A5: GROSS SALES | D5: COGS | G5: DELIVERIES | J5: B.O | M5: ENDING INVENTORY
A6: CATEGORIES | B6: TOTAL | D6: CATEGORIES | E6: TOTAL | G6: CATEGORIES | H6: TOTAL | J6: CATEGORIES | K6: TOTAL | M6: CATEGORIES | N6: TOTAL
B7: AMOUNT | E7: AMOUNT | H7: AMOUNT | K7: AMOUNT | N7: AMOUNT
A8: DAILY | B8: =GROSS!CA55 -> 512383 | D8: DAILY | E8: ='DAILY COGS'!CA55 -> 332893.88 | G8: DAILY | H8: =DELIVERIES!CA55 -> 335172.5 | J8: DAILY | K8: =B.O!CA55 -> 0 | M8: DAILY | N8: ='MONTHLY INV.'!K30 -> 18206.5
A9: WEEKLY | B9: ='WEEKLY INV.'!T121 -> 512383 | D9: WEEKLY | E9: ='WEEKLY INV.'!P121 -> 332893.88 | G9: WEEKLY | H9: ='WEEKLY INV.'!F121 -> 335172.5 | J9: WEEKLY | K9: ='WEEKLY INV.'!H121 -> 0 | M9: WEEKLY | N9: ='WEEKLY INV.'!K119 -> 18206.5
A10: MONTHLY | B10: ='MONTHLY INV.'!T30 -> 512383 | D10: MONTHLY | E10: ='MONTHLY INV.'!P30 -> 332893.88 | G10: MONTHLY | H10: ='MONTHLY INV.'!F30 -> 335172.5 | J10: MONTHLY | K10: ='MONTHLY INV.'!H30 -> 0 | M10: MONTHLY | N10: ='MONTHLY INV.'!K30 -> 18206.5
B11: =B10-'income statement'!C19 -> 0 | E11: =E9-E8 -> 0

Sheet DAILY SUMMARY
A1: CRISPY KING FOOD STATION
A2: DAILY SALES SUMMARY — JULY 2026
A3: DAY | B3: DATE | C3: GROSS SALES | D3: LESS EXPENSES | E3: NET SALES | F3: CASH DEPOSIT | G3: OVER/SHORT | H3: TOTAL OPEX | I3: TOTAL CAPEX | J3: TOTAL PURCHASES | K3: TOTAL DELIVERIES | L3: REMARKS
A4: 1 | B4: ='1'!T3 -> 46204 | C4: ='1'!B33 -> 14797 | D4: ='1'!B34 -> 5970 | E4: ='1'!B35 -> 8827 | F4: ='1'!B36 -> 8827 | G4: ='1'!B37 -> 0 | H4: ='1'!T30 -> 4270 | I4: ='1'!W30 -> 0 | J4: ='1'!W22 -> 1700 | K4: ='1'!AB18 -> 9220
A5: 2 | B5: ='2'!T3 -> 46205 | C5: ='2'!B33 -> 17889 | D5: ='2'!B34 -> 3439 | E5: ='2'!B35 -> 14450 | F5: ='2'!B36 -> 14450 | G5: ='2'!B37 -> 0 | H5: ='2'!T30 -> 1284 | I5: ='2'!W30 -> 60 | J5: ='2'!W22 -> 2095 | K5: ='2'!AB18 -> 6430
A6: 3 | B6: ='3'!T3 -> 46206 | C6: ='3'!B33 -> 16664 | D6: ='3'!B34 -> 5491 | E6: ='3'!B35 -> 11173 | F6: ='3'!B36 -> 11181.5 | G6: ='3'!B37 -> 8.5 | H6: ='3'!T30 -> 1091 | I6: ='3'!W30 -> 0 | J6: ='3'!W22 -> 4400 | K6: ='3'!AB18 -> 11134
A7: 4 | B7: ='4'!T3 -> 46207 | C7: ='4'!B33 -> 12936 | D7: ='4'!B34 -> 10512.5 | E7: ='4'!B35 -> 2423.5 | F7: ='4'!B36 -> 2424 | G7: ='4'!B37 -> 0.5 | H7: ='4'!T30 -> 0 | I7: ='4'!W30 -> 90 | J7: ='4'!W22 -> 1360 | K7: ='4'!AB18 -> 22005
A8: 5 | B8: ='5'!T3 -> 46208 | C8: ='5'!B33 -> 19041 | D8: ='5'!B34 -> 6767.5 | E8: ='5'!B35 -> 12273.5 | F8: ='5'!B36 -> 12279 | G8: ='5'!B37 -> 5.5 | H8: ='5'!T30 -> 4270 | I8: ='5'!W30 -> 500 | J8: ='5'!W22 -> 1997.5 | K8: ='5'!AB18 -> 0
A9: 6 | B9: ='6'!T3 -> 46209 | C9: ='6'!B33 -> 16561 | D9: ='6'!B34 -> 7360 | E9: ='6'!B35 -> 9201 | F9: ='6'!B36 -> 9207.5 | G9: ='6'!B37 -> 6.5 | H9: ='6'!T30 -> 5185 | I9: ='6'!W30 -> 60 | J9: ='6'!W22 -> 2115 | K9: ='6'!AB18 -> 5030
A10: 7 | B10: ='7'!T3 -> 46210 | C10: ='7'!B33 -> 14102 | D10: ='7'!B34 -> 7694 | E10: ='7'!B35 -> 6408 | F10: ='7'!B36 -> 6410 | G10: ='7'!B37 -> 2 | H10: ='7'!T30 -> 3660 | I10: ='7'!W30 -> 530 | J10: ='7'!W22 -> 3504 | K10: ='7'!AB18 -> 8160
A11: 8 | B11: ='8'!T3 -> 46211 | C11: ='8'!B33 -> 18444 | D11: ='8'!B34 -> 8305.29 | E11: ='8'!B35 -> 10138.71 | F11: ='8'!B36 -> 10141 | G11: ='8'!B37 -> 2.29 | H11: ='8'!T30 -> 6775.29 | I11: ='8'!W30 -> 0 | J11: ='8'!W22 -> 1530 | K11: ='8'!AB18 -> 7611
A12: 9 | B12: ='9'!T3 -> 46212 | C12: ='9'!B33 -> 18214 | D12: ='9'!B34 -> 9968.25 | E12: ='9'!B35 -> 8245.75 | F12: ='9'!B36 -> 8250 | G12: ='9'!B37 -> 4.25 | H12: ='9'!T30 -> 8378.25 | I12: ='9'!W30 -> 60 | J12: ='9'!W22 -> 1530 | K12: ='9'!AB18 -> 9254
A13: 10 | B13: ='10'!T3 -> 46213 | C13: ='10'!B33 -> 15286 | D13: ='10'!B34 -> 8505 | E13: ='10'!B35 -> 6781 | F13: ='10'!B36 -> 6781 | G13: ='10'!B37 -> 0 | H13: ='10'!T30 -> 5000 | I13: ='10'!W30 -> 0 | J13: ='10'!W22 -> 3505 | K13: ='10'!AB18 -> 9520
A14: 11 | B14: ='11'!T3 -> 46214 | C14: ='11'!B33 -> 17440 | D14: ='11'!B34 -> 15145.5 | E14: ='11'!B35 -> 2294.5 | F14: ='11'!B36 -> 2295 | G14: ='11'!B37 -> 0.5 | H14: ='11'!T30 -> 4200 | I14: ='11'!W30 -> 60 | J14: ='11'!W22 -> 1823 | K14: ='11'!AB18 -> 21764
A15: 12 | B15: ='12'!T3 -> 46215 | C15: ='12'!B33 -> 20150 | D15: ='12'!B34 -> 2552.14 | E15: ='12'!B35 -> 17597.86 | F15: ='12'!B36 -> 17603 | G15: ='12'!B37 -> 5.14 | H15: ='12'!T30 -> 1022.14 | I15: ='12'!W30 -> 0 | J15: ='12'!W22 -> 1530 | K15: ='12'!AB18 -> 0
A16: 13 | B16: ='13'!T3 -> 46216 | C16: ='13'!B33 -> 15248 | D16: ='13'!B34 -> 3090 | E16: ='13'!B35 -> 12158 | F16: ='13'!B36 -> 12159 | G16: ='13'!B37 -> 1 | H16: ='13'!T30 -> 275 | I16: ='13'!W30 -> 90 | J16: ='13'!W22 -> 2725 | K16: ='13'!AB18 -> 10531
A17: 14 | B17: ='14'!T3 -> 46217 | C17: ='14'!B33 -> 15740 | D17: ='14'!B34 -> 10380.5 | E17: ='14'!B35 -> 5359.5 | F17: ='14'!B36 -> 5359.5 | G17: ='14'!B37 -> 0 | H17: ='14'!T30 -> 6909.5 | I17: ='14'!W30 -> 0 | J17: ='14'!W22 -> 3471 | K17: ='14'!AB18 -> 7160
A18: 15 | B18: ='15'!T3 -> 46218 | C18: ='15'!B33 -> 18654 | D18: ='15'!B34 -> 4627.87 | E18: ='15'!B35 -> 14026.13 | F18: ='15'!B36 -> 14026 | G18: ='15'!B37 -> -0.13 | H18: ='15'!T30 -> 3007.87 | I18: ='15'!W30 -> 90 | J18: ='15'!W22 -> 1530 | K18: ='15'!AB18 -> 8614
A19: 16 | B19: ='16'!T3 -> 46219 | C19: ='16'!B33 -> 17527 | D19: ='16'!B34 -> 5675 | E19: ='16'!B35 -> 11852 | F19: ='16'!B36 -> 11853 | G19: ='16'!B37 -> 1 | H19: ='16'!T30 -> 4060 | I19: ='16'!W30 -> 0 | J19: ='16'!W22 -> 1615 | K19: ='16'!AB18 -> 8120
A20: 17 | B20: ='17'!T3 -> 46220 | C20: ='17'!B33 -> 17898 | D20: ='17'!B34 -> 7460.69 | E20: ='17'!B35 -> 10437.31 | F20: ='17'!B36 -> 10438 | G20: ='17'!B37 -> 0.69 | H20: ='17'!T30 -> 4200.69 | I20: ='17'!W30 -> 90 | J20: ='17'!W22 -> 3170 | K20: ='17'!AB18 -> 12270
A21: 18 | B21: ='18'!T3 -> 38916 | C21: ='18'!B33 -> 16732 | D21: ='18'!B34 -> 14353.57 | E21: ='18'!B35 -> 2378.43 | F21: ='18'!B36 -> 2379 | G21: ='18'!B37 -> 0.57 | H21: ='18'!T30 -> 11.07 | I21: ='18'!W30 -> 30 | J21: ='18'!W22 -> 1700 | K21: ='18'!AB18 -> 22701
A22: 19 | B22: ='19'!T3 -> 46222 | C22: ='19'!B33 -> 20302 | D22: ='19'!B34 -> 2210.87 | E22: ='19'!B35 -> 18091.13 | F22: ='19'!B36 -> 18092 | G22: ='19'!B37 -> 0.87 | H22: ='19'!T30 -> 85.87 | I22: ='19'!W30 -> 0 | J22: ='19'!W22 -> 2125 | K22: ='19'!AB18 -> 0
A23: 20 | B23: ='20'!T3 -> 46223 | C23: ='20'!B33 -> 15110 | D23: ='20'!B34 -> 2175.95 | E23: ='20'!B35 -> 12934.05 | F23: ='20'!B36 -> 12936 | G23: ='20'!B37 -> 1.95 | H23: ='20'!T30 -> 555.95 | I23: ='20'!W30 -> 90 | J23: ='20'!W22 -> 1530 | K23: ='20'!AB18 -> 8704
A24: 21 | B24: ='21'!T3 -> 46224 | C24: ='21'!B33 -> 15951 | D24: ='21'!B34 -> 7877.82 | E24: ='21'!B35 -> 8073.18 | F24: ='21'!B36 -> 8075 | G24: ='21'!B37 -> 1.82 | H24: ='21'!T30 -> 1564.82 | I24: ='21'!W30 -> 135 | J24: ='21'!W22 -> 6178 | K24: ='21'!AB18 -> 12380
A25: 22 | B25: ='22'!T3 -> 46225 | C25: ='22'!B33 -> 15625 | D25: ='22'!B34 -> 3679 | E25: ='22'!B35 -> 11946 | F25: ='22'!B36 -> 11947 | G25: ='22'!B37 -> 1 | H25: ='22'!T30 -> 1444 | I25: ='22'!W30 -> 0 | J25: ='22'!W22 -> 2235 | K25: ='22'!AB18 -> 8004
A26: 23 | B26: ='23'!T3 -> 46226 | C26: ='23'!B33 -> 16503 | D26: ='23'!B34 -> 8999.07 | E26: ='23'!B35 -> 7503.93 | F26: ='23'!B36 -> 7505 | G26: ='23'!B37 -> 1.07 | H26: ='23'!T30 -> 7239.07 | I26: ='23'!W30 -> 60 | J26: ='23'!W22 -> 1700 | K26: ='23'!AB18 -> 7740
A27: 24 | B27: ='24'!T3 -> 45862 | C27: ='24'!B33 -> 17337 | D27: ='24'!B34 -> 6551.75 | E27: ='24'!B35 -> 10785.25 | F27: ='24'!B36 -> 10785.25 | G27: ='24'!B37 -> 0 | H27: ='24'!T30 -> 2961.75 | I27: ='24'!W30 -> 0 | J27: ='24'!W22 -> 3590 | K27: ='24'!AB18 -> 7311
A28: 25 | B28: ='25'!T3 -> 46228 | C28: ='25'!B33 -> 14880 | D28: ='25'!B34 -> 11383.57 | E28: ='25'!B35 -> 3496.43 | F28: ='25'!B36 -> 3482 | G28: ='25'!B37 -> -14.43 | H28: ='25'!T30 -> 11.07 | I28: ='25'!W30 -> 60 | J28: ='25'!W22 -> 1700 | K28: ='25'!AB18 -> 21094
A29: 26 | B29: ='26'!T3 -> 46229 | C29: ='26'!B33 -> 18894 | D29: ='26'!B34 -> 6632.99 | E29: ='26'!B35 -> 12261.01 | F29: ='26'!B36 -> 12263.25 | G29: ='26'!B37 -> 2.24 | H29: ='26'!T30 -> 4932.99 | I29: ='26'!W30 -> 0 | J29: ='26'!W22 -> 1700 | K29: ='26'!AB18 -> 0
A30: 27 | B30: ='27'!T3 -> 46230 | C30: ='27'!B33 -> 15393 | D30: ='27'!B34 -> 2110 | E30: ='27'!B35 -> 13283 | F30: ='27'!B36 -> 13293 | G30: ='27'!B37 -> 10 | H30: ='27'!T30 -> 0 | I30: ='27'!W30 -> 90 | J30: ='27'!W22 -> 2020 | K30: ='27'!AB18 -> 9780
A31: 28 | B31: ='28'!T3 -> 46231 | C31: ='28'!B33 -> 15154 | D31: ='28'!B34 -> 6109.75 | E31: ='28'!B35 -> 9044.25 | F31: ='28'!B36 -> 9050 | G31: ='28'!B37 -> 5.75 | H31: ='28'!T30 -> 1639.75 | I31: ='28'!W30 -> 0 | J31: ='28'!W22 -> 4470 | K31: ='28'!AB18 -> 9335
A32: 29 | B32: ='29'!T3 -> 46232 | C32: ='29'!B33 -> 12776 | D32: ='29'!B34 -> 1873 | E32: ='29'!B35 -> 10903 | F32: ='29'!B36 -> 10903 | G32: ='29'!B37 -> 0 | H32: ='29'!T30 -> 198 | I32: ='29'!W30 -> 60 | J32: ='29'!W22 -> 1615 | K32: ='29'!AB18 -> 7820
A33: 30 | B33: ='30'!T3 -> 46233 | C33: ='30'!B33 -> 15386 | D33: ='30'!B34 -> 2015 | E33: ='30'!B35 -> 13371 | F33: ='30'!B36 -> 13372 | G33: ='30'!B37 -> 1 | H33: ='30'!T30 -> 15 | I33: ='30'!W30 -> 0 | J33: ='30'!W22 -> 2000 | K33: ='30'!AB18 -> 6750
A34: 31 | B34: ='31'!T3 -> 46234 | C34: ='31'!B33 -> 15749 | D34: ='31'!B34 -> 3009 | E34: ='31'!B35 -> 12740 | F34: ='31'!B36 -> 12746 | G34: ='31'!B37 -> 6 | H34: ='31'!T30 -> 0 | I34: ='31'!W30 -> 0 | J34: ='31'!W22 -> 3009 | K34: ='31'!AB18 -> 8084
A35: MONTHLY TOTAL | C35: =SUM(C4:C34) -> 512383 | D35: =SUM(D4:D34) -> 201925.58 | E35: =SUM(E4:E34) -> 310457.42 | F35: =SUM(F4:F34) -> 310513 | G35: =SUM(G4:G34) -> 55.58 | H35: =SUM(H4:H34) -> 84248.08 | I35: =SUM(I4:I34) -> 2155 | J35: =SUM(J4:J34) -> 75172.5 | K35: =SUM(K4:K34) -> 286526
A37: 📋 HOW TO USE: Enter data directly in each Day tab (sheets 1–31). Branch name & Date entered there will auto-appear in the Date column above. Gross Sales, Expenses, Net Sales & Over/Short pull automatically.

Sheet income statement
B3: BRANCH
B4: INCOME STATEMENT
B5: MONTH
A7: PARTICULARS:
B8: SPECIAL CUT | C8: =GROSS!G55 -> 300600
B9: PREMIUM CUT | C9: =GROSS!D55 -> 0
B10: Neck | C10: =GROSS!P55 -> 33384
B11: Rice | C11: =GROSS!V55 -> 88110
B12: Softdrinks | C12: =GROSS!BY55 -> 50689
B13: Ngohiong | C13: =GROSS!J55 -> 4056
B14: Atsara | C14: =GROSS!AE55 -> 2570
B15: Siomai | C15: =GROSS!S55 -> 0
B16: Bola-Bola | C16: =GROSS!Y55 -> 11800
B17: Lumpia | C17: =GROSS!AB55 -> 9224
B18: c-fillet | C18: =GROSS!M55 -> 11950
A19: GROSS SALES: | C19: =SUM(C8:C18) -> 512383
A21: LESS: | B21: Cost of Good Sold | C21: ='DAILY COGS'!CA55 -> 332893.88 | E21: =C21/C19 -> 0.64969735
A23: GROSS PROFIT | C23: =C19-C21 -> 179489.12
A24: LESS: OPERATING EXPENSES
B25: =OPEX!B50 -> LPG | C25: =OPEX!D50 -> 16996 | D25: =C25/C19 -> 0.033170499
B26: =OPEX!B51 -> BREADING | C26: =OPEX!D51 -> 9546 | D26: =C26/C19 -> 0.018630595
B27: =OPEX!B52 -> OIL | C27: =OPEX!D52 -> 15114 | D27: =C27/C19 -> 0.029497466
B28: =OPEX!B53 -> GRAVY | C28: =OPEX!D53 -> 3240 | D28: =C28/C19 -> 0.0063233948
B29: =OPEX!B54 -> SALARY | C29: =OPEX!D54 -> 43550 | D29: =C29/C19 -> 0.084995013
B30: =OPEX!B55 -> HOLIDAY | C30: =OPEX!D55 -> 0 | D30: =C30/C19 -> 0
B31: =OPEX!B56 -> OVERTIME | C31: =OPEX!D56 -> 0 | D31: =C31/C19 -> 0
B32: =OPEX!B57 -> TL ALLOWANCE | C32: =OPEX!D57 -> 1300 | D32: =C32/C19 -> 0.0025371646
B33: =OPEX!B58 -> Admin / Office Supplies | C33: =OPEX!D58 -> 1646.72 | D33: =C33/C19 -> 0.0032138459
B34: =OPEX!B59 -> 13th month | C34: =OPEX!D59 -> 4792.74 | D34: =C34/C19 -> 0.0093538232
B35: =OPEX!B60 -> pag ibig | C35: =OPEX!D60 -> 275 | D35: =C35/C19 -> 0.00053670789
B36: =OPEX!B61 -> SSS | C36: =OPEX!D61 -> 1428.86 | D36: =C36/C19 -> 0.0027886561
B37: =OPEX!B62 -> PHIL HEALTH | C37: =OPEX!D62 -> 346.43 | D37: =C37/C19 -> 0.00067611533
B38: =OPEX!B63 -> SIOMAI SAUCE | C38: =OPEX!D63 -> 0 | D38: =C38/C19 -> 0
B39: =OPEX!B64 -> TRANSPO. | C39: =OPEX!D64 -> 0 | D39: =C39/C19 -> 0
B40: =OPEX!B65 -> CHARGE DEPOSIT | C40: =OPEX!D65 -> 0 | D40: =C40/C19 -> 0
B41: =OPEX!B66 -> RENTAL | C41: =OPEX!D66 -> 28000 | D41: =C41/C19 -> 0.054646622
B42: =OPEX!B67 -> LIGHT | C42: =OPEX!D67 -> 9007.87 | D42: =C42/C19 -> 0.017580345
B43: =OPEX!B68 -> WATER | C43: =OPEX!D68 -> 2160 | D43: =C43/C19 -> 0.0042155965
B44: =OPEX!B69 -> BIR/TAXES | C44: =OPEX!D69 -> 4732.69 | D44: =C44/C19 -> 0.0092366257
B45: =OPEX!B70 -> supot/roll bag/T-bag | C45: =OPEX!D70 -> 2166.75 | D45: =C45/C19 -> 0.0042287703
...

Sheet DAILY COGS
A1: CRISPY KING FOOD STATION : | E1: =GROSS!E1 -> BRANCH | BN1: DRINKS
A2: Daily Monitoring of COGS
A3: For the Month of: | C3: 45473
A5: WEEK- 1 | B5: PREMIUM - CUT | E5: ='1'!A7 -> SPECIAL CUT | H5: ='1'!A8 -> NGOHIONG | K5: ='1'!A15 -> Chicken Fillet | N5: NECK | Q5: SIOMAI | T5: RICE | W5: BOLA-BOLA | Z5: LUMPIA | AC5: ATSARA | AI5: SUBTOTAL | AM5: ='1'!A17 -> 8 oz | AP5: 12 OZ | AS5: WATER 350 ML | AV5: WATER 500 ML | AY5: PANALO | BB5: swakto | BE5: Calamansi Juice | BH5: ='1'!A23 -> GATORADE | BK5: TROPICANA | BN5: STING | BQ5: ='1'!A19 -> 1 LITER | BT5: ='1'!A20 -> 1.5 L | BW5: SUBTOTAL FOR DRINKS | CA5: TOTAL | CC5: AUDIT GROSS | CD5: DIFFERENCE
A6: DATE | B6: QTY | C6: UP | D6: AMOUNT | E6: QTY | F6: UP | G6: AMOUNT | H6: QTY | I6: UP | J6: AMOUNT | K6: QTY | L6: UP | M6: AMOUNT | N6: QTY | O6: UP | P6: AMOUNT | Q6: QTY | R6: UP | S6: AMOUNT | T6: QTY | U6: UP | V6: AMOUNT | W6: QTY | X6: UP | Y6: AMOUNT | Z6: QTY | AA6: UP | AB6: AMOUNT | AC6: QTY | AD6: UP | AE6: AMOUNT | AF6: QTY | AG6: UP | AH6: AMOUNT | AK6: AMOUNT | AM6: QTY | AN6: UP | AO6: AMOUNT | AP6: QTY | AQ6: UP | AR6: AMOUNT | AS6: QTY | AT6: UP | AU6: AMOUNT | AV6: QTY | AW6: UP | AX6: AMOUNT | AY6: QTY | AZ6: UP | BA6: AMOUNT | BB6: QTY | BC6: UP | BD6: AMOUNT | BE6: QTY | BF6: UP | BG6: AMOUNT | BH6: QTY | BI6: UP | BJ6: AMOUNT | BK6: QTY | BL6: UP | BM6: AMOUNT | BN6: QTY | BO6: UP | BP6: AMOUNT | BQ6: QTY | BR6: UP | BS6: AMOUNT | BT6: QTY | BU6: UP | BV6: AMOUNT | BY6: AMOUNT | CA6: AMOUNT
A7: 1 | B7: =GROSS!B7 -> 0 | C7: =DELIVERIES!C7 -> 30 | D7: =B7*C7 -> 0 | E7: ='1'!F7 -> 169 | F7: =DELIVERIES!F7 -> 35 | G7: =E7*F7 -> 5915 | H7: ='1'!F8 -> 15 | I7: =DELIVERIES!I7 -> 8.5 | J7: =H7*I7 -> 127.5 | K7: ='1'!F15 -> 18 | L7: =DELIVERIES!L7 -> 18 | M7: =K7*L7 -> 324 | N7: ='1'!F9 -> 16 | O7: =DELIVERIES!O7 -> 7 | P7: =N7*O7 -> 112 | Q7: ='1'!F10 -> 0 | R7: =DELIVERIES!R7 -> 5.5 | S7: =Q7*R7 -> 0 | T7: ='1'!F11 -> 192 | U7: =DELIVERIES!U7 -> 8.5 | V7: =T7*U7 -> 1632 | W7: ='1'!F12 -> 43 | X7: =DELIVERIES!X7 -> 6 | Y7: =W7*X7 -> 258 | Z7: ='1'!F13 -> 32 | AA7: =DELIVERIES!AA7 -> 6 | AB7: =Z7*AA7 -> 192 | AC7: ='1'!F14 -> 18 | AD7: =DELIVERIES!AD7 -> 8 | AE7: =AC7*AD7 -> 144 | AH7: =AF7*AG7 -> 0 | AK7: =D7+G7+J7+M7+P7+S7+V7+Y7+AB7+AE7+AH7 -> 8704.5 | AM7: ='1'!F17 -> 16 | AN7: =DELIVERIES!AQ7 -> 8.75 | AO7: =AM7*AN7 -> 140 | AP7: ='1'!F18 -> 43 | AQ7: =DELIVERIES!AT7 -> 12.25 | AR7: =AP7*AQ7 -> 526.75 | AS7: ='1'!F21 -> 0 | AT7: =DELIVERIES!AW7 -> 7.9166667 | AU7: =AS7*AT7 -> 0 | AV7: ='1'!F22 -> 7 | AW7: =DELIVERIES!AZ7 -> 9.7916667 | AX7: =AV7*AW7 -> 68.541667 | AY7: ='1'!F26 -> 0 | AZ7: =DELIVERIES!BC7 -> 16.333333 | BA7: =AY7*AZ7 -> 0 | BB7: ='1'!F27 -> 7 | BC7: =DELIVERIES!BF7 -> 11.5 | BD7: =BB7*BC7 -> 80.5 | BE7: ='1'!F28 -> 3 | BF7: =DELIVERIES!BI31 -> 20 | BG7: =BE7*BF7 -> 60 | BH7: ='1'!F23 -> 0 | BI7: =DELIVERIES!BL7 -> 23 | BJ7: =BH7*BI7 -> 0 | BK7: ='1'!F25 -> 0 | BL7: =DELIVERIES!BO7 -> 12.5 | BM7: =BK7*BL7 -> 0 | BN7: ='1'!F24 -> 2 | BO7: =DELIVERIES!BR7 -> 12.75 | BP7: =BN7*BO7 -> 25.5 | BQ7: ='1'!F19 -> 0 | BR7: =DELIVERIES!BU7 -> 30.25 | BS7: =BQ7*BR7 -> 0 | BT7: ='1'!F20 -> 0 | BU7: =DELIVERIES!BX7 -> 15.916667 | BV7: =BT7*BU7 -> 0 | BY7: =AO7+AR7+AU7+AX7+BA7+BD7+BG7+BJ7+BM7+BP7+BS7+BV7 -> 901.29167 | CA7: =BY7+AK7 -> 9605.7917 | CD7: =CA7-CC7 -> 9605.7917
A8: 2 | B8: =GROSS!B8 -> 0 | C8: =DELIVERIES!C8 -> 30 | D8: =B8*C8 -> 0 | E8: ='2'!F7 -> 214 | F8: =DELIVERIES!F8 -> 35 | G8: =E8*F8 -> 7490 | H8: ='2'!F8 -> 12 | I8: =DELIVERIES!I8 -> 8.5 | J8: =H8*I8 -> 102 | K8: ='2'!F15 -> 18 | L8: =DELIVERIES!L8 -> 18 | M8: =K8*L8 -> 324 | N8: ='2'!F9 -> 62 | O8: =DELIVERIES!O8 -> 7 | P8: =N8*O8 -> 434 | Q8: ='2'!F10 -> 0 | R8: =DELIVERIES!R8 -> 5.5 | S8: =Q8*R8 -> 0 | T8: ='2'!F11 -> 176 | U8: =DELIVERIES!U8 -> 8.5 | V8: =T8*U8 -> 1496 | W8: ='2'!F12 -> 74 | X8: =DELIVERIES!X8 -> 6 | Y8: =W8*X8 -> 444 | Z8: ='2'!F13 -> 33 | AA8: =DELIVERIES!AA8 -> 6 | AB8: =Z8*AA8 -> 198 | AC8: ='2'!F14 -> 9 | AD8: =DELIVERIES!AD8 -> 8 | AE8: =AC8*AD8 -> 72 | AG8: =AG7 -> 0 | AH8: =AF8*AG8 -> 0 | AK8: =D8+G8+J8+M8+P8+S8+V8+Y8+AB8+AE8+AH8 -> 10560 | AM8: ='2'!F17 -> 16 | AN8: =DELIVERIES!AQ8 -> 8.75 | AO8: =AM8*AN8 -> 140 | AP8: ='2'!F18 -> 51 | AQ8: =DELIVERIES!AT8 -> 12.25 | AR8: =AP8*AQ8 -> 624.75 | AS8: ='2'!F21 -> 0 | AT8: =DELIVERIES!AW8 -> 7.9166667 | AU8: =AS8*AT8 -> 0 | AV8: ='2'!F22 -> 6 | AW8: =DELIVERIES!AZ8 -> 9.7916667 | AX8: =AV8*AW8 -> 58.75 | AY8: ='2'!F26 -> 0 | AZ8: =DELIVERIES!BC8 -> 16.333333 | BA8: =AY8*AZ8 -> 0 | BB8: ='2'!F27 -> 6 | BC8: =DELIVERIES!BF8 -> 11.5 | BD8: =BB8*BC8 -> 69 | BE8: ='2'!F28 -> 6 | BF8: =DELIVERIES!BI32 -> 20 | BG8: =BE8*BF8 -> 120 | BH8: ='2'!F23 -> 0 | BI8: =DELIVERIES!BL8 -> 23 | BJ8: =BH8*BI8 -> 0 | BK8: ='2'!F25 -> 0 | BL8: =DELIVERIES!BO8 -> 12.5 | BM8: =BK8*BL8 -> 0 | BN8: ='2'!F24 -> 6 | BO8: =DELIVERIES!BR8 -> 12.75 | BP8: =BN8*BO8 -> 76.5 | BQ8: ='2'!F19 -> 0 | BR8: =DELIVERIES!BU8 -> 30.25 | BS8: =BQ8*BR8 -> 0 | BT8: ='2'!F20 -> 0 | BU8: =DELIVERIES!BX8 -> 15.916667 | BV8: =BT8*BU8 -> 0 | BY8: =AO8+AR8+AU8+AX8+BA8+BD8+BG8+BJ8+BM8+BP8+BS8+BV8 -> 1089 | CA8: =BY8+AK8 -> 11649 | CD8: =CA8-CC8 -> 11649
A9: 3 | B9: =GROSS!B9 -> 0 | C9: =DELIVERIES!C9 -> 30 | D9: =B9*C9 -> 0 | E9: ='3'!F7 -> 185 | F9: =DELIVERIES!F9 -> 35 | G9: =E9*F9 -> 6475 | H9: ='3'!F8 -> 11 | I9: =DELIVERIES!I9 -> 8.5 | J9: =H9*I9 -> 93.5 | K9: ='3'!F15 -> 20 | L9: =DELIVERIES!L9 -> 18 | M9: =K9*L9 -> 360 | N9: ='3'!F9 -> 118 | O9: =DELIVERIES!O9 -> 7 | P9: =N9*O9 -> 826 | Q9: ='3'!F10 -> 0 | R9: =DELIVERIES!R9 -> 5.5 | S9: =Q9*R9 -> 0 | T9: ='3'!F11 -> 191 | U9: =DELIVERIES!U9 -> 8.5 | V9: =T9*U9 -> 1623.5 | W9: ='3'!F12 -> 33 | X9: =DELIVERIES!X9 -> 6 | Y9: =W9*X9 -> 198 | Z9: ='3'!F13 -> 44 | AA9: =DELIVERIES!AA9 -> 6 | AB9: =Z9*AA9 -> 264 | AC9: ='3'!F14 -> 12 | AD9: =DELIVERIES!AD9 -> 8 | AE9: =AC9*AD9 -> 96 | AG9: =AG7 -> 0 | AH9: =AF9*AG9 -> 0 | AK9: =D9+G9+J9+M9+P9+S9+V9+Y9+AB9+AE9+AH9 -> 9936 | AM9: ='3'!F17 -> 15 | AN9: =DELIVERIES!AQ9 -> 8.75 | AO9: =AM9*AN9 -> 131.25 | AP9: ='3'!F18 -> 38 | AQ9: =DELIVERIES!AT9 -> 12.25 | AR9: =AP9*AQ9 -> 465.5 | AS9: ='3'!F21 -> 0 | AT9: =DELIVERIES!AW9 -> 7.9166667 | AU9: =AS9*AT9 -> 0 | AV9: ='3'!F22 -> 4 | AW9: =DELIVERIES!AZ9 -> 9.7916667 | AX9: =AV9*AW9 -> 39.166667 | AY9: ='3'!F26 -> 0 | AZ9: =DELIVERIES!BC9 -> 16.333333 | BA9: =AY9*AZ9 -> 0 | BB9: ='3'!F27 -> 7 | BC9: =DELIVERIES!BF9 -> 11.5 | BD9: =BB9*BC9 -> 80.5 | BE9: ='3'!F28 -> 4 | BF9: =DELIVERIES!BI33 -> 20 | BG9: =BE9*BF9 -> 80 | BH9: ='3'!F23 -> 0 | BI9: =DELIVERIES!BL9 -> 23 | BJ9: =BH9*BI9 -> 0 | BK9: ='3'!F25 -> 0 | BL9: =DELIVERIES!BO9 -> 12.5 | BM9: =BK9*BL9 -> 0 | BN9: ='3'!F24 -> 6 | BO9: =DELIVERIES!BR9 -> 12.75 | BP9: =BN9*BO9 -> 76.5 | BQ9: ='3'!F19 -> 0 | BR9: =DELIVERIES!BU9 -> 30.25 | BS9: =BQ9*BR9 -> 0 | BT9: ='3'!F20 -> 0 | BU9: =DELIVERIES!BX9 -> 15.916667 | BV9: =BT9*BU9 -> 0 | BY9: =AO9+AR9+AU9+AX9+BA9+BD9+BG9+BJ9+BM9+BP9+BS9+BV9 -> 872.91667 | CA9: =BY9+AK9 -> 10808.917 | CD9: =CA9-CC9 -> 10808.917
A10: 4 | B10: =GROSS!B10 -> 0 | C10: =DELIVERIES!C10 -> 30 | D10: =B10*C10 -> 0 | E10: ='4'!F7 -> 142 | F10: =DELIVERIES!F10 -> 35 | G10: =E10*F10 -> 4970 | H10: ='4'!F8 -> 12 | I10: =DELIVERIES!I10 -> 8.5 | J10: =H10*I10 -> 102 | K10: ='4'!F15 -> 7 | L10: =DELIVERIES!L10 -> 18 | M10: =K10*L10 -> 126 | N10: ='4'!F9 -> 99 | O10: =DELIVERIES!O10 -> 7 | P10: =N10*O10 -> 693 | Q10: ='4'!F10 -> 0 | R10: =DELIVERIES!R10 -> 5.5 | S10: =Q10*R10 -> 0 | T10: ='4'!F11 -> 160 | U10: =DELIVERIES!U10 -> 8.5 | V10: =T10*U10 -> 1360 | W10: ='4'!F12 -> 24 | X10: =DELIVERIES!X10 -> 6 | Y10: =W10*X10 -> 144 | Z10: ='4'!F13 -> 34 | AA10: =DELIVERIES!AA10 -> 6 | AB10: =Z10*AA10 -> 204 | AC10: ='4'!F14 -> 10 | AD10: =DELIVERIES!AD10 -> 8 | AE10: =AC10*AD10 -> 80 | AG10: =AG7 -> 0 | AH10: =AF10*AG10 -> 0 | AK10: =D10+G10+J10+M10+P10+S10+V10+Y10+AB10+AE10+AH10 -> 7679 | AM10: ='4'!F17 -> 4 | AN10: =DELIVERIES!AQ10 -> 8.75 | AO10: =AM10*AN10 -> 35 | AP10: ='4'!F18 -> 27 | AQ10: =DELIVERIES!AT10 -> 12.25 | AR10: =AP10*AQ10 -> 330.75 | AS10: ='4'!F21 -> 0 | AT10: =DELIVERIES!AW10 -> 7.9166667 | AU10: =AS10*AT10 -> 0 | AV10: ='4'!F22 -> 3 | AW10: =DELIVERIES!AZ10 -> 9.7916667 | AX10: =AV10*AW10 -> 29.375 | AY10: ='4'!F26 -> 0 | AZ10: =DELIVERIES!BC10 -> 16.333333 | BA10: =AY10*AZ10 -> 0 | BB10: ='4'!F27 -> 6 | BC10: =DELIVERIES!BF10 -> 11.5 | BD10: =BB10*BC10 -> 69 | BE10: ='4'!F28 -> 10 | BF10: =DELIVERIES!BI34 -> 20 | BG10: =BE10*BF10 -> 200 | BH10: ='4'!F23 -> 0 | BI10: =DELIVERIES!BL10 -> 23 | BJ10: =BH10*BI10 -> 0 | BK10: ='4'!F25 -> 0 | BL10: =DELIVERIES!BO10 -> 12.5 | BM10: =BK10*BL10 -> 0 | BN10: ='4'!F24 -> 6 | BO10: =DELIVERIES!BR10 -> 12.75 | BP10: =BN10*BO10 -> 76.5 | BQ10: ='4'!F19 -> 0 | BR10: =DELIVERIES!BU10 -> 30.25 | BS10: =BQ10*BR10 -> 0 | BT10: ='4'!F20 -> 0 | BU10: =DELIVERIES!BX10 -> 15.916667 | BV10: =BT10*BU10 -> 0 | BY10: =AO10+AR10+AU10+AX10+BA10+BD10+BG10+BJ10+BM10+BP10+BS10+BV10 -> 740.625 | CA10: =BY10+AK10 -> 8419.625 | CD10: =CA10-CC10 -> 8419.625
A11: 5 | B11: =GROSS!B11 -> 0 | C11: =DELIVERIES!C11 -> 30 | D11: =B11*C11 -> 0 | E11: ='5'!F7 -> 207 | F11: =DELIVERIES!F11 -> 35 | G11: =E11*F11 -> 7245 | H11: ='5'!F8 -> 19 | I11: =DELIVERIES!I11 -> 8.5 | J11: =H11*I11 -> 161.5 | K11: ='5'!F15 -> 22 | L11: =DELIVERIES!L11 -> 18 | M11: =K11*L11 -> 396 | N11: ='5'!F9 -> 21 | O11: =DELIVERIES!O11 -> 7 | P11: =N11*O11 -> 147 | Q11: ='5'!F10 -> 0 | R11: =DELIVERIES!R11 -> 5.5 | S11: =Q11*R11 -> 0 | T11: ='5'!F11 -> 273 | U11: =DELIVERIES!U11 -> 8.5 | V11: =T11*U11 -> 2320.5 | W11: ='5'!F12 -> 59 | X11: =DELIVERIES!X11 -> 6 | Y11: =W11*X11 -> 354 | Z11: ='5'!F13 -> 59 | AA11: =DELIVERIES!AA11 -> 6 | AB11: =Z11*AA11 -> 354 | AC11: ='5'!F14 -> 15 | AD11: =DELIVERIES!AD11 -> 8 | AE11: =AC11*AD11 -> 120 | AG11: =AG7 -> 0 | AH11: =AF11*AG11 -> 0 | AK11: =D11+G11+J11+M11+P11+S11+V11+Y11+AB11+AE11+AH11 -> 11098 | AM11: ='5'!F17 -> 17 | AN11: =DELIVERIES!AQ11 -> 8.75 | AO11: =AM11*AN11 -> 148.75 | AP11: ='5'!F18 -> 50 | AQ11: =DELIVERIES!AT11 -> 12.25 | AR11: =AP11*AQ11 -> 612.5 | AS11: ='5'!F21 -> 0 | AT11: =DELIVERIES!AW11 -> 7.9166667 | AU11: =AS11*AT11 -> 0 | AV11: ='5'!F22 -> 10 | AW11: =DELIVERIES!AZ11 -> 9.7916667 | AX11: =AV11*AW11 -> 97.916667 | AY11: ='5'!F26 -> 0 | AZ11: =DELIVERIES!BC11 -> 16.333333 | BA11: =AY11*AZ11 -> 0 | BB11: ='5'!F27 -> 17 | BC11: =DELIVERIES!BF11 -> 11.5 | BD11: =BB11*BC11 -> 195.5 | BE11: ='5'!F28 -> 8 | BF11: =DELIVERIES!BI35 -> 20 | BG11: =BE11*BF11 -> 160 | BH11: ='5'!F23 -> 0 | BI11: =DELIVERIES!BL11 -> 23 | BJ11: =BH11*BI11 -> 0 | BK11: ='5'!F25 -> 0 | BL11: =DELIVERIES!BO11 -> 12.5 | BM11: =BK11*BL11 -> 0 | BN11: ='5'!F24 -> 3 | BO11: =DELIVERIES!BR11 -> 12.75 | BP11: =BN11*BO11 -> 38.25 | BQ11: ='5'!F19 -> 0 | BR11: =DELIVERIES!BU11 -> 30.25 | BS11: =BQ11*BR11 -> 0 | BT11: ='5'!F20 -> 0 | BU11: =DELIVERIES!BX11 -> 15.916667 | BV11: =BT11*BU11 -> 0 | BY11: =AO11+AR11+AU11+AX11+BA11+BD11+BG11+BJ11+BM11+BP11+BS11+BV11 -> 1252.9167 | CA11: =BY11+AK11 -> 12350.917 | CD11: =CA11-CC11 -> 12350.917
A12: 6 | B12: =GROSS!B12 -> 0 | C12: =DELIVERIES!C12 -> 30 | D12: =B12*C12 -> 0 | E12: ='6'!F7 -> 203 | F12: =DELIVERIES!F12 -> 35 | G12: =E12*F12 -> 7105 | H12: ='6'!F8 -> 6 | I12: =DELIVERIES!I12 -> 8.5 | J12: =H12*I12 -> 51 | K12: ='6'!F15 -> 7 | L12: =DELIVERIES!L12 -> 18 | M12: =K12*L12 -> 126 | N12: ='6'!F9 -> 50 | O12: =DELIVERIES!O12 -> 7 | P12: =N12*O12 -> 350 | Q12: ='6'!F10 -> 0 | R12: =DELIVERIES!R12 -> 5.5 | S12: =Q12*R12 -> 0 | T12: ='6'!F11 -> 220 | U12: =DELIVERIES!U12 -> 8.5 | V12: =T12*U12 -> 1870 | W12: ='6'!F12 -> 35 | X12: =DELIVERIES!X12 -> 6 | Y12: =W12*X12 -> 210 | Z12: ='6'!F13 -> 36 | AA12: =DELIVERIES!AA12 -> 6 | AB12: =Z12*AA12 -> 216 | AC12: ='6'!F14 -> 6 | AD12: =DELIVERIES!AD12 -> 8 | AE12: =AC12*AD12 -> 48 | AG12: =AG7 -> 0 | AH12: =AF12*AG12 -> 0 | AK12: =D12+G12+J12+M12+P12+S12+V12+Y12+AB12+AE12+AH12 -> 9976 | AM12: ='6'!F17 -> 7 | AN12: =DELIVERIES!AQ12 -> 8.75 | AO12: =AM12*AN12 -> 61.25 | AP12: ='6'!F18 -> 41 | AQ12: =DELIVERIES!AT12 -> 12.25 | AR12: =AP12*AQ12 -> 502.25 | AS12: ='6'!F21 -> 0 | AT12: =DELIVERIES!AW12 -> 7.9166667 | AU12: =AS12*AT12 -> 0 | AV12: ='6'!F22 -> 7 | AW12: =DELIVERIES!AZ12 -> 9.7916667 | AX12: =AV12*AW12 -> 68.541667 | AY12: ='6'!F26 -> 0 | AZ12: =DELIVERIES!BC12 -> 16.333333 | BA12: =AY12*AZ12 -> 0 | BB12: ='6'!F27 -> 8 | BC12: =DELIVERIES!BF12 -> 11.5 | BD12: =BB12*BC12 -> 92 | BE12: ='6'!F28 -> 3 | BF12: =DELIVERIES!BI36 -> 20 | BG12: =BE12*BF12 -> 60 | BH12: ='6'!F23 -> 0 | BI12: =DELIVERIES!BL12 -> 23 | BJ12: =BH12*BI12 -> 0 | BK12: ='6'!F25 -> 0 | BL12: =DELIVERIES!BO12 -> 12.5 | BM12: =BK12*BL12 -> 0 | BN12: ='6'!F24 -> 2 | BO12: =DELIVERIES!BR12 -> 12.75 | BP12: =BN12*BO12 -> 25.5 | BQ12: ='6'!F19 -> 0 | BR12: =DELIVERIES!BU12 -> 30.25 | BS12: =BQ12*BR12 -> 0 | BT12: ='6'!F20 -> 0 | BU12: =DELIVERIES!BX12 -> 15.916667 | BV12: =BT12*BU12 -> 0 | BY12: =AO12+AR12+AU12+AX12+BA12+BD12+BG12+BJ12+BM12+BP12+BS12+BV12 -> 809.54167 | CA12: =BY12+AK12 -> 10785.542 | CD12: =CA12-CC12 -> 10785.542
A13: 7 | B13: =GROSS!B13 -> 0 | C13: =DELIVERIES!C13 -> 30 | D13: =B13*C13 -> 0 | E13: ='7'!F7 -> 158 | F13: =DELIVERIES!F13 -> 35 | G13: =E13*F13 -> 5530 | H13: ='7'!F8 -> 17 | I13: =DELIVERIES!I13 -> 8.5 | J13: =H13*I13 -> 144.5 | K13: ='7'!F15 -> 11 | L13: =DELIVERIES!L13 -> 18 | M13: =K13*L13 -> 198 | N13: ='7'!F9 -> 86 | O13: =DELIVERIES!O13 -> 7 | P13: =N13*O13 -> 602 | Q13: ='7'!F10 -> 0 | R13: =DELIVERIES!R13 -> 5.5 | S13: =Q13*R13 -> 0 | T13: ='7'!F11 -> 169 | U13: =DELIVERIES!U13 -> 8.5 | V13: =T13*U13 -> 1436.5 | W13: ='7'!F12 -> 34 | X13: =DELIVERIES!X13 -> 6 | Y13: =W13*X13 -> 204 | Z13: ='7'!F13 -> 33 | AA13: =DELIVERIES!AA13 -> 6 | AB13: =Z13*AA13 -> 198 | AC13: ='7'!F14 -> 11 | AD13: =DELIVERIES!AD13 -> 8 | AE13: =AC13*AD13 -> 88 | AG13: =AG7 -> 0 | AH13: =AF13*AG13 -> 0 | AK13: =D13+G13+J13+M13+P13+S13+V13+Y13+AB13+AE13+AH13 -> 8401 | AM13: ='7'!F17 -> 8 | AN13: =DELIVERIES!AQ13 -> 8.75 | AO13: =AM13*AN13 -> 70 | AP13: ='7'!F18 -> 31 | AQ13: =DELIVERIES!AT13 -> 12.25 | AR13: =AP13*AQ13 -> 379.75 | AS13: ='7'!F21 -> 0 | AT13: =DELIVERIES!AW13 -> 7.9166667 | AU13: =AS13*AT13 -> 0 | AV13: ='7'!F22 -> 9 | AW13: =DELIVERIES!AZ13 -> 9.7916667 | AX13: =AV13*AW13 -> 88.125 | AY13: ='7'!F26 -> 0 | AZ13: =DELIVERIES!BC13 -> 16.333333 | BA13: =AY13*AZ13 -> 0 | BB13: ='7'!F27 -> 6 | BC13: =DELIVERIES!BF13 -> 11.5 | BD13: =BB13*BC13 -> 69 | BE13: ='7'!F28 -> 2 | BF13: =DELIVERIES!BI37 -> 20 | BG13: =BE13*BF13 -> 40 | BH13: ='7'!F23 -> 0 | BI13: =DELIVERIES!BL13 -> 23 | BJ13: =BH13*BI13 -> 0 | BK13: ='7'!F25 -> 0 | BL13: =DELIVERIES!BO13 -> 12.5 | BM13: =BK13*BL13 -> 0 | BN13: ='7'!F24 -> 7 | BO13: =DELIVERIES!BR13 -> 12.75 | BP13: =BN13*BO13 -> 89.25 | BQ13: ='7'!F19 -> 0 | BR13: =DELIVERIES!BU13 -> 30.25 | BS13: =BQ13*BR13 -> 0 | BT13: ='7'!F20 -> 0 | BU13: =DELIVERIES!BX13 -> 15.916667 | BV13: =BT13*BU13 -> 0 | BY13: =AO13+AR13+AU13+AX13+BA13+BD13+BG13+BJ13+BM13+BP13+BS13+BV13 -> 736.125 | CA13: =BY13+AK13 -> 9137.125 | CD13: =CA13-CC13 -> 9137.125
A14: TOTAL | B14: =SUM(B7:B13) -> 0 | D14: =SUM(D7:D13) -> 0 | E14: =SUM(E7:E13) -> 1278 | G14: =SUM(G7:G13) -> 44730 | H14: =SUM(H7:H13) -> 92 | J14: =SUM(J7:J13) -> 782 | K14: =SUM(K7:K13) -> 103 | M14: =SUM(M7:M13) -> 1854 | N14: =SUM(N7:N13) -> 452 | P14: =SUM(P7:P13) -> 3164 | Q14: =SUM(Q7:Q13) -> 0 | S14: =SUM(S7:S13) -> 0 | T14: =SUM(T7:T13) -> 1381 | V14: =SUM(V7:V13) -> 11738.5 | W14: =SUM(W7:W13) -> 302 | Y14: =SUM(Y7:Y13) -> 1812 | Z14: =SUM(Z7:Z13) -> 271 | AB14: =SUM(AB7:AB13) -> 1626 | AC14: =SUM(AC7:AC13) -> 81 | AE14: =SUM(AE7:AE13) -> 648 | AF14: =SUM(AF7:AF13) -> 0 | AH14: =SUM(AH7:AH13) -> 0 | AK14: =SUM(AK7:AK13) -> 66354.5 | AM14: =SUM(AM7:AM13) -> 83 | AO14: =SUM(AO7:AO13) -> 726.25 | AP14: =SUM(AP7:AP13) -> 281 | AR14: =SUM(AR7:AR13) -> 3442.25 | AS14: =SUM(AS7:AS13) -> 0 | AU14: =SUM(AU7:AU13) -> 0 | AV14: =SUM(AV7:AV13) -> 46 | AX14: =SUM(AX7:AX13) -> 450.41667 | AY14: =SUM(AY7:AY13) -> 0 | BA14: =SUM(BA7:BA13) -> 0 | BB14: =SUM(BB7:BB13) -> 57 | BD14: =SUM(BD7:BD13) -> 655.5 | BE14: =SUM(BE7:BE13) -> 36 | BG14: =SUM(BG7:BG13) -> 720 | BH14: =SUM(BH7:BH13) -> 0 | BJ14: =SUM(BJ7:BJ13) -> 0 | BK14: =SUM(BK7:BK13) -> 0 | BM14: =SUM(BM7:BM13) -> 0 | BN14: =SUM(BN7:BN13) -> 32 | BP14: =SUM(BP7:BP13) -> 408 | BQ14: =SUM(BQ7:BQ13) -> 0 | BS14: =SUM(BS7:BS13) -> 0 | BT14: =SUM(BT7:BT13) -> 0 | BV14: =SUM(BV7:BV13) -> 0 | BY14: =SUM(BY7:BY13) -> 6402.4167 | CA14: =SUM(CA7:CA13) -> 72756.917 | CD14: =SUM(CD7:CD13) -> 72756.917
A17: WEEK- 2 | B17: =B5 -> PREMIUM - CUT | E17: SPECIAL CUT | H17: NGOHIONG | K17: =K5 -> Chicken Fillet | N17: NECK | Q17: SIOMAI | T17: RICE | W17: BOLA-BOLA | Z17: LUMPIA | AC17: ATSARA | AF17: =AF5 -> 0 | AI17: =AI5 -> SUBTOTAL | AM17: 8OZ | AP17: 12 OZ | AS17: WATER 350 ML | AV17: WATER 500 ML | AY17: PANALO | BB17: =BB5 -> swakto | BE17: =BE5 -> Calamansi Juice | BH17: =BH5 -> GATORADE | BK17: TROPICANA | BN17: STING | BQ17: =BQ5 -> 1 LITER | BT17: =BT5 -> 1.5 L | BW17: SUBTOTAL FOR DRINKS | CA17: TOTAL
A18: DATE | B18: QTY | C18: UP | D18: AMOUNT | E18: QTY | F18: UP | G18: AMOUNT | H18: QTY | I18: UP | J18: AMOUNT | K18: QTY | L18: UP | M18: AMOUNT | N18: QTY | O18: UP | P18: AMOUNT | Q18: QTY | R18: UP | S18: AMOUNT | T18: QTY | U18: UP | V18: AMOUNT | W18: QTY | X18: UP | Y18: AMOUNT | Z18: QTY | AA18: UP | AB18: AMOUNT | AC18: QTY | AD18: UP | AE18: AMOUNT | AF18: QTY | AG18: UP | AH18: AMOUNT | AK18: AMOUNT | AM18: QTY | AN18: UP | AO18: AMOUNT | AP18: QTY | AQ18: UP | AR18: AMOUNT | AS18: QTY | AT18: UP | AU18: AMOUNT | AV18: QTY | AW18: UP | AX18: AMOUNT | AY18: QTY | AZ18: UP | BA18: AMOUNT | BB18: QTY | BC18: UP | BD18: AMOUNT | BE18: QTY | BF18: UP | BG18: AMOUNT | BH18: QTY | BI18: UP | BJ18: AMOUNT | BK18: QTY | BL18: UP | BM18: AMOUNT | BN18: QTY | BO18: UP | BP18: AMOUNT | BQ18: QTY | BR18: UP | BS18: AMOUNT | BT18: QTY | BU18: UP | BV18: AMOUNT | BY18: AMOUNT | CA18: AMOUNT
A19: 8 | B19: =GROSS!B19 -> 0 | C19: =DELIVERIES!C19 -> 30 | D19: =B19*C19 -> 0 | E19: ='8'!F7 -> 243 | F19: =DELIVERIES!F19 -> 35 | G19: =E19*F19 -> 8505 | H19: ='8'!F8 -> 8 | I19: =DELIVERIES!I19 -> 8.5 | J19: =H19*I19 -> 68 | K19: ='8'!F15 -> 12 | L19: =DELIVERIES!L19 -> 18 | M19: =K19*L19 -> 216 | N19: ='8'!F9 -> 64 | O19: =DELIVERIES!O19 -> 7 | P19: =N19*O19 -> 448 | Q19: ='8'!F10 -> 0 | R19: =DELIVERIES!R19 -> 5.5 | S19: =Q19*R19 -> 0 | T19: ='8'!F11 -> 180 | U19: =DELIVERIES!U19 -> 8.5 | V19: =T19*U19 -> 1530 | W19: ='8'!F12 -> 44 | X19: =DELIVERIES!X19 -> 6 | Y19: =W19*X19 -> 264 | Z19: ='8'!F13 -> 41 | AA19: =DELIVERIES!AA19 -> 6 | AB19: =Z19*AA19 -> 246 | AC19: ='8'!F14 -> 4 | AD19: =DELIVERIES!AD19 -> 8 | AE19: =AC19*AD19 -> 32 | AG19: =AG7 -> 0 | AH19: =AF19*AG19 -> 0 | AK19: =D19+G19+J19+M19+P19+S19+V19+Y19+AB19+AE19+AH19 -> 11309 | AM19: ='8'!F17 -> 13 | AN19: =DELIVERIES!AQ19 -> 8.75 | AO19: =AM19*AN19 -> 113.75 | AP19: ='8'!F18 -> 32 | AQ19: =DELIVERIES!AT19 -> 12.25 | AR19: =AP19*AQ19 -> 392 | AS19: ='8'!F21 -> 0 | AT19: =DELIVERIES!AZ19 -> 9.7916667 | AU19: =AS19*AT19 -> 0 | AV19: ='8'!F22 -> 10 | AW19: =DELIVERIES!AZ19 -> 9.7916667 | AX19: =AV19*AW19 -> 97.916667 | AY19: ='8'!F26 -> 0 | AZ19: =DELIVERIES!BC19 -> 16.333333 | BA19: =AY19*AZ19 -> 0 | BB19: ='8'!F27 -> 11 | BC19: =DELIVERIES!BF19 -> 11.5 | BD19: =BB19*BC19 -> 126.5 | BE19: ='8'!F28 -> 3 | BF19: =DELIVERIES!BI43 -> 20 | BG19: =BE19*BF19 -> 60 | BH19: ='8'!F23 -> 0 | BI19: =DELIVERIES!BL19 -> 23 | BJ19: =BH19*BI19 -> 0 | BK19: ='8'!F25 -> 0 | BL19: =DELIVERIES!BO19 -> 12.5 | BM19: =BK19*BL19 -> 0 | BN19: ='8'!F24 -> 4 | BO19: =DELIVERIES!BR19 -> 12.75 | BP19: =BN19*BO19 -> 51 | BQ19: ='8'!F19 -> 0 | BR19: =DELIVERIES!BU19 -> 30.25 | BS19: =BQ19*BR19 -> 0 | BT19: ='8'!F20 -> 0 | BU19: =DELIVERIES!BX19 -> 15.916667 | BV19: =BT19*BU19 -> 0 | BY19: =AO19+AR19+AU19+AX19+BA19+BD19+BG19+BJ19+BM19+BP19+BS19+BV19 -> 841.16667 | CA19: =AK19+BY19 -> 12150.167 | CD19: =CA19-CC19 -> 12150.167
A20: 9 | B20: =GROSS!B20 -> 0 | C20: =DELIVERIES!C20 -> 30 | D20: =B20*C20 -> 0 | E20: ='9'!F7 -> 226 | F20: =DELIVERIES!F20 -> 35 | G20: =E20*F20 -> 7910 | H20: ='9'!F8 -> 8 | I20: =DELIVERIES!I20 -> 8.5 | J20: =H20*I20 -> 68 | K20: ='9'!F15 -> 16 | L20: =DELIVERIES!L20 -> 18 | M20: =K20*L20 -> 288 | N20: ='9'!F9 -> 100 | O20: =DELIVERIES!O20 -> 7 | P20: =N20*O20 -> 700 | Q20: ='9'!F10 -> 0 | R20: =DELIVERIES!R20 -> 5.5 | S20: =Q20*R20 -> 0 | T20: ='9'!F11 -> 203 | U20: =DELIVERIES!U20 -> 8.5 | V20: =T20*U20 -> 1725.5 | W20: ='9'!F12 -> 39 | X20: =DELIVERIES!X20 -> 6 | Y20: =W20*X20 -> 234 | Z20: ='9'!F13 -> 35 | AA20: =DELIVERIES!AA20 -> 6 | AB20: =Z20*AA20 -> 210 | AC20: ='9'!F14 -> 7 | AD20: =DELIVERIES!AD20 -> 8 | AE20: =AC20*AD20 -> 56 | AG20: =AG7 -> 0 | AH20: =AF20*AG20 -> 0 | AK20: =D20+G20+J20+M20+P20+S20+V20+Y20+AB20+AE20+AH20 -> 11191.5 | AM20: ='9'!F17 -> 10 | AN20: =DELIVERIES!AQ20 -> 8.75 | AO20: =AM20*AN20 -> 87.5 | AP20: ='9'!F18 -> 38 | AQ20: =DELIVERIES!AT20 -> 12.25 | AR20: =AP20*AQ20 -> 465.5 | AS20: ='9'!F21 -> 0 | AT20: =DELIVERIES!AZ20 -> 9.7916667 | AU20: =AS20*AT20 -> 0 | AV20: ='9'!F22 -> 1 | AW20: =DELIVERIES!AZ20 -> 9.7916667 | AX20: =AV20*AW20 -> 9.7916667 | AY20: ='9'!F26 -> 0 | AZ20: =DELIVERIES!BC20 -> 16.333333 | BA20: =AY20*AZ20 -> 0 | BB20: ='9'!F27 -> 14 | BC20: =DELIVERIES!BF20 -> 11.5 | BD20: =BB20*BC20 -> 161 | BE20: ='9'!F28 -> 0 | BF20: =DELIVERIES!BI44 -> 20 | BG20: =BE20*BF20 -> 0 | BH20: ='9'!F23 -> 0 | BI20: =DELIVERIES!BL20 -> 23 | BJ20: =BH20*BI20 -> 0 | BK20: ='9'!F25 -> 0 | BL20: =DELIVERIES!BO20 -> 12.5 | BM20: =BK20*BL20 -> 0 | BN20: ='9'!F24 -> 1 | BO20: =DELIVERIES!BR20 -> 12.75 | BP20: =BN20*BO20 -> 12.75 | BQ20: ='9'!F19 -> 0 | BR20: =DELIVERIES!BU20 -> 30.25 | BS20: =BQ20*BR20 -> 0 | BT20: ='9'!F20 -> 0 | BU20: =DELIVERIES!BX20 -> 15.916667 | BV20: =BT20*BU20 -> 0 | BY20: =AO20+AR20+AU20+AX20+BA20+BD20+BG20+BJ20+BM20+BP20+BS20+BV20 -> 736.54167 | CA20: =AK20+BY20 -> 11928.042 | CD20: =CA20-CC20 -> 11928.042
A21: 10 | B21: =GROSS!B21 -> 0 | C21: =DELIVERIES!C21 -> 30 | D21: =B21*C21 -> 0 | E21: ='10'!F7 -> 190 | F21: =DELIVERIES!F21 -> 35 | G21: =E21*F21 -> 6650 | H21: ='10'!F8 -> 4 | I21: =DELIVERIES!I21 -> 8.5 | J21: =H21*I21 -> 34 | K21: ='10'!F15 -> 7 | L21: =DELIVERIES!L21 -> 18 | M21: =K21*L21 -> 126 | N21: ='10'!F9 -> 100 | O21: =DELIVERIES!O21 -> 7 | P21: =N21*O21 -> 700 | Q21: ='10'!F10 -> 0 | R21: =DELIVERIES!R21 -> 5.5 | S21: =Q21*R21 -> 0 | T21: ='10'!F11 -> 167 | U21: =DELIVERIES!U21 -> 8.5 | V21: =T21*U21 -> 1419.5 | W21: ='10'!F12 -> 36 | X21: =DELIVERIES!X21 -> 6 | Y21: =W21*X21 -> 216 | Z21: ='10'!F13 -> 35 | AA21: =DELIVERIES!AA21 -> 6 | AB21: =Z21*AA21 -> 210 | AC21: ='10'!F14 -> 5 | AD21: =DELIVERIES!AD21 -> 8 | AE21: =AC21*AD21 -> 40 | AG21: =AG7 -> 0 | AH21: =AF21*AG21 -> 0 | AK21: =D21+G21+J21+M21+P21+S21+V21+Y21+AB21+AE21+AH21 -> 9395.5 | AM21: ='10'!F17 -> 8 | AN21: =DELIVERIES!AQ21 -> 8.75 | AO21: =AM21*AN21 -> 70 | AP21: ='10'!F18 -> 30 | AQ21: =DELIVERIES!AT21 -> 12.25 | AR21: =AP21*AQ21 -> 367.5 | AS21: ='10'!F21 -> 0 | AT21: =DELIVERIES!AZ21 -> 9.7916667 | AU21: =AS21*AT21 -> 0 | AV21: ='10'!F22 -> 2 | AW21: =DELIVERIES!AZ21 -> 9.7916667 | AX21: =AV21*AW21 -> 19.583333 | AY21: ='10'!F26 -> 0 | AZ21: =DELIVERIES!BC21 -> 16.333333 | BA21: =AY21*AZ21 -> 0 | BB21: ='10'!F27 -> 4 | BC21: =DELIVERIES!BF21 -> 11.5 | BD21: =BB21*BC21 -> 46 | BE21: ='10'!F28 -> 5 | BF21: =DELIVERIES!BI45 -> 20 | BG21: =BE21*BF21 -> 100 | BH21: ='10'!F23 -> 0 | BI21: =DELIVERIES!BL21 -> 23 | BJ21: =BH21*BI21 -> 0 | BK21: ='10'!F25 -> 0 | BL21: =DELIVERIES!BO21 -> 12.5 | BM21: =BK21*BL21 -> 0 | BN21: ='10'!F24 -> 1 | BO21: =DELIVERIES!BR21 -> 12.75 | BP21: =BN21*BO21 -> 12.75 | BQ21: ='10'!F19 -> 0 | BR21: =DELIVERIES!BU21 -> 30.25 | BS21: =BQ21*BR21 -> 0 | BT21: ='10'!F20 -> 0 | BU21: =DELIVERIES!BX21 -> 15.916667 | BV21: =BT21*BU21 -> 0 | BY21: =AO21+AR21+AU21+AX21+BA21+BD21+BG21+BJ21+BM21+BP21+BS21+BV21 -> 615.83333 | CA21: =AK21+BY21 -> 10011.333 | CD21: =CA21-CC21 -> 10011.333
A22: 11 | B22: =GROSS!B22 -> 0 | C22: =DELIVERIES!C22 -> 30 | D22: =B22*C22 -> 0 | E22: ='11'!F7 -> 213 | F22: =DELIVERIES!F22 -> 35 | G22: =E22*F22 -> 7455 | H22: ='11'!F8 -> 7 | I22: =DELIVERIES!I22 -> 8.5 | J22: =H22*I22 -> 59.5 | K22: ='11'!F15 -> 16 | L22: =DELIVERIES!L22 -> 18 | M22: =K22*L22 -> 288 | N22: ='11'!F9 -> 110 | O22: =DELIVERIES!O22 -> 7 | P22: =N22*O22 -> 770 | Q22: ='11'!F10 -> 0 | R22: =DELIVERIES!R22 -> 5.5 | S22: =Q22*R22 -> 0 | T22: ='11'!F11 -> 190 | U22: =DELIVERIES!U22 -> 8.5 | V22: =T22*U22 -> 1615 | W22: ='11'!F12 -> 41 | X22: =DELIVERIES!X22 -> 6 | Y22: =W22*X22 -> 246 | Z22: ='11'!F13 -> 37 | AA22: =DELIVERIES!AA22 -> 6 | AB22: =Z22*AA22 -> 222 | AC22: ='11'!F14 -> 12 | AD22: =DELIVERIES!AD22 -> 8 | AE22: =AC22*AD22 -> 96 | AG22: =AG7 -> 0 | AH22: =AF22*AG22 -> 0 | AK22: =D22+G22+J22+M22+P22+S22+V22+Y22+AB22+AE22+AH22 -> 10751.5 | AM22: ='11'!F17 -> 16 | AN22: =DELIVERIES!AQ22 -> 8.75 | AO22: =AM22*AN22 -> 140 | AP22: ='11'!F18 -> 27 | AQ22: =DELIVERIES!AT22 -> 12.25 | AR22: =AP22*AQ22 -> 330.75 | AS22: ='11'!F21 -> 0 | AT22: =DELIVERIES!AZ22 -> 9.7916667 | AU22: =AS22*AT22 -> 0 | AV22: ='11'!F22 -> 1 | AW22: =DELIVERIES!AZ22 -> 9.7916667 | AX22: =AV22*AW22 -> 9.7916667 | AY22: ='11'!F26 -> 0 | AZ22: =DELIVERIES!BC22 -> 16.333333 | BA22: =AY22*AZ22 -> 0 | BB22: ='11'!F27 -> 10 | BC22: =DELIVERIES!BF22 -> 11.5 | BD22: =BB22*BC22 -> 115 | BE22: ='11'!F28 -> 0 | BF22: =DELIVERIES!BI46 -> 20 | BG22: =BE22*BF22 -> 0 | BH22: ='11'!F23 -> 0 | BI22: =DELIVERIES!BL22 -> 23 | BJ22: =BH22*BI22 -> 0 | BK22: ='11'!F25 -> 0 | BL22: =DELIVERIES!BO22 -> 12.5 | BM22: =BK22*BL22 -> 0 | BN22: ='11'!F24 -> 5 | BO22: =DELIVERIES!BR22 -> 12.75 | BP22: =BN22*BO22 -> 63.75 | BQ22: ='11'!F19 -> 0 | BR22: =DELIVERIES!BU22 -> 30.25 | BS22: =BQ22*BR22 -> 0 | BT22: ='11'!F20 -> 0 | BU22: =DELIVERIES!BX22 -> 15.916667 | BV22: =BT22*BU22 -> 0 | BY22: =AO22+AR22+AU22+AX22+BA22+BD22+BG22+BJ22+BM22+BP22+BS22+BV22 -> 659.29167 | CA22: =AK22+BY22 -> 11410.792 | CD22: =CA22-CC22 -> 11410.792
A23: 12 | B23: =GROSS!B23 -> 0 | C23: =DELIVERIES!C23 -> 30 | D23: =B23*C23 -> 0 | E23: ='12'!F7 -> 258 | F23: =DELIVERIES!F23 -> 35 | G23: =E23*F23 -> 9030 | H23: ='12'!F8 -> 12 | I23: =DELIVERIES!I23 -> 8.5 | J23: =H23*I23 -> 102 | K23: ='12'!F15 -> 25 | L23: =DELIVERIES!L23 -> 18 | M23: =K23*L23 -> 450 | N23: ='12'!F9 -> 40 | O23: =DELIVERIES!O23 -> 7 | P23: =N23*O23 -> 280 | Q23: ='12'!F10 -> 0 | R23: =DELIVERIES!R23 -> 5.5 | S23: =Q23*R23 -> 0 | T23: ='12'!F11 -> 183 | U23: =DELIVERIES!U23 -> 8.5 | V23: =T23*U23 -> 1555.5 | W23: ='12'!F12 -> 65 | X23: =DELIVERIES!X23 -> 6 | Y23: =W23*X23 -> 390 | Z23: ='12'!F13 -> 48 | AA23: =DELIVERIES!AA23 -> 6 | AB23: =Z23*AA23 -> 288 | AC23: ='12'!F14 -> 21 | AD23: =DELIVERIES!AD23 -> 8 | AE23: =AC23*AD23 -> 168 | AG23: =AG7 -> 0 | AH23: =AF23*AG23 -> 0 | AK23: =D23+G23+J23+M23+P23+S23+V23+Y23+AB23+AE23+AH23 -> 12263.5 | AM23: ='12'!F17 -> 16 | AN23: =DELIVERIES!AQ23 -> 8.75 | AO23: =AM23*AN23 -> 140 | AP23: ='12'!F18 -> 44 | AQ23: =DELIVERIES!AT23 -> 12.25 | AR23: =AP23*AQ23 -> 539 | AS23: ='12'!F21 -> 0 | AT23: =DELIVERIES!AZ23 -> 9.7916667 | AU23: =AS23*AT23 -> 0 | AV23: ='12'!F22 -> 9 | AW23: =DELIVERIES!AZ23 -> 9.7916667 | AX23: =AV23*AW23 -> 88.125 | AY23: ='12'!F26 -> 0 | AZ23: =DELIVERIES!BC23 -> 16.333333 | BA23: =AY23*AZ23 -> 0 | BB23: ='12'!F27 -> 11 | BC23: =DELIVERIES!BF23 -> 11.666667 | BD23: =BB23*BC23 -> 128.33333 | BE23: ='12'!F28 -> 7 | BF23: =DELIVERIES!BI47 -> 20 | BG23: =BE23*BF23 -> 140 | BH23: ='12'!F23 -> 0 | BI23: =DELIVERIES!BL23 -> 23 | BJ23: =BH23*BI23 -> 0 | BK23: ='12'!F25 -> 0 | BL23: =DELIVERIES!BO23 -> 12.5 | BM23: =BK23*BL23 -> 0 | BN23: ='12'!F24 -> 2 | BO23: =DELIVERIES!BR23 -> 12.75 | BP23: =BN23*BO23 -> 25.5 | BQ23: ='12'!F19 -> 0 | BR23: =DELIVERIES!BU23 -> 30.25 | BS23: =BQ23*BR23 -> 0 | BT23: ='12'!F20 -> 0 | BU23: =DELIVERIES!BX23 -> 15.916667 | BV23: =BT23*BU23 -> 0 | BY23: =AO23+AR23+AU23+AX23+BA23+BD23+BG23+BJ23+BM23+BP23+BS23+BV23 -> 1060.9583 | CA23: =AK23+BY23 -> 13324.458 | CD23: =CA23-CC23 -> 13324.458
A24: 13 | B24: =GROSS!B24 -> 0 | C24: =DELIVERIES!C24 -> 30 | D24: =B24*C24 -> 0 | E24: ='13'!F7 -> 183 | F24: =DELIVERIES!F24 -> 35 | G24: =E24*F24 -> 6405 | H24: ='13'!F8 -> 6 | I24: =DELIVERIES!I24 -> 8.5 | J24: =H24*I24 -> 51 | K24: ='13'!F15 -> 11 | L24: =DELIVERIES!L24 -> 18 | M24: =K24*L24 -> 198 | N24: ='13'!F9 -> 89 | O24: =DELIVERIES!O24 -> 7 | P24: =N24*O24 -> 623 | Q24: ='13'!F10 -> 0 | R24: =DELIVERIES!R24 -> 5.5 | S24: =Q24*R24 -> 0 | T24: ='13'!F11 -> 169 | U24: =DELIVERIES!U24 -> 8.5 | V24: =T24*U24 -> 1436.5 | W24: ='13'!F12 -> 39 | X24: =DELIVERIES!X24 -> 6 | Y24: =W24*X24 -> 234 | Z24: ='13'!F13 -> 36 | AA24: =DELIVERIES!AA24 -> 6 | AB24: =Z24*AA24 -> 216 | AC24: ='13'!F14 -> 11 | AD24: =DELIVERIES!AD24 -> 8 | AE24: =AC24*AD24 -> 88 | AG24: =AG7 -> 0 | AH24: =AF24*AG24 -> 0 | AK24: =D24+G24+J24+M24+P24+S24+V24+Y24+AB24+AE24+AH24 -> 9251.5 | AM24: ='13'!F17 -> 17 | AN24: =DELIVERIES!AQ24 -> 8.75 | AO24: =AM24*AN24 -> 148.75 | AP24: ='13'!F18 -> 32 | AQ24: =DELIVERIES!AT24 -> 12.25 | AR24: =AP24*AQ24 -> 392 | AS24: ='13'!F21 -> 0 | AT24: =DELIVERIES!AZ24 -> 9.7916667 | AU24: =AS24*AT24 -> 0 | AV24: ='13'!F22 -> 6 | AW24: =DELIVERIES!AZ24 -> 9.7916667 | AX24: =AV24*AW24 -> 58.75 | AY24: ='13'!F26 -> 0 | AZ24: =DELIVERIES!BC24 -> 16.333333 | BA24: =AY24*AZ24 -> 0 | BB24: ='13'!F27 -> 0 | BC24: =DELIVERIES!BF24 -> 11.666667 | BD24: =BB24*BC24 -> 0 | BE24: ='13'!F28 -> 2 | BF24: =DELIVERIES!BI48 -> 20 | BG24: =BE24*BF24 -> 40 | BH24: ='13'!F23 -> 0 | BI24: =DELIVERIES!BL24 -> 23 | BJ24: =BH24*BI24 -> 0 | BK24: ='13'!F25 -> 0 | BL24: =DELIVERIES!BO24 -> 12.5 | BM24: =BK24*BL24 -> 0 | BN24: ='13'!F24 -> 2 | BO24: =DELIVERIES!BR24 -> 12.75 | BP24: =BN24*BO24 -> 25.5 | BQ24: ='13'!F19 -> 0 | BR24: =DELIVERIES!BU24 -> 30.25 | BS24: =BQ24*BR24 -> 0 | BT24: ='13'!F20 -> 0 | BU24: =DELIVERIES!BX24 -> 15.916667 | BV24: =BT24*BU24 -> 0 | BY24: =AO24+AR24+AU24+AX24+BA24+BD24+BG24+BJ24+BM24+BP24+BS24+BV24 -> 665 | CA24: =AK24+BY24 -> 9916.5 | CD24: =CA24-CC24 -> 9916.5
A25: 14 | B25: =GROSS!B25 -> 0 | C25: =DELIVERIES!C25 -> 30 | D25: =B25*C25 -> 0 | E25: ='14'!F7 -> 183 | F25: =DELIVERIES!F25 -> 35 | G25: =E25*F25 -> 6405 | H25: ='14'!F8 -> 3 | I25: =DELIVERIES!I25 -> 8.5 | J25: =H25*I25 -> 25.5 | K25: ='14'!F15 -> 10 | L25: =DELIVERIES!L25 -> 18 | M25: =K25*L25 -> 180 | N25: ='14'!F9 -> 111 | O25: =DELIVERIES!O25 -> 7 | P25: =N25*O25 -> 777 | Q25: ='14'!F10 -> 0 | R25: =DELIVERIES!R25 -> 5.5 | S25: =Q25*R25 -> 0 | T25: ='14'!F11 -> 167 | U25: =DELIVERIES!U25 -> 8.5 | V25: =T25*U25 -> 1419.5 | W25: ='14'!F12 -> 26 | X25: =DELIVERIES!X25 -> 6 | Y25: =W25*X25 -> 156 | Z25: ='14'!F13 -> 34 | AA25: =DELIVERIES!AA25 -> 6 | AB25: =Z25*AA25 -> 204 | AC25: ='14'!F14 -> 20 | AD25: =DELIVERIES!AD25 -> 8 | AE25: =AC25*AD25 -> 160 | AG25: =AG7 -> 0 | AH25: =AF25*AG25 -> 0 | AK25: =D25+G25+J25+M25+P25+S25+V25+Y25+AB25+AE25+AH25 -> 9327 | AM25: ='14'!F17 -> 13 | AN25: =DELIVERIES!AQ25 -> 8.75 | AO25: =AM25*AN25 -> 113.75 | AP25: ='14'!F18 -> 39 | AQ25: =DELIVERIES!AT25 -> 12.25 | AR25: =AP25*AQ25 -> 477.75 | AS25: ='14'!F21 -> 0 | AT25: =DELIVERIES!AZ25 -> 9.7916667 | AU25: =AS25*AT25 -> 0 | AV25: ='14'!F22 -> 10 | AW25: =DELIVERIES!AZ25 -> 9.7916667 | AX25: =AV25*AW25 -> 97.916667 | AY25: ='14'!F26 -> 0 | AZ25: =DELIVERIES!BC25 -> 16.333333 | BA25: =AY25*AZ25 -> 0 | BB25: ='14'!F27 -> 0 | BC25: =DELIVERIES!BF25 -> 11.666667 | BD25: =BB25*BC25 -> 0 | BE25: ='14'!F28 -> 8 | BF25: =DELIVERIES!BI49 -> 20 | BG25: =BE25*BF25 -> 160 | BH25: ='14'!F23 -> 0 | BI25: =DELIVERIES!BL25 -> 23 | BJ25: =BH25*BI25 -> 0 | BK25: ='14'!F25 -> 0 | BL25: =DELIVERIES!BO25 -> 12.5 | BM25: =BK25*BL25 -> 0 | BN25: ='14'!F24 -> 4 | BO25: =DELIVERIES!BR25 -> 12.75 | BP25: =BN25*BO25 -> 51 | BQ25: ='14'!F19 -> 0 | BR25: =DELIVERIES!BU25 -> 30.25 | BS25: =BQ25*BR25 -> 0 | BT25: ='14'!F20 -> 0 | BU25: =DELIVERIES!BX25 -> 15.916667 | BV25: =BT25*BU25 -> 0 | BY25: =AO25+AR25+AU25+AX25+BA25+BD25+BG25+BJ25+BM25+BP25+BS25+BV25 -> 900.41667 | CA25: =AK25+BY25 -> 10227.417 | CD25: =CA25-CC25 -> 10227.417
A26: TOTAL | B26: =SUM(B19:B25) -> 0 | D26: =SUM(D19:D25) -> 0 | E26: =SUM(E19:E25) -> 1496 | G26: =SUM(G19:G25) -> 52360 | H26: =SUM(H19:H25) -> 48 | J26: =SUM(J19:J25) -> 408 | K26: =SUM(K19:K25) -> 97 | M26: =SUM(M19:M25) -> 1746 | N26: =SUM(N19:N25) -> 614 | P26: =SUM(P19:P25) -> 4298 | Q26: =SUM(Q19:Q25) -> 0 | S26: =SUM(S19:S25) -> 0 | T26: =SUM(T19:T25) -> 1259 | V26: =SUM(V19:V25) -> 10701.5 | W26: =SUM(W19:W25) -> 290 | Y26: =SUM(Y19:Y25) -> 1740 | Z26: =SUM(Z19:Z25) -> 266 | AB26: =SUM(AB19:AB25) -> 1596 | AC26: =SUM(AC19:AC25) -> 80 | AE26: =SUM(AE19:AE25) -> 640 | AF26: =SUM(AF19:AF25) -> 0 | AH26: =SUM(AH19:AH25) -> 0 | AK26: =SUM(AK19:AK25) -> 73489.5 | AM26: =SUM(AM19:AM25) -> 93 | AO26: =SUM(AO19:AO25) -> 813.75 | AP26: =SUM(AP19:AP25) -> 242 | AR26: =SUM(AR19:AR25) -> 2964.5 | AS26: =SUM(AS19:AS25) -> 0 | AU26: =SUM(AU19:AU25) -> 0 | AV26: =SUM(AV19:AV25) -> 39 | AX26: =SUM(AX19:AX25) -> 381.875 | AY26: =SUM(AY19:AY25) -> 0 | BA26: =SUM(BA19:BA25) -> 0 | BB26: =SUM(BB19:BB25) -> 50 | BD26: =SUM(BD19:BD25) -> 576.83333 | BE26: =SUM(BE19:BE25) -> 25 | BG26: =SUM(BG19:BG25) -> 500 | BH26: =SUM(BH19:BH25) -> 0 | BJ26: =SUM(BJ19:BJ25) -> 0 | BK26: =SUM(BK19:BK25) -> 0 | BM26: =SUM(BM19:BM25) -> 0 | BN26: =SUM(BN19:BN25) -> 19 | BP26: =SUM(BP19:BP25) -> 242.25 | BQ26: =SUM(BQ19:BQ25) -> 0 | BS26: =SUM(BS19:BS25) -> 0 | BT26: =SUM(BT19:BT25) -> 0 | BV26: =SUM(BV19:BV25) -> 0 | BY26: =SUM(BY19:BY25) -> 5479.2083 | CA26: =SUM(CA19:CA25) -> 78968.708 | CD26: =SUM(CD19:CD25) -> 78968.708
A29: WEEK- 3 | B29: =B5 -> PREMIUM - CUT | E29: SPECIAL CUT | H29: NGOHIONG | K29: =K17 -> Chicken Fillet | N29: NECK | Q29: SIOMAI | T29: RICE | W29: BOLA-BOLA | Z29: LUMPIA | AC29: ATSARA | AF29: =AF5 -> 0 | AI29: =AI5 -> SUBTOTAL | AM29: 8OZ | AP29: 12 OZ | AS29: WATER 350 ML | AV29: WATER 500 ML | AY29: PANALO | BB29: =BB17 -> swakto | BE29: Calamansi Juice | BH29: =BH17 -> GATORADE | BK29: TROPICANA | BN29: STING | BQ29: =BQ17 -> 1 LITER | BT29: =BT17 -> 1.5 L | BW29: SUBTOTAL FOR DRINKS | CA29: TOTAL
A30: DATE | B30: QTY | C30: UP | D30: AMOUNT | E30: QTY | F30: UP | G30: AMOUNT | H30: QTY | I30: UP | J30: AMOUNT | K30: QTY | L30: UP | M30: AMOUNT | N30: QTY | O30: UP | P30: AMOUNT | Q30: QTY | R30: UP | S30: AMOUNT | T30: QTY | U30: UP | V30: AMOUNT | W30: QTY | X30: UP | Y30: AMOUNT | Z30: QTY | AA30: UP | AB30: AMOUNT | AC30: QTY | AD30: UP | AE30: AMOUNT | AF30: QTY | AG30: UP | AH30: AMOUNT | AK30: AMOUNT | AM30: QTY | AN30: UP | AO30: AMOUNT | AP30: QTY | AQ30: UP | AR30: AMOUNT | AS30: QTY | AT30: UP | AU30: AMOUNT | AV30: QTY | AW30: UP | AX30: AMOUNT | AY30: QTY | AZ30: UP | BA30: AMOUNT | BB30: QTY | BC30: UP | BD30: AMOUNT | BE30: QTY | BF30: UP | BG30: AMOUNT | BH30: QTY | BI30: UP | BJ30: AMOUNT | BK30: QTY | BL30: UP | BM30: AMOUNT | BN30: QTY | BO30: UP | BP30: AMOUNT | BQ30: QTY | BR30: UP | BS30: AMOUNT | BT30: QTY | BU30: UP | BV30: AMOUNT | BY30: AMOUNT | CA30: AMOUNT
A31: 15 | B31: =GROSS!B31 -> 0 | C31: =DELIVERIES!C31 -> 30 | D31: =B31*C31 -> 0 | E31: ='15'!F7 -> 238 | F31: =DELIVERIES!F31 -> 35 | G31: =E31*F31 -> 8330 | H31: ='15'!F8 -> 14 | I31: =DELIVERIES!I31 -> 8.5 | J31: =H31*I31 -> 119 | K31: ='15'!F15 -> 10 | L31: =DELIVERIES!L31 -> 18 | M31: =K31*L31 -> 180 | N31: ='15'!F9 -> 50 | O31: =DELIVERIES!O31 -> 7 | P31: =N31*O31 -> 350 | Q31: ='15'!F10 -> 0 | R31: =DELIVERIES!R31 -> 5.5 | S31: =Q31*R31 -> 0 | T31: ='15'!F11 -> 195 | U31: =DELIVERIES!U31 -> 8.5 | V31: =T31*U31 -> 1657.5 | W31: ='15'!F12 -> 36 | X31: =DELIVERIES!X31 -> 6 | Y31: =W31*X31 -> 216 | Z31: ='15'!F13 -> 42 | AA31: =DELIVERIES!AA31 -> 6 | AB31: =Z31*AA31 -> 252 | AC31: ='15'!F14 -> 12 | AD31: =DELIVERIES!AD31 -> 8 | AE31: =AC31*AD31 -> 96 | AG31: =AG7 -> 0 | AH31: =AF31*AG31 -> 0 | AK31: =D31+G31+J31+M31+P31+S31+V31+Y31+AB31+AE31+AH31 -> 11200.5 | AM31: ='15'!F17 -> 20 | AN31: =DELIVERIES!AQ31 -> 8.75 | AO31: =AM31*AN31 -> 175 | AP31: ='15'!F18 -> 54 | AQ31: =DELIVERIES!AT31 -> 12.25 | AR31: =AP31*AQ31 -> 661.5 | AS31: ='15'!F21 -> 0 | AT31: =DELIVERIES!AW31 -> 7.9166667 | AU31: =AS31*AT31 -> 0 | AV31: ='15'!F22 -> 6 | AW31: =DELIVERIES!AZ31 -> 9.7916667 | AX31: =AV31*AW31 -> 58.75 | AY31: ='15'!F26 -> 0 | AZ31: =DELIVERIES!BC31 -> 16.333333 | BA31: =AY31*AZ31 -> 0 | BB31: ='15'!F27 -> 0 | BC31: =DELIVERIES!BF31 -> 11.666667 | BD31: =BB31*BC31 -> 0 | BE31: ='15'!F28 -> 2 | BF31: =DELIVERIES!BI31 -> 20 | BG31: =BE31*BF31 -> 40 | BH31: ='15'!F23 -> 0 | BI31: =DELIVERIES!BL31 -> 23 | BJ31: =BH31*BI31 -> 0 | BK31: ='15'!F25 -> 0 | BL31: =DELIVERIES!BO31 -> 12.5 | BM31: =BK31*BL31 -> 0 | BN31: ='15'!F24 -> 3 | BO31: =DELIVERIES!BR31 -> 12.75 | BP31: =BN31*BO31 -> 38.25 | BQ31: ='15'!F19 -> 0 | BR31: =DELIVERIES!BU31 -> 30.25 | BS31: =BQ31*BR31 -> 0 | BT31: ='15'!F20 -> 0 | BU31: =DELIVERIES!BX31 -> 15.916667 | BV31: =BT31*BU31 -> 0 | BY31: =AO31+AR31+AU31+AX31+BA31+BD31+BG31+BJ31+BM31+BP31+BS31+BV31 -> 973.5 | CA31: =AK31+BY31 -> 12174 | CD31: =CA31-CC31 -> 12174
A32: 16 | B32: =GROSS!B32 -> 0 | C32: =DELIVERIES!C32 -> 30 | D32: =B32*C32 -> 0 | E32: ='16'!F7 -> 214 | F32: =DELIVERIES!F32 -> 35 | G32: =E32*F32 -> 7490 | H32: ='16'!F8 -> 6 | I32: =DELIVERIES!I32 -> 8.5 | J32: =H32*I32 -> 51 | K32: ='16'!F15 -> 20 | L32: =DELIVERIES!L32 -> 18 | M32: =K32*L32 -> 360 | N32: ='16'!F9 -> 80 | O32: =DELIVERIES!O32 -> 7 | P32: =N32*O32 -> 560 | Q32: ='16'!F10 -> 0 | R32: =DELIVERIES!R32 -> 5.5 | S32: =Q32*R32 -> 0 | T32: ='16'!F11 -> 204 | U32: =DELIVERIES!U32 -> 8.5 | V32: =T32*U32 -> 1734 | W32: ='16'!F12 -> 24 | X32: =DELIVERIES!X32 -> 6 | Y32: =W32*X32 -> 144 | Z32: ='16'!F13 -> 25 | AA32: =DELIVERIES!AA32 -> 6 | AB32: =Z32*AA32 -> 150 | AC32: ='16'!F14 -> 7 | AD32: =DELIVERIES!AD32 -> 8 | AE32: =AC32*AD32 -> 56 | AG32: =AG7 -> 0 | AH32: =AF32*AG32 -> 0 | AK32: =D32+G32+J32+M32+P32+S32+V32+Y32+AB32+AE32+AH32 -> 10545 | AM32: ='16'!F17 -> 9 | AN32: =DELIVERIES!AQ32 -> 8.75 | AO32: =AM32*AN32 -> 78.75 | AP32: ='16'!F18 -> 47 | AQ32: =DELIVERIES!AT32 -> 12.25 | AR32: =AP32*AQ32 -> 575.75 | AS32: ='16'!F21 -> 0 | AT32: =DELIVERIES!AW32 -> 7.9166667 | AU32: =AS32*AT32 -> 0 | AV32: ='16'!F22 -> 6 | AW32: =DELIVERIES!AZ32 -> 9.7916667 | AX32: =AV32*AW32 -> 58.75 | AY32: ='16'!F26 -> 0 | AZ32: =DELIVERIES!BC32 -> 16.333333 | BA32: =AY32*AZ32 -> 0 | BB32: ='16'!F27 -> 0 | BC32: =DELIVERIES!BF32 -> 11.666667 | BD32: =BB32*BC32 -> 0 | BE32: ='16'!F28 -> 6 | BF32: =DELIVERIES!BI32 -> 20 | BG32: =BE32*BF32 -> 120 | BH32: ='16'!F23 -> 0 | BI32: =DELIVERIES!BL32 -> 23 | BJ32: =BH32*BI32 -> 0 | BK32: ='16'!F25 -> 0 | BL32: =DELIVERIES!BO32 -> 12.5 | BM32: =BK32*BL32 -> 0 | BN32: ='16'!F24 -> 4 | BO32: =DELIVERIES!BR32 -> 12.75 | BP32: =BN32*BO32 -> 51 | BQ32: ='16'!F19 -> 0 | BR32: =DELIVERIES!BU32 -> 30.25 | BS32: =BQ32*BR32 -> 0 | BT32: ='16'!F20 -> 0 | BU32: =DELIVERIES!BX32 -> 15.916667 | BV32: =BT32*BU32 -> 0 | BY32: =AO32+AR32+AU32+AX32+BA32+BD32+BG32+BJ32+BM32+BP32+BS32+BV32 -> 884.25 | CA32: =AK32+BY32 -> 11429.25 | CD32: =CA32-CC32 -> 11429.25
A33: 17 | B33: =GROSS!B33 -> 0 | C33: =DELIVERIES!C33 -> 30 | D33: =B33*C33 -> 0 | E33: ='17'!F7 -> 217 | F33: =DELIVERIES!F33 -> 35 | G33: =E33*F33 -> 7595 | H33: ='17'!F8 -> 15 | I33: =DELIVERIES!I33 -> 8.5 | J33: =H33*I33 -> 127.5 | K33: ='17'!F15 -> 10 | L33: =DELIVERIES!L33 -> 18 | M33: =K33*L33 -> 180 | N33: ='17'!F9 -> 110 | O33: =DELIVERIES!O33 -> 7 | P33: =N33*O33 -> 770 | Q33: ='17'!F10 -> 0 | R33: =DELIVERIES!R33 -> 5.5 | S33: =Q33*R33 -> 0 | T33: ='17'!F11 -> 200 | U33: =DELIVERIES!U33 -> 8.5 | V33: =T33*U33 -> 1700 | W33: ='17'!F12 -> 34 | X33: =DELIVERIES!X33 -> 6 | Y33: =W33*X33 -> 204 | Z33: ='17'!F13 -> 31 | AA33: =DELIVERIES!AA33 -> 6 | AB33: =Z33*AA33 -> 186 | AC33: ='17'!F14 -> 0 | AD33: =DELIVERIES!AD33 -> 8 | AE33: =AC33*AD33 -> 0 | AG33: =AG7 -> 0 | AH33: =AF33*AG33 -> 0 | AK33: =D33+G33+J33+M33+P33+S33+V33+Y33+AB33+AE33+AH33 -> 10762.5 | AM33: ='17'!F17 -> 14 | AN33: =DELIVERIES!AQ33 -> 8.75 | AO33: =AM33*AN33 -> 122.5 | AP33: ='17'!F18 -> 45 | AQ33: =DELIVERIES!AT33 -> 12.25 | AR33: =AP33*AQ33 -> 551.25 | AS33: ='17'!F21 -> 0 | AT33: =DELIVERIES!AW33 -> 7.9166667 | AU33: =AS33*AT33 -> 0 | AV33: ='17'!F22 -> 9 | AW33: =DELIVERIES!AZ33 -> 9.7916667 | AX33: =AV33*AW33 -> 88.125 | AY33: ='17'!F26 -> 0 | AZ33: =DELIVERIES!BC33 -> 16.333333 | BA33: =AY33*AZ33 -> 0 | BB33: ='17'!F27 -> 0 | BC33: =DELIVERIES!BF33 -> 11.666667 | BD33: =BB33*BC33 -> 0 | BE33: ='17'!F28 -> 4 | BF33: =DELIVERIES!BI33 -> 20 | BG33: =BE33*BF33 -> 80 | BH33: ='17'!F23 -> 0 | BI33: =DELIVERIES!BL33 -> 23 | BJ33: =BH33*BI33 -> 0 | BK33: ='17'!F25 -> 0 | BL33: =DELIVERIES!BO33 -> 12.5 | BM33: =BK33*BL33 -> 0 | BN33: ='17'!F24 -> 1 | BO33: =DELIVERIES!BR33 -> 12.75 | BP33: =BN33*BO33 -> 12.75 | BQ33: ='17'!F19 -> 0 | BR33: =DELIVERIES!BU33 -> 30.25 | BS33: =BQ33*BR33 -> 0 | BT33: ='17'!F20 -> 0 | BU33: =DELIVERIES!BX33 -> 15.916667 | BV33: =BT33*BU33 -> 0 | BY33: =AO33+AR33+AU33+AX33+BA33+BD33+BG33+BJ33+BM33+BP33+BS33+BV33 -> 854.625 | CA33: =AK33+BY33 -> 11617.125 | CD33: =CA33-CC33 -> 11617.125
A34: 18 | B34: =GROSS!B34 -> 0 | C34: =DELIVERIES!C34 -> 30 | D34: =B34*C34 -> 0 | E34: ='18'!F7 -> 195 | F34: =DELIVERIES!F34 -> 35 | G34: =E34*F34 -> 6825 | H34: ='18'!F8 -> 23 | I34: =DELIVERIES!I34 -> 8.5 | J34: =H34*I34 -> 195.5 | K34: ='18'!F15 -> 20 | L34: =DELIVERIES!L34 -> 18 | M34: =K34*L34 -> 360 | N34: ='18'!F9 -> 100 | O34: =DELIVERIES!O34 -> 7 | P34: =N34*O34 -> 700 | Q34: ='18'!F10 -> 0 | R34: =DELIVERIES!R34 -> 5.5 | S34: =Q34*R34 -> 0 | T34: ='18'!F11 -> 197 | U34: =DELIVERIES!U34 -> 8.5 | V34: =T34*U34 -> 1674.5 | W34: ='18'!F12 -> 50 | X34: =DELIVERIES!X34 -> 6 | Y34: =W34*X34 -> 300 | Z34: ='18'!F13 -> 47 | AA34: =DELIVERIES!AA34 -> 6 | AB34: =Z34*AA34 -> 282 | AC34: ='18'!F14 -> 0 | AD34: =DELIVERIES!AD34 -> 8 | AE34: =AC34*AD34 -> 0 | AG34: =AG7 -> 0 | AH34: =AF34*AG34 -> 0 | AK34: =D34+G34+J34+M34+P34+S34+V34+Y34+AB34+AE34+AH34 -> 10337 | AM34: ='18'!F17 -> 13 | AN34: =DELIVERIES!AQ34 -> 8.75 | AO34: =AM34*AN34 -> 113.75 | AP34: ='18'!F18 -> 28 | AQ34: =DELIVERIES!AT34 -> 12.25 | AR34: =AP34*AQ34 -> 343 | AS34: ='18'!F21 -> 0 | AT34: =DELIVERIES!AW34 -> 7.9166667 | AU34: =AS34*AT34 -> 0 | AV34: ='18'!F22 -> 7 | AW34: =DELIVERIES!AZ34 -> 9.7916667 | AX34: =AV34*AW34 -> 68.541667 | AY34: ='18'!F26 -> 0 | AZ34: =DELIVERIES!BC34 -> 16.333333 | BA34: =AY34*AZ34 -> 0 | BB34: ='18'!F27 -> 0 | BC34: =DELIVERIES!BF34 -> 11.666667 | BD34: =BB34*BC34 -> 0 | BE34: ='18'!F28 -> 2 | BF34: =DELIVERIES!BI34 -> 20 | BG34: =BE34*BF34 -> 40 | BH34: ='18'!F23 -> 0 | BI34: =DELIVERIES!BL34 -> 23 | BJ34: =BH34*BI34 -> 0 | BK34: ='18'!F25 -> 0 | BL34: =DELIVERIES!BO34 -> 12.5 | BM34: =BK34*BL34 -> 0 | BN34: ='18'!F24 -> 1 | BO34: =DELIVERIES!BR34 -> 12.75 | BP34: =BN34*BO34 -> 12.75 | BQ34: ='18'!F19 -> 0 | BR34: =DELIVERIES!BU34 -> 30.416667 | BS34: =BQ34*BR34 -> 0 | BT34: ='18'!F20 -> 0 | BU34: =DELIVERIES!BX34 -> 15.916667 | BV34: =BT34*BU34 -> 0 | BY34: =AO34+AR34+AU34+AX34+BA34+BD34+BG34+BJ34+BM34+BP34+BS34+BV34 -> 578.04167 | CA34: =AK34+BY34 -> 10915.042 | CD34: =CA34-CC34 -> 10915.042
A35: 19 | B35: =GROSS!B35 -> 0 | C35: =DELIVERIES!C35 -> 30 | D35: =B35*C35 -> 0 | E35: ='19'!F7 -> 236 | F35: =DELIVERIES!F35 -> 35 | G35: =E35*F35 -> 8260 | H35: ='19'!F8 -> 5 | I35: =DELIVERIES!I35 -> 8.5 | J35: =H35*I35 -> 42.5 | K35: ='19'!F15 -> 25 | L35: =DELIVERIES!L35 -> 18 | M35: =K35*L35 -> 450 | N35: ='19'!F9 -> 120 | O35: =DELIVERIES!O35 -> 7 | P35: =N35*O35 -> 840 | Q35: ='19'!F10 -> 0 | R35: =DELIVERIES!R35 -> 5.5 | S35: =Q35*R35 -> 0 | T35: ='19'!F11 -> 229 | U35: =DELIVERIES!U35 -> 8.5 | V35: =T35*U35 -> 1946.5 | W35: ='19'!F12 -> 34 | X35: =DELIVERIES!X35 -> 6 | Y35: =W35*X35 -> 204 | Z35: ='19'!F13 -> 44 | AA35: =DELIVERIES!AA35 -> 6 | AB35: =Z35*AA35 -> 264 | AC35: ='19'!F14 -> 0 | AD35: =DELIVERIES!AD35 -> 8 | AE35: =AC35*AD35 -> 0 | AG35: =AG7 -> 0 | AH35: =AF35*AG35 -> 0 | AK35: =D35+G35+J35+M35+P35+S35+V35+Y35+AB35+AE35+AH35 -> 12007 | AM35: ='19'!F17 -> 21 | AN35: =DELIVERIES!AQ35 -> 8.75 | AO35: =AM35*AN35 -> 183.75 | AP35: ='19'!F18 -> 61 | AQ35: =DELIVERIES!AT35 -> 12.25 | AR35: =AP35*AQ35 -> 747.25 | AS35: ='19'!F21 -> 0 | AT35: =DELIVERIES!AW35 -> 7.9166667 | AU35: =AS35*AT35 -> 0 | AV35: ='19'!F22 -> 9 | AW35: =DELIVERIES!AZ35 -> 9.7916667 | AX35: =AV35*AW35 -> 88.125 | AY35: ='19'!F26 -> 0 | AZ35: =DELIVERIES!BC35 -> 16.333333 | BA35: =AY35*AZ35 -> 0 | BB35: ='19'!F27 -> 0 | BC35: =DELIVERIES!BF35 -> 11.666667 | BD35: =BB35*BC35 -> 0 | BE35: ='19'!F28 -> 1 | BF35: =DELIVERIES!BI35 -> 20 | BG35: =BE35*BF35 -> 20 | BH35: ='19'!F23 -> 0 | BI35: =DELIVERIES!BL35 -> 23 | BJ35: =BH35*BI35 -> 0 | BK35: ='19'!F25 -> 0 | BL35: =DELIVERIES!BO35 -> 12.5 | BM35: =BK35*BL35 -> 0 | BN35: ='19'!F24 -> 4 | BO35: =DELIVERIES!BR35 -> 12.75 | BP35: =BN35*BO35 -> 51 | BQ35: ='19'!F19 -> 0 | BR35: =DELIVERIES!BU35 -> 30.416667 | BS35: =BQ35*BR35 -> 0 | BT35: ='19'!F20 -> 0 | BU35: =DELIVERIES!BX35 -> 15.916667 | BV35: =BT35*BU35 -> 0 | BY35: =AO35+AR35+AU35+AX35+BA35+BD35+BG35+BJ35+BM35+BP35+BS35+BV35 -> 1090.125 | CA35: =AK35+BY35 -> 13097.125 | CD35: =CA35-CC35 -> 13097.125
A36: 20 | B36: =GROSS!B36 -> 0 | C36: =DELIVERIES!C36 -> 30 | D36: =B36*C36 -> 0 | E36: ='20'!F7 -> 176 | F36: =DELIVERIES!F36 -> 35 | G36: =E36*F36 -> 6160 | H36: ='20'!F8 -> 5 | I36: =DELIVERIES!I36 -> 8.5 | J36: =H36*I36 -> 42.5 | K36: ='20'!F15 -> 13 | L36: =DELIVERIES!L36 -> 18 | M36: =K36*L36 -> 234 | N36: ='20'!F9 -> 90 | O36: =DELIVERIES!O36 -> 7 | P36: =N36*O36 -> 630 | Q36: ='20'!F10 -> 0 | R36: =DELIVERIES!R36 -> 5.5 | S36: =Q36*R36 -> 0 | T36: ='20'!F11 -> 185 | U36: =DELIVERIES!U36 -> 8.5 | V36: =T36*U36 -> 1572.5 | W36: ='20'!F12 -> 25 | X36: =DELIVERIES!X36 -> 6 | Y36: =W36*X36 -> 150 | Z36: ='20'!F13 -> 25 | AA36: =DELIVERIES!AA36 -> 6 | AB36: =Z36*AA36 -> 150 | AC36: ='20'!F14 -> 0 | AD36: =DELIVERIES!AD36 -> 8 | AE36: =AC36*AD36 -> 0 | AG36: =AG7 -> 0 | AH36: =AF36*AG36 -> 0 | AK36: =D36+G36+J36+M36+P36+S36+V36+Y36+AB36+AE36+AH36 -> 8939 | AM36: ='20'!F17 -> 9 | AN36: =DELIVERIES!AQ36 -> 8.75 | AO36: =AM36*AN36 -> 78.75 | AP36: ='20'!F18 -> 44 | AQ36: =DELIVERIES!AT36 -> 12.25 | AR36: =AP36*AQ36 -> 539 | AS36: ='20'!F21 -> 0 | AT36: =DELIVERIES!AW36 -> 7.9166667 | AU36: =AS36*AT36 -> 0 | AV36: ='20'!F22 -> 12 | AW36: =DELIVERIES!AZ36 -> 9.7916667 | AX36: =AV36*AW36 -> 117.5 | AY36: ='20'!F26 -> 0 | AZ36: =DELIVERIES!BC36 -> 16.333333 | BA36: =AY36*AZ36 -> 0 | BB36: ='20'!F27 -> 0 | BC36: =DELIVERIES!BF36 -> 11.666667 | BD36: =BB36*BC36 -> 0 | BE36: ='20'!F28 -> 2 | BF36: =DELIVERIES!BI36 -> 20 | BG36: =BE36*BF36 -> 40 | BH36: ='20'!F23 -> 0 | BI36: =DELIVERIES!BL36 -> 23 | BJ36: =BH36*BI36 -> 0 | BK36: ='20'!F25 -> 0 | BL36: =DELIVERIES!BO36 -> 12.5 | BM36: =BK36*BL36 -> 0 | BN36: ='20'!F24 -> 2 | BO36: =DELIVERIES!BR36 -> 12.75 | BP36: =BN36*BO36 -> 25.5 | BQ36: ='20'!F19 -> 0 | BR36: =DELIVERIES!BU36 -> 30.416667 | BS36: =BQ36*BR36 -> 0 | BT36: ='20'!F20 -> 0 | BU36: =DELIVERIES!BX36 -> 15.916667 | BV36: =BT36*BU36 -> 0 | BY36: =AO36+AR36+AU36+AX36+BA36+BD36+BG36+BJ36+BM36+BP36+BS36+BV36 -> 800.75 | CA36: =AK36+BY36 -> 9739.75 | CD36: =CA36-CC36 -> 9739.75
