Workbook

Sheet Sheet4
B1: VITERBO FOODS OPC - CRISPY KING
B2: SALES COMPARISON
A4: 1 | B4: AYUNGON 2 | C4: 46023 | D4: 46054 | E4: 46082
B5: GROSS SALES | C5: 575689.5 | D5: 494977.5 | E5: 519613.5
B6: COST OF GOOGS | C6: 385184.17 | D6: 331160.57 | E6: 347500.32
B7: OPEX | C7: 141054.7 | D7: 135657.29 | E7: 126503.24
B8: NET INCOME | C8: =C5-C6-C7 -> 49450.63 | D8: =D5-D6-D7 -> 28159.64 | E8: =E5-E6-E7 -> 45609.94
A11: 2 | B11: AYUNGON 1 | C11: 46023 | D11: 46054 | E11: 46082
B12: GROSS SALES | C12: 824216 | D12: 668379 | E12: 730344
B13: COST OF GOOGS | C13: 552617.61 | D13: 448218.2 | E13: 489400.4
B14: OPEX | C14: 207819 | D14: 203708.17 | E14: 176377.34
B15: NET INCOME | C15: =C12-C13-C14 -> 63779.39 | D15: =D12-D13-D14 -> 16452.63 | E15: =E12-E13-E14 -> 64566.26
A18: 3 | B18: BACONG 1 | C18: 46023 | D18: 46054 | E18: 46082
B19: GROSS SALES | C19: 610111 | D19: 545964.5 | E19: 612575
B20: COST OF GOOGS | C20: 411472.29 | D20: 368801.04 | E20: 412999.13
B21: OPEX | C21: 156442.81 | D21: 167634.74 | E21: 143738.43
B22: NET INCOME | C22: =C19-C20-C21 -> 42195.9 | D22: =D19-D20-D21 -> 9528.72 | E22: =E19-E20-E21 -> 55837.44
A25: 4 | B25: BACONG 2 | C25: 46023 | D25: 46054 | E25: 46082
B26: GROSS SALES | C26: 304710.5 | D26: 288500 | E26: 321537
B27: COST OF GOOGS | C27: 203245.08 | D27: 193568.3 | E27: 214530.92
B28: OPEX | C28: 93880.29 | D28: 99903.41 | E28: 89396.54
B29: NET INCOME | C29: =C26-C27-C28 -> 7585.13 | D29: =D26-D27-D28 -> -4971.71 | E29: =E26-E27-E28 -> 17609.54
A32: 5 | B32: BAGACAY | C32: 46023 | D32: 46054 | E32: 46082
B33: GROSS SALES | C33: 550265 | D33: 505422 | E33: 569205
B34: COST OF GOOGS | C34: 369484.17 | D34: 338901.17 | E34: 382404.08
B35: OPEX | C35: 176413.58 | D35: 161950.04 | E35: 159564.85
B36: NET INCOME | C36: =C33-C34-C35 -> 4367.25 | D36: =D33-D34-D35 -> 4570.79 | E36: =E33-E34-E35 -> 27236.07
A39: 6 | B39: BAYAWAN | C39: 46023 | D39: 46054 | E39: 46082
B40: GROSS SALES | C40: 623237 | D40: 519687.5 | E40: 560768
B41: COST OF GOOGS | C41: 419147.42 | D41: 349199.05 | E41: 376312.23
B42: OPEX | C42: 182544.55 | D42: 136610.83 | E42: 150903.62
B43: NET INCOME | C43: =C40-C41-C42 -> 21545.03 | D43: =D40-D41-D42 -> 33877.62 | E43: =E40-E41-E42 -> 33552.15
A46: 7 | B46: BINDOY 1 | C46: 46023 | D46: 46054 | E46: 46082
B47: GROSS SALES | C47: 1092355 | D47: 949506.5 | E47: 1085109
B48: COST OF GOOGS | C48: 740138.61 | D48: 643565.89 | E48: 734897.52
B49: OPEX | C49: 232540.1 | D49: 209121.08 | E49: 207575.54
B50: NET INCOME | C50: =C47-C48-C49 -> 119676.29 | D50: =D47-D48-D49 -> 96819.53 | E50: =E47-E48-E49 -> 142635.94
A53: 8 | B53: BINDOY 2 | C53: 46023 | D53: 46054 | E53: 46082
B54: GROSS SALES | C54: 468779 | D54: 389125.5 | E54: 443250
B55: COST OF GOOGS | C55: 316349.25 | D55: 263201.5 | E55: 301039.26
...

Sheet JAN
A1: CRISPY KING FRANCHISE PERFORMANCE REPORT
A3: MONTH 2026 - AREA/REGION | BU3: CONSOLIDATED REPORT FOR THE MONTH OF JANUARY 2026
G5: DO NOT EDIT! | J5: DO NOT EDIT! | M5: DO NOT EDIT! | P5: DO NOT EDIT! | S5: DO NOT EDIT! | V5: DO NOT EDIT! | Y5: DO NOT EDIT! | AB5: DO NOT EDIT! | AE5: DO NOT EDIT! | AH5: DO NOT EDIT! | AK5: DO NOT EDIT! | AN5: DO NOT EDIT! | AR5: DO NOT EDIT! | AU5: DO NOT EDIT! | AX5: ! | AZ5: CAUTION! AUTO-FORMULA! DO NOT EDIT! | BI5: CAUTION! AUTO-FORMULA! DO NOT EDIT! | BV5: DO NOT EDIT! | CF5: CAUTION! AUTO-FORMULA! DO NOT EDIT!
A6: GROSS RANK | B6: MAN POWER | C6: BRANCH | D6: OWNER | E6: SALES SUPERVISOR | F6: QUANTITY SOLD | I6: S-CUT | L6: J-CUT | O6: RICE | R6: NECK(PCS) | U6: LUMPIA | X6: NGOHIONG | AA6: BOLA2X | AD6: C-FILLET | AG6: SIOMAI | AJ6: ATSARA (15) | AM6: ATSARA (12) | AP6: TOTAL OTHER PRODUCT | AW6: OTHER DRINKS SOLD | AX6: TOTAL QTY SOLD S.DRINKSPCS) | AZ6: CHICKEN VS RICE (50%) | BA6: CHICKEN VS OTHER PRODUCTS (20%) | BB6: RICE VS DRINKS (40%) | BC6: TOTAL AMOUNT FOR LPG % | BD6: TOTAL AMOUNT FOR BREADING% | BE6: TOTAL AMOUNT FOR OIL % | BF6: TOTAL AMOUNT FOR SAUCE % | BG6: TOTAL GROSS SALES | BH6: COST OF GOODS SOLD | BI6: COGS (%) | BJ6: TOTAL AMOUNT USAGES | BK6: USAGES (%) | BL6: MAN POWER | BM6: SALARY | BN6: SALARY (%) | BO6: OVERTIME | BP6: OVERTIME (%) | BQ6: RENT | BR6: RENT (%) | BS6: OPERATIONAL EXPENSES | BT6: OPERATION (%) | BU6: TOTAL OPEX | BV6: OPEX (%) | BW6: NET INCOME | BX6: NET (%) | BY6: NON - SALES ITEM | CK6: 20% ROYALTY SHARE
F7: CHICKEN 40(PCS) | G7: UNIT PRICE | H7: TOTAL AMOUNT | I7: QNTY | J7: UNIT PRICE | K7: TOTAL AMOUNT | L7: J -CUT 60 (PCS) | M7: UNIT PRICE | N7: TOTAL AMOUNT | O7: RICE(PCS) | P7: UNIT PRICE | Q7: TOTAL AMOUNT | R7: NECK(PCS) | S7: UNIT PRICE | T7: TOTAL AMOUNT | U7: LUMPIA(PCS) | V7: UNIT PRICE | W7: TOTAL AMOUNT | X7: NGOHIONG(PCS) | Y7: UNIT PRICE | Z7: TOTAL AMOUNT | AA7: BOLA2X(PCS) | AB7: UNIT PRICE | AC7: TOTAL AMOUNT | AD7: C. FILLET(PCS) | AE7: UNIT PRICE | AF7: TOTAL AMOUNT | AG7: SIOMAI(PCS) | AH7: UNIT PRICE | AI7: TOTAL AMOUNT | AJ7: ATSARA( 15 ) | AK7: UNIT PRICE | AL7: TOTAL AMOUNT | AM7: ATSARA( 12 ) | AN7: UNIT PRICE | AO7: TOTAL AMOUNT | AQ7: 1 LITER | AR7: PCS *4 | AS7: TOTAL PCS | AT7: 1.5 LITER | AU7: PCS * 6 | AV7: TOTAL PCS | AY7: TOTAL AMOUNT | BY7: LPG | BZ7: BREADING | CA7: OIL | CB7: SAUCE | CC7: SALARY | CD7: OVERTIME | CE7: RENT | CF7: LPG | CG7: BREADING | CH7: OIL | CI7: SAUCE | CJ7: SALARY
A8: 1 | B8: 4 | C8: AYUNGON 2 | G8: 40 | H8: =SUM(F8*G8) -> 0 | I8: 9033 | J8: 50 | K8: =J8*I8 -> 451650 | M8: 60 | N8: =M8*L8 -> 0 | O8: 3130 | P8: 12 | Q8: =O8*P8 -> 37560 | R8: 1608 | S8: 12 | T8: =R8*S8 -> 19296 | U8: 852 | V8: 8 | W8: =U8*V8 -> 6816 | X8: 556 | Y8: 12 | Z8: =X8*Y8 -> 6672 | AA8: 1103 | AB8: 10 | AC8: =AA8*AB8 -> 11030 | AD8: 236 | AE8: 25 | AF8: =AD8*AE8 -> 5900 | AG8: 257 | AH8: 7.5 | AI8: =AG8*AH8 -> 1927.5 | AK8: 15 | AL8: =AJ8*AK8 -> 0 | AM8: 180 | AN8: 10 | AO8: =AM8*AN8 -> 1800 | AP8: =R8+U8+X8+AA8+AD8+AG8+AM8 -> 4792 | AX8: =936+168+346+156+42 -> 1648 | AZ8: =O8/(I8+F8+L8) -> 0.34650725 | BA8: =AP8/(I8+F8+L8) -> 0.53049928 | BB8: =AX8/O8 -> 0.52651757 | BC8: =H8+W8+Z8+AC8+AF8+T8+K8+N8 -> 501364 | BD8: =H8+AF8+T8+K8+N8 -> 476846 | BE8: =H8+W8+Z8+AC8+AF8+T8+K8+N8 -> 501364 | BF8: =H8+W8+Z8+AC8+AF8+AI8+T8+K8+N8 -> 503291.5 | BG8: 575689.5 | BH8: 385184.17 | BI8: =+BH8/BG8% -> 66.90832 | BJ8: =SUM(BY8+BZ8+CA8+CB8) -> 36410 | BK8: =SUM(CF8+CG8+CH8+CI8) -> 0.063245899 | BL8: =B8 -> 4 | BM8: =CC8 -> 56211 | BN8: =+BU8/BM8 -> 2.5093789 | BO8: =CD8 -> 875 | BP8: =+BU8/BO8 -> 161.20537 | BQ8: =CE8 -> 20000 | BR8: =+BU8/BQ8 -> 7.052735 | BS8: =BU8-BM8-BO8-BQ8-BY8-BZ8-CA8-CB8 -> 27558.7 | BT8: =+BU8/BS8 -> 5.1183365 | BU8: 141054.7 | BV8: =+BU8/BG8% -> 24.501871 | BW8: =SUM(BG8-BH8-BU8) -> 49450.63 | BX8: =+BW8/BG8% -> 8.5898093 | BY8: 14719 | BZ8: 7955 | CA8: 10496 | CB8: 3240 | CC8: 56211 | CD8: 875 | CE8: 20000 | CF8: =BY8/BG8 -> 0.025567602 | CG8: =BZ8/BG8 -> 0.013818213 | CH8: =CA8/BG8 -> 0.01823205 | CI8: =CB8/BG8 -> 0.0056280339 | CJ8: =CC8/BG8 -> 0.097641176 | CK8: =+BW8*20% -> 9890.126
A9: =A8+1 -> 2 | B9: 5 | C9: AYUNGON 1 | G9: 40 | H9: =SUM(F9*G9) -> 0 | I9: 13187 | J9: 50 | K9: =J9*I9 -> 659350 | M9: 60 | N9: =M9*L9 -> 0 | O9: 5612 | P9: 12 | Q9: =O9*P9 -> 67344 | R9: 1684 | S9: 12 | T9: =R9*S9 -> 20208 | U9: 726 | V9: 8 | W9: =U9*V9 -> 5808 | X9: 489 | Y9: 12 | Z9: =X9*Y9 -> 5868 | AA9: 989 | AB9: 10 | AC9: =AA9*AB9 -> 9890 | AD9: 274 | AE9: 25 | AF9: =AD9*AE9 -> 6850 | AG9: 144 | AH9: 7.5 | AI9: =AG9*AH9 -> 1080 | AK9: 15 | AL9: =AJ9*AK9 -> 0 | AM9: 180 | AN9: 10 | AO9: =AM9*AN9 -> 1800 | AP9: =R9+U9+X9+AA9+AD9+AG9+AM9 -> 4486 | AX9: =1343+223+360+95+331+83 -> 2435 | AZ9: =O9/(I9+F9+L9) -> 0.42557064 | BA9: =AP9/(I9+F9+L9) -> 0.34018351 | BB9: =AX9/O9 -> 0.43389166 | BC9: =H9+W9+Z9+AC9+AF9+T9+K9+N9 -> 707974 | BD9: =H9+AF9+T9+K9+N9 -> 686408 | BE9: =H9+W9+Z9+AC9+AF9+T9+K9+N9 -> 707974 | BF9: =H9+W9+Z9+AC9+AF9+AI9+T9+K9+N9 -> 709054 | BG9: 824216 | BH9: 552617.61 | BI9: =+BH9/BG9% -> 67.047668 | BJ9: =SUM(BY9+BZ9+CA9+CB9) -> 55735 | BK9: =SUM(CF9+CG9+CH9+CI9) -> 0.067621837 | BL9: =B9 -> 5 | BM9: =CC9 -> 71152 | BN9: =+BU9/BM9 -> 2.9207821 | BO9: =CD9 -> 1062.5 | BP9: =+BU9/BO9 -> 195.59481 | BQ9: =CE9 -> 31500 | BR9: =+BU9/BQ9 -> 6.5974441 | BS9: =BU9-BM9-BO9-BQ9-BY9-BZ9-CA9-CB9 -> 48369.99 | BT9: =+BU9/BS9 -> 4.2964551 | BU9: 207819.49 | BV9: =+BU9/BG9% -> 25.214202 | BW9: =SUM(BG9-BH9-BU9) -> 63778.9 | BX9: =+BW9/BG9% -> 7.7381293 | BY9: 22133 | BZ9: 12728 | CA9: 15744 | CB9: 5130 | CC9: 71152 | CD9: 1062.5 | CE9: 31500 | CF9: =BY9/BG9 -> 0.026853398 | CG9: =BZ9/BG9 -> 0.015442554 | CH9: =CA9/BG9 -> 0.019101789 | CI9: =CB9/BG9 -> 0.0062240966 | CJ9: =CC9/BG9 -> 0.086326885 | CK9: =+BW9*20% -> 12755.78
A10: =A9+1 -> 3 | B10: 4 | C10: BACONG 1 | G10: 40 | H10: =SUM(F10*G10) -> 0 | I10: 8461 | J10: 50 | K10: =J10*I10 -> 423050 | M10: 60 | N10: =M10*L10 -> 0 | O10: 5149 | P10: 12 | Q10: =O10*P10 -> 61788 | R10: 4313 | S10: 12 | T10: =R10*S10 -> 51756 | U10: 1115 | V10: 8 | W10: =U10*V10 -> 8920 | X10: 245 | Y10: 12 | Z10: =X10*Y10 -> 2940 | AA10: 1011 | AB10: 10 | AC10: =AA10*AB10 -> 10110 | AD10: 415 | AE10: 25 | AF10: =AD10*AE10 -> 10375 | AG10: 724 | AH10: 7.5 | AI10: =AG10*AH10 -> 5430 | AK10: 15 | AL10: =AJ10*AK10 -> 0 | AM10: 297 | AN10: 10 | AO10: =AM10*AN10 -> 2970 | AP10: =R10+U10+X10+AA10+AD10+AG10+AM10 -> 8120 | AX10: =294+983+136+177+114 -> 1704 | AZ10: =O10/(I10+F10+L10) -> 0.60855691 | BA10: =AP10/(I10+F10+L10) -> 0.95969744 | BB10: =AX10/O10 -> 0.33093805 | BC10: =H10+W10+Z10+AC10+AF10+T10+K10+N10 -> 507151 | BD10: =H10+AF10+T10+K10+N10 -> 485181 | BE10: =H10+W10+Z10+AC10+AF10+T10+K10+N10 -> 507151 | BF10: =H10+W10+Z10+AC10+AF10+AI10+T10+K10+N10 -> 512581 | BG10: 610111 | BH10: 411472.29 | BI10: =+BH10/BG10% -> 67.442202 | BJ10: =SUM(BY10+BZ10+CA10+CB10) -> 34941.5 | BK10: =SUM(CF10+CG10+CH10+CI10) -> 0.057270726 | BL10: =B10 -> 4 | BM10: =CC10 -> 70525 | BN10: =+BU10/BM10 -> 2.2182603 | BO10: =CD10 -> 750 | BP10: =+BU10/BO10 -> 208.59041 | BQ10: =CE10 -> 16000 | BR10: =+BU10/BQ10 -> 9.7776756 | BS10: =BU10-BM10-BO10-BQ10-BY10-BZ10-CA10-CB10 -> 34226.31 | BT10: =+BU10/BS10 -> 4.5708348 | BU10: 156442.81 | BV10: =+BU10/BG10% -> 25.641696 | BW10: =SUM(BG10-BH10-BU10) -> 42195.9 | BX10: =+BW10/BG10% -> 6.9161022 | BY10: 11119.5 | BZ10: 9546 | CA10: 10496 | CB10: 3780 | CC10: 70525 | CD10: 750 | CE10: 16000 | CF10: =BY10/BG10 -> 0.018225372 | CG10: =BZ10/BG10 -> 0.015646333 | CH10: =CA10/BG10 -> 0.017203427 | CI10: =CB10/BG10 -> 0.0061955939 | CJ10: =CC10/BG10 -> 0.11559372 | CK10: =+BW10*20% -> 8439.18
A11: =A10+1 -> 4 | B11: 2 | C11: BACONG2 | G11: 40 | H11: =SUM(F11*G11) -> 0 | I11: 3994 | J11: 50 | K11: =J11*I11 -> 199700 | M11: 60 | N11: =M11*L11 -> 0 | O11: 2381 | P11: 12 | Q11: =O11*P11 -> 28572 | R11: 3438 | S11: 12 | T11: =R11*S11 -> 41256 | U11: 371 | V11: 8 | W11: =U11*V11 -> 2968 | X11: 130 | Y11: 12 | Z11: =X11*Y11 -> 1560 | AA11: 370 | AB11: 10 | AC11: =AA11*AB11 -> 3700 | AD11: 174 | AE11: 25 | AF11: =AD11*AE11 -> 4350 | AG11: 197 | AH11: 7.5 | AI11: =AG11*AH11 -> 1477.5 | AK11: 15 | AL11: =AJ11*AK11 -> 0 | AM11: 172 | AN11: 10 | AO11: =AM11*AN11 -> 1720 | AP11: =R11+U11+X11+AA11+AD11+AG11+AM11 -> 4852 | AX11: 1014 | AZ11: =O11/(I11+F11+L11) -> 0.59614422 | BA11: =AP11/(I11+F11+L11) -> 1.2148222 | BB11: =AX11/O11 -> 0.42587148 | BC11: =H11+W11+Z11+AC11+AF11+T11+K11+N11 -> 253534 | BD11: =H11+AF11+T11+K11+N11 -> 245306 | BE11: =H11+W11+Z11+AC11+AF11+T11+K11+N11 -> 253534 | BF11: =H11+W11+Z11+AC11+AF11+AI11+T11+K11+N11 -> 255011.5 | BG11: 304710.5 | BH11: 203245.08 | BI11: =+BH11/BG11% -> 66.701042 | BJ11: =SUM(BY11+BZ11+CA11+CB11) -> 21455 | BK11: =SUM(CF11+CG11+CH11+CI11) -> 0.070411095 | BL11: =B11 -> 2 | BM11: =CC11 -> 35637.5 | BN11: =+BU11/BM11 -> 2.6343119 | BO11: =CD11 -> 3156.25 | BP11: =+BU11/BO11 -> 29.74425 | BQ11: =CE11 -> 8269 | BR11: =+BU11/BQ11 -> 11.353282 | BS11: =BU11-BM11-BO11-BQ11-BY11-BZ11-CA11-CB11 -> 25362.54 | BT11: =+BU11/BS11 -> 3.7015334 | BU11: 93880.29 | BV11: =+BU11/BG11% -> 30.809667 | BW11: =SUM(BG11-BH11-BU11) -> 7585.13 | BX11: =+BW11/BG11% -> 2.4892907 | BY11: 7413 | BZ11: 6364 | CA11: 5248 | CB11: 2430 | CC11: 35637.5 | CD11: 3156.25 | CE11: 8269 | CF11: =BY11/BG11 -> 0.02432801 | CG11: =BZ11/BG11 -> 0.020885398 | CH11: =CA11/BG11 -> 0.017222905 | CI11: =CB11/BG11 -> 0.0079747826 | CJ11: =CC11/BG11 -> 0.11695527 | CK11: =+BW11*20% -> 1517.026
A12: =A11+1 -> 5 | B12: 4 | C12: BAGACAY | G12: 40 | H12: =SUM(F12*G12) -> 0 | I12: 7383 | J12: 50 | K12: =J12*I12 -> 369150 | M12: 60 | N12: =M12*L12 -> 0 | O12: 6567 | P12: 12 | Q12: =O12*P12 -> 78804 | R12: 1880 | S12: 12 | T12: =R12*S12 -> 22560 | U12: 1209 | V12: 8 | W12: =U12*V12 -> 9672 | X12: 523 | Y12: 12 | Z12: =X12*Y12 -> 6276 | AA12: 919 | AB12: 10 | AC12: =AA12*AB12 -> 9190 | AD12: 315 | AE12: 25 | AF12: =AD12*AE12 -> 7875 | AG12: 540 | AH12: 7.5 | AI12: =AG12*AH12 -> 4050 | AK12: 15 | AL12: =AJ12*AK12 -> 0 | AM12: 226 | AN12: 10 | AO12: =AM12*AN12 -> 2260 | AP12: =R12+U12+X12+AA12+AD12+AG12+AM12 -> 5612 | AX12: 2175 | AZ12: =O12/(I12+F12+L12) -> 0.88947582 | BA12: =AP12/(I12+F12+L12) -> 0.76012461 | BB12: =AX12/O12 -> 0.33120146 | BC12: =H12+W12+Z12+AC12+AF12+T12+K12+N12 -> 424723 | BD12: =H12+AF12+T12+K12+N12 -> 399585 | BE12: =H12+W12+Z12+AC12+AF12+T12+K12+N12 -> 424723 | BF12: =H12+W12+Z12+AC12+AF12+AI12+T12+K12+N12 -> 428773 | BG12: 550265 | BH12: 369484.17 | BI12: =+BH12/BG12% -> 67.146588 | BJ12: =SUM(BY12+BZ12+CA12+CB12) -> 36833.75 | BK12: =SUM(CF12+CG12+CH12+CI12) -> 0.066938203 | BL12: =B12 -> 4 | BM12: =CC12 -> 62525 | BN12: =+BU12/BM12 -> 2.8214887 | BO12: =CD12 -> 375 | BP12: =+BU12/BO12 -> 470.43621 | BQ12: =CE12 -> 28000 | BR12: =+BU12/BQ12 -> 6.300485 | BS12: =BU12-BM12-BO12-BQ12-BY12-BZ12-CA12-CB12 -> 48679.83 | BT12: =+BU12/BS12 -> 3.6239564 | BU12: 176413.58 | BV12: =+BU12/BG12% -> 32.059749 | BW12: =SUM(BG12-BH12-BU12) -> 4367.25 | BX12: =+BW12/BG12% -> 0.79366305 | BY12: 11119.5 | BZ12: 11137 | CA12: 10797.25 | CB12: 3780 | CC12: 62525 | CD12: 375 | CE12: 28000 | CF12: =BY12/BG12 -> 0.020207536 | CG12: =BZ12/BG12 -> 0.020239339 | CH12: =CA12/BG12 -> 0.019621909 | CI12: =CB12/BG12 -> 0.0068694175 | CJ12: =CC12/BG12 -> 0.11362707 | CK12: =+BW12*20% -> 873.45
A13: =A12+1 -> 6 | B13: 4 | C13: BAYAWAN | G13: 40 | H13: =SUM(F13*G13) -> 0 | I13: 10401 | J13: 50 | K13: =J13*I13 -> 520050 | M13: 60 | N13: =M13*L13 -> 0 | O13: 3494 | P13: 12 | Q13: =O13*P13 -> 41928 | S13: 12 | T13: =R13*S13 -> 0 | U13: 800 | V13: 8 | W13: =U13*V13 -> 6400 | X13: 522 | Y13: 12 | Z13: =X13*Y13 -> 6264 | AA13: 1086 | AB13: 10 | AC13: =AA13*AB13 -> 10860 | AD13: 340 | AE13: 25 | AF13: =AD13*AE13 -> 8500 | AG13: 369 | AH13: 7.5 | AI13: =AG13*AH13 -> 2767.5 | AK13: 15 | AL13: =AJ13*AK13 -> 0 | AN13: 10 | AO13: =AM13*AN13 -> 0 | AP13: =R13+U13+X13+AA13+AD13+AG13+AM13 -> 3117 | AX13: 1309 | AZ13: =O13/(I13+F13+L13) -> 0.33592924 | BA13: =AP13/(I13+F13+L13) -> 0.29968272 | BB13: =AX13/O13 -> 0.37464224 | BC13: =H13+W13+Z13+AC13+AF13+T13+K13+N13 -> 552074 | BD13: =H13+AF13+T13+K13+N13 -> 528550 | BE13: =H13+W13+Z13+AC13+AF13+T13+K13+N13 -> 552074 | BF13: =H13+W13+Z13+AC13+AF13+AI13+T13+K13+N13 -> 554841.5 | BG13: 623237 | BH13: 419147.42 | BI13: =+BH13/BG13% -> 67.253295 | BJ13: =SUM(BY13+BZ13+CA13+CB13) -> 53815 | BK13: =SUM(CF13+CG13+CH13+CI13) -> 0.086347569 | BL13: =B13 -> 4 | BM13: =CC13 -> 62339 | BN13: =+BU13/BM13 -> 2.928256 | BO13: =CD13 -> 4687 | BP13: =+BU13/BO13 -> 38.946992 | BQ13: =CE13 -> 13000 | BR13: =+BU13/BQ13 -> 14.041888 | BS13: =BU13-BM13-BO13-BQ13-BY13-BZ13-CA13-CB13 -> 48703.55 | BT13: =+BU13/BS13 -> 3.7480748 | BU13: 182544.55 | BV13: =+BU13/BG13% -> 29.289749 | BW13: =SUM(BG13-BH13-BU13) -> 21545.03 | BX13: =+BW13/BG13% -> 3.4569562 | BY13: 18314 | BZ13: 14319 | CA13: 16862 | CB13: 4320 | CC13: 62339 | CD13: 4687 | CE13: 13000 | CF13: =BY13/BG13 -> 0.02938529 | CG13: =BZ13/BG13 -> 0.022975208 | CH13: =CA13/BG13 -> 0.027055518 | CI13: =CB13/BG13 -> 0.0069315525 | CJ13: =CC13/BG13 -> 0.10002455 | CK13: =+BW13*20% -> 4309.006
A14: =A13+1 -> 7 | B14: 7 | C14: BINDOY1 | G14: 40 | H14: =SUM(F14*G14) -> 0 | I14: 18741 | J14: 50 | K14: =J14*I14 -> 937050 | M14: 60 | N14: =M14*L14 -> 0 | O14: 6194 | P14: 12 | Q14: =O14*P14 -> 74328 | S14: 12 | T14: =R14*S14 -> 0 | U14: 1048 | V14: 8 | W14: =U14*V14 -> 8384 | X14: 436 | Y14: 12 | Z14: =X14*Y14 -> 5232 | AA14: 1294 | AB14: 10 | AC14: =AA14*AB14 -> 12940 | AD14: 350 | AE14: 25 | AF14: =AD14*AE14 -> 8750 | AG14: 292 | AH14: 7.5 | AI14: =AG14*AH14 -> 2190 | AK14: 15 | AL14: =AJ14*AK14 -> 0 | AM14: 360 | AN14: 10 | AO14: =AM14*AN14 -> 3600 | AP14: =R14+U14+X14+AA14+AD14+AG14+AM14 -> 3780 | AX14: 2224 | AZ14: =O14/(I14+F14+L14) -> 0.33050531 | BA14: =AP14/(I14+F14+L14) -> 0.20169681 | BB14: =AX14/O14 -> 0.35905715 | BC14: =H14+W14+Z14+AC14+AF14+T14+K14+N14 -> 972356 | BD14: =H14+AF14+T14+K14+N14 -> 945800 | BE14: =H14+W14+Z14+AC14+AF14+T14+K14+N14 -> 972356 | BF14: =H14+W14+Z14+AC14+AF14+AI14+T14+K14+N14 -> 974546 | BG14: 1092355 | BH14: 740138.61 | BI14: =+BH14/BG14% -> 67.756234 | BJ14: =SUM(BY14+BZ14+CA14+CB14) -> 67338 | BK14: =SUM(CF14+CG14+CH14+CI14) -> 0.061644795 | BL14: =B14 -> 7 | BM14: =CC14 -> 92737.5 | BN14: =+BU14/BM14 -> 2.5075088 | BO14: =CD14 -> 2750 | BP14: =+BU14/BO14 -> 84.560036 | BQ14: =CE14 -> 14500 | BR14: =+BU14/BQ14 -> 16.037248 | BS14: =BU14-BM14-BO14-BQ14-BY14-BZ14-CA14-CB14 -> 55214.6 | BT14: =+BU14/BS14 -> 4.211569 | BU14: 232540.1 | BV14: =+BU14/BG14% -> 21.28796 | BW14: =SUM(BG14-BH14-BU14) -> 119676.29 | BX14: =+BW14/BG14% -> 10.955806 | BY14: 22133 | BZ14: 17501 | CA14: 22304 | CB14: 5400 | CC14: 92737.5 | CD14: 2750 | CE14: 14500 | CF14: =BY14/BG14 -> 0.020261728 | CG14: =BZ14/BG14 -> 0.016021348 | CH14: =CA14/BG14 -> 0.020418271 | CI14: =CB14/BG14 -> 0.0049434479 | CJ14: =CC14/BG14 -> 0.084896851 | CK14: =+BW14*20% -> 23935.258
A15: =A14+1 -> 8 | B15: 3 | C15: BINDOY2 | G15: 40 | H15: =SUM(F15*G15) -> 0 | I15: 7410 | J15: 50 | K15: =J15*I15 -> 370500 | M15: 60 | N15: =M15*L15 -> 0 | O15: 2269 | P15: 12 | Q15: =O15*P15 -> 27228 | R15: 3120 | S15: 12 | T15: =R15*S15 -> 37440 | U15: 506 | V15: 8 | W15: =U15*V15 -> 4048 | X15: 299 | Y15: 12 | Z15: =X15*Y15 -> 3588 | AA15: 722 | AB15: 10 | AC15: =AA15*AB15 -> 7220 | AD15: 140 | AE15: 25 | AF15: =AD15*AE15 -> 3500 | AG15: 122 | AH15: 7.5 | AI15: =AG15*AH15 -> 915 | AK15: 15 | AL15: =AJ15*AK15 -> 0 | AM15: 148 | AN15: 10 | AO15: =AM15*AN15 -> 1480 | AP15: =R15+U15+X15+AA15+AD15+AG15+AM15 -> 5057 | AX15: 677 | AZ15: =O15/(I15+F15+L15) -> 0.30620783 | BA15: =AP15/(I15+F15+L15) -> 0.68245614 | BB15: =AX15/O15 -> 0.29836933 | BC15: =H15+W15+Z15+AC15+AF15+T15+K15+N15 -> 426296 | BD15: =H15+AF15+T15+K15+N15 -> 411440 | BE15: =H15+W15+Z15+AC15+AF15+T15+K15+N15 -> 426296 | BF15: =H15+W15+Z15+AC15+AF15+AI15+T15+K15+N15 -> 427211 | BG15: 468779 | BH15: 316349.25 | BI15: =+BH15/BG15% -> 67.483665 | BJ15: =SUM(BY15+BZ15+CA15+CB15) -> 33854 | BK15: =SUM(CF15+CG15+CH15+CI15) -> 0.072217399 | BL15: =B15 -> 3 | BM15: =CC15 -> 49012.5 | BN15: =+BU15/BM15 -> 2.6190258 | BO15: =CD15 -> 3687.5 | BP15: =+BU15/BO15 -> 34.810847 | BQ15: =CE15 -> 15000 | BR15: =+BU15/BQ15 -> 8.5576667 | BS15: =BU15-BM15-BO15-BQ15-BY15-BZ15-CA15-CB15 -> 26811 | BT15: =+BU15/BS15 -> 4.7877737 | BU15: 128365 | BV15: =+BU15/BG15% -> 27.382839 | BW15: =SUM(BG15-BH15-BU15) -> 24064.75 | BX15: =+BW15/BG15% -> 5.1334957 | BY15: 11121 | BZ15: 7955 | CA15: 11808 | CB15: 2970 | CC15: 49012.5 | CD15: 3687.5 | CE15: 15000 | CF15: =BY15/BG15 -> 0.023723332 | CG15: =BZ15/BG15 -> 0.016969617 | CH15: =CA15/BG15 -> 0.025188842 | CI15: =CB15/BG15 -> 0.006335608 | CJ15: =CC15/BG15 -> 0.10455353 | CK15: =+BW15*20% -> 4812.95
A16: =A15+1 -> 9 | B16: 4 | C16: CADIZ 3 | G16: 40 | H16: =SUM(F16*G16) -> 0 | I16: 10625 | J16: 50 | K16: =J16*I16 -> 531250 | M16: 60 | N16: =M16*L16 -> 0 | O16: 4094 | P16: 12 | Q16: =O16*P16 -> 49128 | R16: 1470 | S16: 12 | T16: =R16*S16 -> 17640 | U16: 394 | V16: 8 | W16: =U16*V16 -> 3152 | X16: 210 | Y16: 12 | Z16: =X16*Y16 -> 2520 | AA16: 483 | AB16: 10 | AC16: =AA16*AB16 -> 4830 | AD16: 164 | AE16: 25 | AF16: =AD16*AE16 -> 4100 | AG16: 80 | AH16: 7.5 | AI16: =AG16*AH16 -> 600 | AK16: 15 | AL16: =AJ16*AK16 -> 0 | AN16: 12 | AO16: =AM16*AN16 -> 0 | AP16: =R16+U16+X16+AA16+AD16+AG16+AM16 -> 2801 | AX16: 1515 | AZ16: =O16/(I16+F16+L16) -> 0.38531765 | BA16: =AP16/(I16+F16+L16) -> 0.26362353 | BB16: =AX16/O16 -> 0.37005374 | BC16: =H16+W16+Z16+AC16+AF16+T16+K16+N16 -> 563492 | BD16: =H16+AF16+T16+K16+N16 -> 552990 | BE16: =H16+W16+Z16+AC16+AF16+T16+K16+N16 -> 563492 | BF16: =H16+W16+Z16+AC16+AF16+AI16+T16+K16+N16 -> 564092 | BG16: 641725 | BH16: 427735.27 | BI16: =+BH16/BG16% -> 66.653983 | BJ16: =SUM(BY16+BZ16+CA16+CB16) -> 38703 | BK16: =SUM(CF16+CG16+CH16+CI16) -> 0.060310881 | BL16: =B16 -> 4 | BM16: =CC16 -> 65997.6 | BN16: =+BU16/BM16 -> 2.6657053 | BO16: =CD16 -> 1731 | BP16: =+BU16/BO16 -> 101.63498 | BQ16: =CE16 -> 18000 | BR16: =+BU16/BQ16 -> 9.7738972 | BS16: =BU16-BM16-BO16-BQ16-BY16-BZ16-CA16-CB16 -> 51498.55 | BT16: =+BU16/BS16 -> 3.4162156 | BU16: 175930.15 | BV16: =+BU16/BG16% -> 27.415193 | BW16: =SUM(BG16-BH16-BU16) -> 38059.58 | BX16: =+BW16/BG16% -> 5.930824 | BY16: 14723 | BZ16: 10380 | CA16: 10400 | CB16: 3200 | CC16: 65997.6 | CD16: 1731 | CE16: 18000 | CF16: =BY16/BG16 -> 0.022942849 | CG16: =BZ16/BG16 -> 0.016175153 | CH16: =CA16/BG16 -> 0.016206319 | CI16: =CB16/BG16 -> 0.0049865597 | CJ16: =CC16/BG16 -> 0.10284405 | CK16: =+BW16*20% -> 7611.916
A17: =A16+1 -> 10 | B17: 6 | C17: DARO | G17: 40 | H17: =SUM(F17*G17) -> 0 | I17: 14122 | J17: 50 | K17: =J17*I17 -> 706100 | M17: 60 | N17: =M17*L17 -> 0 | O17: 9999 | P17: 12 | Q17: =O17*P17 -> 119988 | S17: 12 | T17: =R17*S17 -> 0 | U17: 1200 | V17: 8 | W17: =U17*V17 -> 9600 | X17: 622 | Y17: 12 | Z17: =X17*Y17 -> 7464 | AA17: 1131 | AB17: 10 | AC17: =AA17*AB17 -> 11310 | AD17: 481 | AE17: 25 | AF17: =AD17*AE17 -> 12025 | AG17: 1149 | AH17: 7.5 | AI17: =AG17*AH17 -> 8617.5 | AK17: 15 | AL17: =AJ17*AK17 -> 0 | AM17: 569 | AN17: 10 | AO17: =AM17*AN17 -> 5690 | AP17: =R17+U17+X17+AA17+AD17+AG17+AM17 -> 5152 | AX17: 2373 | AZ17: =O17/(I17+F17+L17) -> 0.70804419 | BA17: =AP17/(I17+F17+L17) -> 0.36482085 | BB17: =AX17/O17 -> 0.23732373 | BC17: =H17+W17+Z17+AC17+AF17+T17+K17+N17 -> 746499 | BD17: =H17+AF17+T17+K17+N17 -> 718125 | BE17: =H17+W17+Z17+AC17+AF17+T17+K17+N17 -> 746499 | BF17: =H17+W17+Z17+AC17+AF17+AI17+T17+K17+N17 -> 755116.5 | BG17: 927633.5 | BH17: 633026.54 | BI17: =+BH17/BG17% -> 68.241018 | BJ17: =SUM(BY17+BZ17+CA17+CB17) -> 52065 | BK17: =SUM(CF17+CG17+CH17+CI17) -> 0.056126692 | BL17: =B17 -> 6 | BM17: =CC17 -> 92850 | BN17: =+BU17/BM17 -> 2.5152299 | BO17: =CD17 -> 1062 | BP17: =+BU17/BO17 -> 219.90499 | BQ17: =CE17 -> 22050 | BR17: =+BU17/BQ17 -> 10.591342 | BS17: =BU17-BM17-BO17-BQ17-BY17-BZ17-CA17-CB17 -> 65512.1 | BT17: =+BU17/BS17 -> 3.5648239 | BU17: 233539.1 | BV17: =+BU17/BG17% -> 25.175794 | BW17: =SUM(BG17-BH17-BU17) -> 61067.86 | BX17: =+BW17/BG17% -> 6.5831883 | BY17: 14826 | BZ17: 14319 | CA17: 19680 | CB17: 3240 | CC17: 92850 | CD17: 1062 | CE17: 22050 | CF17: =BY17/BG17 -> 0.015982605 | CG17: =BZ17/BG17 -> 0.015436053 | CH17: =CA17/BG17 -> 0.021215275 | CI17: =CB17/BG17 -> 0.0034927587 | CJ17: =CC17/BG17 -> 0.10009341 | CK17: =+BW17*20% -> 12213.572
A18: =A17+1 -> 11 | B18: 4 | C18: GUIHULNGAN | G18: 40 | H18: =SUM(F18*G18) -> 0 | I18: 10223 | J18: 50 | K18: =J18*I18 -> 511150 | M18: 60 | N18: =M18*L18 -> 0 | O18: 3272 | P18: 12 | Q18: =O18*P18 -> 39264 | R18: 2032 | S18: 12 | T18: =R18*S18 -> 24384 | U18: 511 | V18: 8 | W18: =U18*V18 -> 4088 | X18: 894 | Y18: 12 | Z18: =X18*Y18 -> 10728 | AA18: 672 | AB18: 10 | AC18: =AA18*AB18 -> 6720 | AD18: 240 | AE18: 25 | AF18: =AD18*AE18 -> 6000 | AG18: 167 | AH18: 7.5 | AI18: =AG18*AH18 -> 1252.5 | AK18: 15 | AL18: =AJ18*AK18 -> 0 | AM18: 236 | AN18: 10 | AO18: =AM18*AN18 -> 2360 | AP18: =R18+U18+X18+AA18+AD18+AG18+AM18 -> 4752 | AX18: 1563 | AZ18: =O18/(I18+F18+L18) -> 0.3200626 | BA18: =AP18/(I18+F18+L18) -> 0.4648342 | BB18: =AX18/O18 -> 0.47768949 | BC18: =H18+W18+Z18+AC18+AF18+T18+K18+N18 -> 563070 | BD18: =H18+AF18+T18+K18+N18 -> 541534 | BE18: =H18+W18+Z18+AC18+AF18+T18+K18+N18 -> 563070 | BF18: =H18+W18+Z18+AC18+AF18+AI18+T18+K18+N18 -> 564322.5 | BG18: 635621.5 | BH18: 426238.17 | BI18: =+BH18/BG18% -> 67.058488 | BJ18: =SUM(BY18+BZ18+CA18+CB18) -> 42433 | BK18: =SUM(CF18+CG18+CH18+CI18) -> 0.066758283 | BL18: =B18 -> 4 | BM18: =CC18 -> 64783 | BN18: =+BU18/BM18 -> 3.0784678 | BO18: =CD18 -> 499 | BP18: =+BU18/BO18 -> 399.66409 | BQ18: =CE18 -> 36000 | BR18: =+BU18/BQ18 -> 5.5397883 | BS18: =BU18-BM18-BO18-BQ18-BY18-BZ18-CA18-CB18 -> 55717.38 | BT18: =+BU18/BS18 -> 3.5793567 | BU18: 199432.38 | BV18: =+BU18/BG18% -> 31.375965 | BW18: =SUM(BG18-BH18-BU18) -> 9950.95 | BX18: =+BW18/BG18% -> 1.5655465 | BY18: 14719 | BZ18: 12110 | CA18: 10854 | CB18: 4750 | CC18: 64783 | CD18: 499 | CE18: 36000 | CF18: =BY18/BG18 -> 0.023156863 | CG18: =BZ18/BG18 -> 0.019052219 | CH18: =CA18/BG18 -> 0.0170762 | CI18: =CB18/BG18 -> 0.0074730008 | CJ18: =CC18/BG18 -> 0.10192072 | CK18: =+BW18*20% -> 1990.19
A19: =A18+1 -> 12 | B19: 3 | C19: JIMALALUD | G19: 40 | H19: =SUM(F19*G19) -> 0 | I19: 9997 | J19: 50 | K19: =J19*I19 -> 499850 | M19: 60 | N19: =M19*L19 -> 0 | O19: 4497 | P19: 12 | Q19: =O19*P19 -> 53964 | R19: 2400 | S19: 12 | T19: =R19*S19 -> 28800 | U19: 700 | V19: 8 | W19: =U19*V19 -> 5600 | X19: 554 | Y19: 12 | Z19: =X19*Y19 -> 6648 | AA19: 757 | AB19: 10 | AC19: =AA19*AB19 -> 7570 | AD19: 266 | AE19: 25 | AF19: =AD19*AE19 -> 6650 | AG19: 243 | AH19: 7.5 | AI19: =AG19*AH19 -> 1822.5 | AK19: 15 | AL19: =AJ19*AK19 -> 0 | AM19: 230 | AN19: 10 | AO19: =AM19*AN19 -> 2300 | AP19: =R19+U19+X19+AA19+AD19+AG19+AM19 -> 5150 | AX19: 2227 | AZ19: =O19/(I19+F19+L19) -> 0.44983495 | BA19: =AP19/(I19+F19+L19) -> 0.51515455 | BB19: =AX19/O19 -> 0.49521903 | BC19: =H19+W19+Z19+AC19+AF19+T19+K19+N19 -> 555118 | BD19: =H19+AF19+T19+K19+N19 -> 535300 | BE19: =H19+W19+Z19+AC19+AF19+T19+K19+N19 -> 555118 | BF19: =H19+W19+Z19+AC19+AF19+AI19+T19+K19+N19 -> 556940.5 | BG19: 655174.5 | BH19: 436893.86 | BI19: =+BH19/BG19% -> 66.683587 | BJ19: =SUM(BY19+BZ19+CA19+CB19) -> 40904 | BK19: =SUM(CF19+CG19+CH19+CI19) -> 0.062432222 | BL19: =B19 -> 3 | BM19: =CC19 -> 69037.5 | BN19: =+BU19/BM19 -> 2.2163786 | BO19: =CD19 -> 187.5 | BP19: =+BU19/BO19 -> 816.07061 | BQ19: =CE19 -> 15000 | BR19: =+BU19/BQ19 -> 10.200883 | BS19: =BU19-BM19-BO19-BQ19-BY19-BZ19-CA19-CB19 -> 27884.24 | BT19: =+BU19/BS19 -> 5.4874452 | BU19: 153013.24 | BV19: =+BU19/BG19% -> 23.354578 | BW19: =SUM(BG19-BH19-BU19) -> 65267.4 | BX19: =+BW19/BG19% -> 9.9618346 | BY19: 14719 | BZ19: 11137 | CA19: 11808 | CB19: 3240 | CC19: 69037.5 | CD19: 187.5 | CE19: 15000 | CF19: =BY19/BG19 -> 0.022465771 | CG19: =BZ19/BG19 -> 0.016998525 | CH19: =CA19/BG19 -> 0.018022679 | CI19: =CB19/BG19 -> 0.0049452474 | CJ19: =CC19/BG19 -> 0.10537269 | CK19: =+BW19*20% -> 13053.48
A20: =A19+1 -> 13 | B20: 3 | C20: JUNOB | G20: 40 | H20: =SUM(F20*G20) -> 0 | I20: 8045 | J20: 50 | K20: =J20*I20 -> 402250 | M20: 60 | N20: =M20*L20 -> 0 | O20: 4108 | P20: 12 | Q20: =O20*P20 -> 49296 | R20: 920 | S20: 12 | T20: =R20*S20 -> 11040 | U20: 520 | V20: 8 | W20: =U20*V20 -> 4160 | X20: 281 | Y20: 12 | Z20: =X20*Y20 -> 3372 | AA20: 619 | AB20: 10 | AC20: =AA20*AB20 -> 6190 | AD20: 129 | AE20: 25 | AF20: =AD20*AE20 -> 3225 | AG20: 184 | AH20: 7.5 | AI20: =AG20*AH20 -> 1380 | AK20: 15 | AL20: =AJ20*AK20 -> 0 | AM20: 243 | AN20: 10 | AO20: =AM20*AN20 -> 2430 | AP20: =R20+U20+X20+AA20+AD20+AG20+AM20 -> 2896 | AX20: 1404 | AZ20: =O20/(I20+F20+L20) -> 0.51062772 | BA20: =AP20/(I20+F20+L20) -> 0.35997514 | BB20: =AX20/O20 -> 0.34177215 | BC20: =H20+W20+Z20+AC20+AF20+T20+K20+N20 -> 430237 | BD20: =H20+AF20+T20+K20+N20 -> 416515 | BE20: =H20+W20+Z20+AC20+AF20+T20+K20+N20 -> 430237 | BF20: =H20+W20+Z20+AC20+AF20+AI20+T20+K20+N20 -> 431617 | BG20: 510732 | BH20: 348854.75 | BI20: =+BH20/BG20% -> 68.304855 | BJ20: =SUM(BY20+BZ20+CA20+CB20) -> 34131.2 | BK20: =SUM(CF20+CG20+CH20+CI20) -> 0.066828004 | BL20: =B20 -> 3 | BM20: =CC20 -> 57999.5 | BN20: =+BU20/BM20 -> 2.7654913 | BO20: =CD20 -> 375 | BP20: =+BU20/BO20 -> 427.72563 | BQ20: =CE20 -> 26750 | BR20: =+BU20/BQ20 -> 5.9961536 | BS20: =BU20-BM20-BO20-BQ20-BY20-BZ20-CA20-CB20 -> 41141.41 | BT20: =+BU20/BS20 -> 3.898678 | BU20: 160397.11 | BV20: =+BU20/BG20% -> 31.405338 | BW20: =SUM(BG20-BH20-BU20) -> 1480.14 | BX20: =+BW20/BG20% -> 0.28980757 | BY20: 11119.2 | BZ20: 9546 | CA20: 10496 | CB20: 2970 | CC20: 57999.5 | CD20: 375 | CE20: 26750 | CF20: =BY20/BG20 -> 0.021771105 | CG20: =BZ20/BG20 -> 0.01869082 | CH20: =CA20/BG20 -> 0.020550896 | CI20: =CB20/BG20 -> 0.0058151829 | CJ20: =CC20/BG20 -> 0.11356152 | CK20: =+BW20*20% -> 296.028
A21: =A20+1 -> 14 | B21: 4 | C21: LARENA | G21: 40 | H21: =SUM(F21*G21) -> 0 | I21: 6500 | J21: 50 | K21: =J21*I21 -> 325000 | M21: 60 | N21: =M21*L21 -> 0 | O21: 5136 | P21: 12 | Q21: =O21*P21 -> 61632 | R21: 7932 | S21: 12 | T21: =R21*S21 -> 95184 | U21: 664 | V21: 8 | W21: =U21*V21 -> 5312 | X21: 205 | Y21: 12 | Z21: =X21*Y21 -> 2460 | AA21: 597 | AB21: 10 | AC21: =AA21*AB21 -> 5970 | AD21: 255 | AE21: 25 | AF21: =AD21*AE21 -> 6375 | AG21: 814 | AH21: 7.5 | AI21: =AG21*AH21 -> 6105 | AK21: 15 | AL21: =AJ21*AK21 -> 0 | AM21: 277 | AN21: 10 | AO21: =AM21*AN21 -> 2770 | AP21: =R21+U21+X21+AA21+AD21+AG21+AM21 -> 10744 | AX21: 1522 | AZ21: =O21/(I21+F21+L21) -> 0.79015385 | BA21: =AP21/(I21+F21+L21) -> 1.6529231 | BB21: =AX21/O21 -> 0.29633956 | BC21: =H21+W21+Z21+AC21+AF21+T21+K21+N21 -> 440301 | BD21: =H21+AF21+T21+K21+N21 -> 426559 | BE21: =H21+W21+Z21+AC21+AF21+T21+K21+N21 -> 440301 | BF21: =H21+W21+Z21+AC21+AF21+AI21+T21+K21+N21 -> 446406 | BG21: 540963 | BH21: 359062.46 | BI21: =+BH21/BG21% -> 66.37468 | BJ21: =SUM(BY21+BZ21+CA21+CB21) -> 37034.5 | BK21: =SUM(CF21+CG21+CH21+CI21) -> 0.06846032 | BL21: =B21 -> 4 | BM21: =CC21 -> 56625 | BN21: =+BU21/BM21 -> 3.2527182 | BO21: =CD21 -> 687.5 | BP21: =+BU21/BO21 -> 267.9057 | BQ21: =CE21 -> 35000 | BR21: =+BU21/BQ21 -> 5.2624334 | BS21: =BU21-BM21-BO21-BQ21-BY21-BZ21-CA21-CB21 -> 54838.17 | BT21: =+BU21/BS21 -> 3.3587038 | BU21: 184185.17 | BV21: =+BU21/BG21% -> 34.047647 | BW21: =SUM(BG21-BH21-BU21) -> -2284.63 | BX21: =+BW21/BG21% -> -0.42232648 | BY21: 11119.5 | BZ21: 11137 | CA21: 11808 | CB21: 2970 | CC21: 56625 | CD21: 687.5 | CE21: 35000 | CF21: =BY21/BG21 -> 0.02055501 | CG21: =BZ21/BG21 -> 0.02058736 | CH21: =CA21/BG21 -> 0.021827741 | CI21: =CB21/BG21 -> 0.0054902091 | CJ21: =CC21/BG21 -> 0.10467444 | CK21: =+BW21*20% -> -456.926
A22: =A21+1 -> 15 | B22: 9 | C22: LOCSIN | G22: 40 | H22: =SUM(F22*G22) -> 0 | I22: 23827 | J22: 50 | K22: =J22*I22 -> 1191350 | M22: 60 | N22: =M22*L22 -> 0 | O22: 21552 | P22: 12 | Q22: =O22*P22 -> 258624 | S22: 12 | T22: =R22*S22 -> 0 | U22: 2900 | V22: 8 | W22: =U22*V22 -> 23200 | X22: 839 | Y22: 12 | Z22: =X22*Y22 -> 10068 | AA22: 2498 | AB22: 10 | AC22: =AA22*AB22 -> 24980 | AD22: 1087 | AE22: 25 | AF22: =AD22*AE22 -> 27175 | AG22: 980 | AH22: 7.5 | AI22: =AG22*AH22 -> 7350 | AK22: 15 | AL22: =AJ22*AK22 -> 0 | AM22: 1080 | AN22: 10 | AO22: =AM22*AN22 -> 10800 | AP22: =R22+U22+X22+AA22+AD22+AG22+AM22 -> 9384 | AX22: 8423 | AZ22: =O22/(I22+F22+L22) -> 0.90452008 | BA22: =AP22/(I22+F22+L22) -> 0.39383892 | BB22: =AX22/O22 -> 0.3908222 | BC22: =H22+W22+Z22+AC22+AF22+T22+K22+N22 -> 1276773 | BD22: =H22+AF22+T22+K22+N22 -> 1218525 | BE22: =H22+W22+Z22+AC22+AF22+T22+K22+N22 -> 1276773 | BF22: =H22+W22+Z22+AC22+AF22+AI22+T22+K22+N22 -> 1284123 | BG22: 1716607 | BH22: 1158880.2 | BI22: =+BH22/BG22% -> 67.50993 | BJ22: =SUM(BY22+BZ22+CA22+CB22) -> 93796 | BK22: =SUM(CF22+CG22+CH22+CI22) -> 0.054640346 | BL22: =B22 -> 9 | BM22: =CC22 -> 144037.5 | BN22: =+BU22/BM22 -> 3.054672 | BO22: =CD22 -> 2312.5 | BP22: =+BU22/BO22 -> 190.26479 | BQ22: =CE22 -> 66150 | BR22: =+BU22/BQ22 -> 6.6513578 | BS22: =BU22-BM22-BO22-BQ22-BY22-BZ22-CA22-CB22 -> 133691.32 | BT22: =+BU22/BS22 -> 3.2910687 | BU22: 439987.32 | BV22: =+BU22/BG22% -> 25.63122 | BW22: =SUM(BG22-BH22-BU22) -> 117739.5 | BX22: =+BW22/BG22% -> 6.85885 | BY22: 22239 | BZ22: 23865 | CA22: 40672 | CB22: 7020 | CC22: 144037.5 | CD22: 2312.5 | CE22: 66150 | CF22: =BY22/BG22 -> 0.012955208 | CG22: =BZ22/BG22 -> 0.013902425 | CH22: =CA22/BG22 -> 0.023693251 | CI22: =CB22/BG22 -> 0.0040894625 | CJ22: =CC22/BG22 -> 0.083908256 | CK22: =+BW22*20% -> 23547.9
A23: =A22+1 -> 16 | B23: 6 | C23: MABINAY1 | G23: 40 | H23: =SUM(F23*G23) -> 0 | I23: 17250 | J23: 50 | K23: =J23*I23 -> 862500 | M23: 60 | N23: =M23*L23 -> 0 | O23: 6998 | P23: 12 | Q23: =O23*P23 -> 83976 | S23: 12 | T23: =R23*S23 -> 0 | U23: 852 | V23: 8 | W23: =U23*V23 -> 6816 | X23: 698 | Y23: 12 | Z23: =X23*Y23 -> 8376 | AA23: 1318 | AB23: 10 | AC23: =AA23*AB23 -> 13180 | AD23: 260 | AE23: 25 | AF23: =AD23*AE23 -> 6500 | AG23: 496 | AH23: 7.5 | AI23: =AG23*AH23 -> 3720 | AK23: 15 | AL23: =AJ23*AK23 -> 0 | AM23: 100 | AN23: 10 | AO23: =AM23*AN23 -> 1000 | AP23: =R23+U23+X23+AA23+AD23+AG23+AM23 -> 3724 | AX23: 4087 | AZ23: =O23/(I23+F23+L23) -> 0.40568116 | BA23: =AP23/(I23+F23+L23) -> 0.21588406 | BB23: =AX23/O23 -> 0.58402401 | BC23: =H23+W23+Z23+AC23+AF23+T23+K23+N23 -> 897372 | BD23: =H23+AF23+T23+K23+N23 -> 869000 | BE23: =H23+W23+Z23+AC23+AF23+T23+K23+N23 -> 897372 | BF23: =H23+W23+Z23+AC23+AF23+AI23+T23+K23+N23 -> 901092 | BG23: 1059917 | BH23: 710921.03 | BI23: =+BH23/BG23% -> 67.073274 | BJ23: =SUM(BY23+BZ23+CA23+CB23) -> 70406.3 | BK23: =SUM(CF23+CG23+CH23+CI23) -> 0.066426239 | BL23: =B23 -> 6 | BM23: =CC23 -> 96000.5 | BN23: =+BU23/BM23 -> 2.7972644 | BO23: =CD23 -> 937 | BP23: =+BU23/BO23 -> 286.59422 | BQ23: =CE23 -> 26250 | BR23: =+BU23/BQ23 -> 10.230049 | BS23: =BU23-BM23-BO23-BQ23-BY23-BZ23-CA23-CB23 -> 74944.98 | BT23: =+BU23/BS23 -> 3.5831457 | BU23: 268538.78 | BV23: =+BU23/BG23% -> 25.335831 | BW23: =SUM(BG23-BH23-BU23) -> 80457.19 | BX23: =+BW23/BG23% -> 7.5908953 | BY23: 25944.3 | BZ23: 15910 | CA23: 20992 | CB23: 7560 | CC23: 96000.5 | CD23: 937 | CE23: 26250 | CF23: =BY23/BG23 -> 0.024477671 | CG23: =BZ23/BG23 -> 0.015010609 | CH23: =CA23/BG23 -> 0.019805324 | CI23: =CB23/BG23 -> 0.007132634 | CJ23: =CC23/BG23 -> 0.090573602 | CK23: =+BW23*20% -> 16091.438
A24: =A23+1 -> 17 | B24: 4 | C24: MABINAY2 | G24: 40 | H24: =SUM(F24*G24) -> 0 | I24: 7972 | J24: 50 | K24: =J24*I24 -> 398600 | M24: 60 | N24: =M24*L24 -> 0 | O24: 3155 | P24: 12 | Q24: =O24*P24 -> 37860 | R24: 200 | S24: 12 | T24: =R24*S24 -> 2400 | U24: 380 | V24: 8 | W24: =U24*V24 -> 3040 | X24: 304 | Y24: 12 | Z24: =X24*Y24 -> 3648 | AA24: 680 | AB24: 10 | AC24: =AA24*AB24 -> 6800 | AE24: 25 | AF24: =AD24*AE24 -> 0 | AG24: 248 | AH24: 7.5 | AI24: =AG24*AH24 -> 1860 | AK24: 15 | AL24: =AJ24*AK24 -> 0 | AM24: 83 | AN24: 10 | AO24: =AM24*AN24 -> 830 | AP24: =R24+U24+X24+AA24+AD24+AG24+AM24 -> 1895 | AX24: 1314 | AZ24: =O24/(I24+F24+L24) -> 0.39576016 | BA24: =AP24/(I24+F24+L24) -> 0.23770697 | BB24: =AX24/O24 -> 0.41648177 | BC24: =H24+W24+Z24+AC24+AF24+T24+K24+N24 -> 414488 | BD24: =H24+AF24+T24+K24+N24 -> 401000 | BE24: =H24+W24+Z24+AC24+AF24+T24+K24+N24 -> 414488 | BF24: =H24+W24+Z24+AC24+AF24+AI24+T24+K24+N24 -> 416348 | BG24: 480962 | BH24: 322470.72 | BI24: =+BH24/BG24% -> 67.047027 | BJ24: =SUM(BY24+BZ24+CA24+CB24) -> 35902.5 | BK24: =SUM(CF24+CG24+CH24+CI24) -> 0.074647269 | BL24: =B24 -> 4 | BM24: =CC24 -> 63250 | BN24: =+BU24/BM24 -> 2.5535107 | BO24: =CD24 -> 1812.5 | BP24: =+BU24/BO24 -> 89.108717 | BQ24: =CE24 -> 10000 | BR24: =+BU24/BQ24 -> 16.150955 | BS24: =BU24-BM24-BO24-BQ24-BY24-BZ24-CA24-CB24 -> 50544.55 | BT24: =+BU24/BS24 -> 3.19539 | BU24: 161509.55 | BV24: =+BU24/BG24% -> 33.580522 | BW24: =SUM(BG24-BH24-BU24) -> -3018.27 | BX24: =+BW24/BG24% -> -0.62754854 | BY24: 11119.5 | BZ24: 11137 | CA24: 10676 | CB24: 2970 | CC24: 63250 | CD24: 1812.5 | CE24: 10000 | CF24: =BY24/BG24 -> 0.02311929 | CG24: =BZ24/BG24 -> 0.023155676 | CH24: =CA24/BG24 -> 0.02219718 | CI24: =CB24/BG24 -> 0.006175124 | CJ24: =CC24/BG24 -> 0.13150727 | CK24: =+BW24*20% -> -603.654
A25: =A24+1 -> 18 | B25: 6 | C25: MANJUYOD | G25: 40 | H25: =SUM(F25*G25) -> 0 | I25: 18203.08 | J25: 50 | K25: =J25*I25 -> 910154 | M25: 60 | N25: =M25*L25 -> 0 | O25: 8775 | P25: 12 | Q25: =O25*P25 -> 105300 | R25: 715 | S25: 12 | T25: =R25*S25 -> 8580 | U25: 1019 | V25: 8 | W25: =U25*V25 -> 8152 | X25: 405 | Y25: 12 | Z25: =X25*Y25 -> 4860 | AA25: 1605 | AB25: 10 | AC25: =AA25*AB25 -> 16050 | AD25: 360 | AE25: 25 | AF25: =AD25*AE25 -> 9000 | AG25: 304 | AH25: 7.5 | AI25: =AG25*AH25 -> 2280 | AK25: 15 | AL25: =AJ25*AK25 -> 0 | AM25: 263 | AN25: 10 | AO25: =AM25*AN25 -> 2630 | AP25: =R25+U25+X25+AA25+AD25+AG25+AM25 -> 4671 | AX25: 2764 | AZ25: =O25/(I25+F25+L25) -> 0.48206128 | BA25: =AP25/(I25+F25+L25) -> 0.25660493 | BB25: =AX25/O25 -> 0.31498575 | BC25: =H25+W25+Z25+AC25+AF25+T25+K25+N25 -> 956796 | BD25: =H25+AF25+T25+K25+N25 -> 927734 | BE25: =H25+W25+Z25+AC25+AF25+T25+K25+N25 -> 956796 | BF25: =H25+W25+Z25+AC25+AF25+AI25+T25+K25+N25 -> 959076 | BG25: 1123129 | BH25: 770926.53 | BI25: =+BH25/BG25% -> 68.64096 | BJ25: =SUM(BY25+BZ25+CA25+CB25) -> 68132 | BK25: =SUM(CF25+CG25+CH25+CI25) -> 0.060662667 | BL25: =B25 -> 6 | BM25: =CC25 -> 80562.3 | BN25: =+BU25/BM25 -> 2.8386604 | BO25: =CD25 -> 2250 | BP25: =+BU25/BO25 -> 101.63956 | BQ25: =CE25 -> 25000 | BR25: =+BU25/BQ25 -> 9.1475604 | BS25: =BU25-BM25-BO25-BQ25-BY25-BZ25-CA25-CB25 -> 52744.71 | BT25: =+BU25/BS25 -> 4.3357715 | BU25: 228689.01 | BV25: =+BU25/BG25% -> 20.361776 | BW25: =SUM(BG25-BH25-BU25) -> 123513.46 | BX25: =+BW25/BG25% -> 10.997264 | BY25: 22133 | BZ25: 17501 | CA25: 23098 | CB25: 5400 | CC25: 80562.3 | CD25: 2250 | CE25: 25000 | CF25: =BY25/BG25 -> 0.019706552 | CG25: =BZ25/BG25 -> 0.01558236 | CH25: =CA25/BG25 -> 0.020565759 | CI25: =CB25/BG25 -> 0.0048079962 | CJ25: =CC25/BG25 -> 0.071730229 | CK25: =+BW25*20% -> 24702.692
A26: =A25+1 -> 19 | B26: 9 | C26: NOPH | G26: 40 | H26: =SUM(F26*G26) -> 0 | I26: 22829 | J26: 50 | K26: =J26*I26 -> 1141450 | M26: 60 | N26: =M26*L26 -> 0 | O26: 20438 | P26: 12 | Q26: =O26*P26 -> 245256 | S26: 12 | T26: =R26*S26 -> 0 | U26: 2454 | V26: 8 | W26: =U26*V26 -> 19632 | X26: 1279 | Y26: 12 | Z26: =X26*Y26 -> 15348 | AA26: 2126 | AB26: 10 | AC26: =AA26*AB26 -> 21260 | AD26: 680 | AE26: 25 | AF26: =AD26*AE26 -> 17000 | AG26: 789 | AH26: 7.5 | AI26: =AG26*AH26 -> 5917.5 | AK26: 15 | AL26: =AJ26*AK26 -> 0 | AM26: 614 | AN26: 10 | AO26: =AM26*AN26 -> 6140 | AP26: =R26+U26+X26+AA26+AD26+AG26+AM26 -> 7942 | AX26: 5069 | AZ26: =O26/(I26+F26+L26) -> 0.89526479 | BA26: =AP26/(I26+F26+L26) -> 0.34789084 | BB26: =AX26/O26 -> 0.2480184 | BC26: =H26+W26+Z26+AC26+AF26+T26+K26+N26 -> 1214690 | BD26: =H26+AF26+T26+K26+N26 -> 1158450 | BE26: =H26+W26+Z26+AC26+AF26+T26+K26+N26 -> 1214690 | BF26: =H26+W26+Z26+AC26+AF26+AI26+T26+K26+N26 -> 1220607.5 | BG26: 1571502.5 | BH26: 1067451.7 | BI26: =+BH26/BG26% -> 67.925552 | BJ26: =SUM(BY26+BZ26+CA26+CB26) -> 81401 | BK26: =SUM(CF26+CG26+CH26+CI26) -> 0.051798199 | BL26: =B26 -> 9 | BM26: =CC26 -> 127975 | BN26: =+BU26/BM26 -> 2.6389159 | BO26: =CD26 -> 1562.5 | BP26: =+BU26/BO26 -> 216.13777 | BQ26: =CE26 -> 38217.86 | BR26: =+BU26/BQ26 -> 8.8365822 | BS26: =BU26-BM26-BO26-BQ26-BY26-BZ26-CA26-CB26 -> 88558.9 | BT26: =+BU26/BS26 -> 3.8134536 | BU26: 337715.26 | BV26: =+BU26/BG26% -> 21.48996 | BW26: =SUM(BG26-BH26-BU26) -> 166335.5 | BX26: =+BW26/BG26% -> 10.584488 | BY26: 22239 | BZ26: 22274 | CA26: 31488 | CB26: 5400 | CC26: 127975 | CD26: 1562.5 | CE26: 38217.86 | CF26: =BY26/BG26 -> 0.014151425 | CG26: =BZ26/BG26 -> 0.014173697 | CH26: =CA26/BG26 -> 0.020036876 | CI26: =CB26/BG26 -> 0.003436202 | CJ26: =CC26/BG26 -> 0.081434805 | CK26: =+BW26*20% -> 33267.1
A27: =A26+1 -> 20 | B27: 5 | C27: PAMPLONA | G27: 40 | H27: =SUM(F27*G27) -> 0 | I27: 10774 | J27: 50 | K27: =J27*I27 -> 538700 | M27: 60 | N27: =M27*L27 -> 0 | O27: 3439 | P27: 12 | Q27: =O27*P27 -> 41268 | R27: 2500 | S27: 12 | T27: =R27*S27 -> 30000 | U27: 771 | V27: 8 | W27: =U27*V27 -> 6168 | X27: 201 | Y27: 12 | Z27: =X27*Y27 -> 2412 | AA27: 716 | AB27: 10 | AC27: =AA27*AB27 -> 7160 | AD27: 104 | AE27: 25 | AF27: =AD27*AE27 -> 2600 | AG27: 268 | AH27: 7.5 | AI27: =AG27*AH27 -> 2010 | AK27: 15 | AL27: =AJ27*AK27 -> 0 | AM27: 162 | AN27: 10 | AO27: =AM27*AN27 -> 1620 | AP27: =R27+U27+X27+AA27+AD27+AG27+AM27 -> 4722 | AX27: 2334 | AZ27: =O27/(I27+F27+L27) -> 0.31919436 | BA27: =AP27/(I27+F27+L27) -> 0.43827733 | BB27: =AX27/O27 -> 0.67868566 | BC27: =H27+W27+Z27+AC27+AF27+T27+K27+N27 -> 587040 | BD27: =H27+AF27+T27+K27+N27 -> 571300 | BE27: =H27+W27+Z27+AC27+AF27+T27+K27+N27 -> 587040 | BF27: =H27+W27+Z27+AC27+AF27+AI27+T27+K27+N27 -> 589050 | BG27: 677210 | BH27: 454569.8 | BI27: =+BH27/BG27% -> 67.123905 | BJ27: =SUM(BY27+BZ27+CA27+CB27) -> 49354.5 | BK27: =SUM(CF27+CG27+CH27+CI27) -> 0.072879166 | BL27: =B27 -> 5 | BM27: =CC27 -> 74412.5 | BN27: =+BU27/BM27 -> 2.5922739 | BO27: =CD27 -> 1750 | BP27: =+BU27/BO27 -> 110.22719 | BQ27: =CE27 -> 16000 | BR27: =+BU27/BQ27 -> 12.056099 | BS27: =BU27-BM27-BO27-BQ27-BY27-BZ27-CA27-CB27 -> 51380.58 | BT27: =+BU27/BS27 -> 3.7542897 | BU27: 192897.58 | BV27: =+BU27/BG27% -> 28.48416 | BW27: =SUM(BG27-BH27-BU27) -> 29742.62 | BX27: =+BW27/BG27% -> 4.3919346 | BY27: 18423.5 | BZ27: 11137 | CA27: 15744 | CB27: 4050 | CC27: 74412.5 | CD27: 1750 | CE27: 16000 | CF27: =BY27/BG27 -> 0.027205003 | CG27: =BZ27/BG27 -> 0.016445416 | CH27: =CA27/BG27 -> 0.023248328 | CI27: =CB27/BG27 -> 0.0059804197 | CJ27: =CC27/BG27 -> 0.10988098 | CK27: =+BW27*20% -> 5948.524
A28: =A27+1 -> 21 | B28: 4 | C28: QUEZON | G28: 40 | H28: =SUM(F28*G28) -> 0 | I28: 9611 | J28: 50 | K28: =J28*I28 -> 480550 | M28: 60 | N28: =M28*L28 -> 0 | O28: 4221 | P28: 12 | Q28: =O28*P28 -> 50652 | R28: 1830 | S28: 12 | T28: =R28*S28 -> 21960 | U28: 1174 | V28: 8 | W28: =U28*V28 -> 9392 | X28: 931 | Y28: 12 | Z28: =X28*Y28 -> 11172 | AA28: 1887 | AB28: 10 | AC28: =AA28*AB28 -> 18870 | AD28: 315 | AE28: 25 | AF28: =AD28*AE28 -> 7875 | AG28: 360 | AH28: 7.5 | AI28: =AG28*AH28 -> 2700 | AK28: 15 | AL28: =AJ28*AK28 -> 0 | AN28: 10 | AO28: =AM28*AN28 -> 0 | AP28: =R28+U28+X28+AA28+AD28+AG28+AM28 -> 6497 | AX28: 1976 | AZ28: =O28/(I28+F28+L28) -> 0.43918427 | BA28: =AP28/(I28+F28+L28) -> 0.67599625 | BB28: =AX28/O28 -> 0.46813551 | BC28: =H28+W28+Z28+AC28+AF28+T28+K28+N28 -> 549819 | BD28: =H28+AF28+T28+K28+N28 -> 510385 | BE28: =H28+W28+Z28+AC28+AF28+T28+K28+N28 -> 549819 | BF28: =H28+W28+Z28+AC28+AF28+AI28+T28+K28+N28 -> 552519 | BG28: 641258 | BH28: 426800.29 | BI28: =+BH28/BG28% -> 66.55672 | BJ28: =SUM(BY28+BZ28+CA28+CB28) -> 42804 | BK28: =SUM(CF28+CG28+CH28+CI28) -> 0.066750044 | BL28: =B28 -> 4 | BM28: =CC28 -> 61209 | BN28: =+BU28/BM28 -> 2.4651332 | BO28: =CD28 -> 6631.5 | BP28: =+BU28/BO28 -> 22.753275 | BQ28: =CE28 -> 12000 | BR28: =+BU28/BQ28 -> 12.574028 | BS28: =BU28-BM28-BO28-BQ28-BY28-BZ28-CA28-CB28 -> 28243.84 | BT28: =+BU28/BS28 -> 5.3423451 | BU28: 150888.34 | BV28: =+BU28/BG28% -> 23.530052 | BW28: =SUM(BG28-BH28-BU28) -> 63569.37 | BX28: =+BW28/BG28% -> 9.9132284 | BY28: 18426 | BZ28: 8650 | CA28: 9648 | CB28: 6080 | CC28: 61209 | CD28: 6631.5 | CE28: 12000 | CF28: =BY28/BG28 -> 0.028734144 | CG28: =BZ28/BG28 -> 0.01348911 | CH28: =CA28/BG28 -> 0.015045426 | CI28: =CB28/BG28 -> 0.0094813632 | CJ28: =CC28/BG28 -> 0.095451441 | CK28: =+BW28*20% -> 12713.874
A29: =A28+1 -> 22 | B29: 7 | C29: SAGAY1 | G29: 40 | H29: =SUM(F29*G29) -> 0 | I29: 26010 | J29: 50 | K29: =J29*I29 -> 1300500 | M29: 60 | N29: =M29*L29 -> 0 | O29: 8655 | P29: 12 | Q29: =O29*P29 -> 103860 | R29: 330 | S29: 12 | T29: =R29*S29 -> 3960 | U29: 910 | V29: 8 | W29: =U29*V29 -> 7280 | X29: 771 | Y29: 12 | Z29: =X29*Y29 -> 9252 | AA29: 1570 | AB29: 10 | AC29: =AA29*AB29 -> 15700 | AD29: 210 | AE29: 25 | AF29: =AD29*AE29 -> 5250 | AG29: 169 | AH29: 7.5 | AI29: =AG29*AH29 -> 1267.5 | AK29: 15 | AL29: =AJ29*AK29 -> 0 | AM29: 277 | AN29: 10 | AO29: =AM29*AN29 -> 2770 | AP29: =R29+U29+X29+AA29+AD29+AG29+AM29 -> 4237 | AX29: 4357 | AZ29: =O29/(I29+F29+L29) -> 0.33275663 | BA29: =AP29/(I29+F29+L29) -> 0.16289889 | BB29: =AX29/O29 -> 0.50340843 | BC29: =H29+W29+Z29+AC29+AF29+T29+K29+N29 -> 1341942 | BD29: =H29+AF29+T29+K29+N29 -> 1309710 | BE29: =H29+W29+Z29+AC29+AF29+T29+K29+N29 -> 1341942 | BF29: =H29+W29+Z29+AC29+AF29+AI29+T29+K29+N29 -> 1343209.5 | BG29: 1534824.5 | BH29: 1031408.1 | BI29: =+BH29/BG29% -> 67.200394 | BJ29: =SUM(BY29+BZ29+CA29+CB29) -> 88738 | BK29: =SUM(CF29+CG29+CH29+CI29) -> 0.057816382 | BL29: =B29 -> 7 | BM29: =CC29 -> 114398.74 | BN29: =+BU29/BM29 -> 2.9277669 | BO29: =CD29 -> 3654.84 | BP29: =+BU29/BO29 -> 91.640904 | BQ29: =CE29 -> 20000 | BR29: =+BU29/BQ29 -> 16.746642 | BS29: =BU29-BM29-BO29-BQ29-BY29-BZ29-CA29-CB29 -> 108141.26 | BT29: =+BU29/BS29 -> 3.097179 | BU29: 334932.84 | BV29: =+BU29/BG29% -> 21.822224 | BW29: =SUM(BG29-BH29-BU29) -> 168483.55 | BX29: =+BW29/BG29% -> 10.977382 | BY29: 28582 | BZ29: 27680 | CA29: 28636 | CB29: 3840 | CC29: 114398.74 | CD29: 3654.84 | CE29: 20000 | CF29: =BY29/BG29 -> 0.018622325 | CG29: =BZ29/BG29 -> 0.018034635 | CH29: =CA29/BG29 -> 0.018657508 | CI29: =CB29/BG29 -> 0.0025019147 | CJ29: =CC29/BG29 -> 0.074535388 | CK29: =+BW29*20% -> 33696.71
A30: =A29+1 -> 23 | B30: 2 | C30: SAGAY2 | G30: 40 | H30: =SUM(F30*G30) -> 0 | I30: 7326 | J30: 50 | K30: =J30*I30 -> 366300 | M30: 60 | N30: =M30*L30 -> 0 | O30: 2712 | P30: 12 | Q30: =O30*P30 -> 32544 | R30: 2290 | S30: 12 | T30: =R30*S30 -> 27480 | U30: 222 | V30: 8 | W30: =U30*V30 -> 1776 | X30: 177 | Y30: 12 | Z30: =X30*Y30 -> 2124 | AA30: 233 | AB30: 10 | AC30: =AA30*AB30 -> 2330 | AD30: 84 | AE30: 25 | AF30: =AD30*AE30 -> 2100 | AG30: 83 | AH30: 7.5 | AI30: =AG30*AH30 -> 622.5 | AK30: 15 | AL30: =AJ30*AK30 -> 0 | AM30: 90 | AN30: 10 | AO30: =AM30*AN30 -> 900 | AP30: =R30+U30+X30+AA30+AD30+AG30+AM30 -> 3179 | AX30: 893 | AZ30: =O30/(I30+F30+L30) -> 0.37018837 | BA30: =AP30/(I30+F30+L30) -> 0.43393393 | BB30: =AX30/O30 -> 0.32927729 | BC30: =H30+W30+Z30+AC30+AF30+T30+K30+N30 -> 402110 | BD30: =H30+AF30+T30+K30+N30 -> 395880 | BE30: =H30+W30+Z30+AC30+AF30+T30+K30+N30 -> 402110 | BF30: =H30+W30+Z30+AC30+AF30+AI30+T30+K30+N30 -> 402732.5 | BG30: 453453.5 | BH30: 302381.15 | BI30: =+BH30/BG30% -> 66.684048 | BJ30: =SUM(BY30+BZ30+CA30+CB30) -> 29946 | BK30: =SUM(CF30+CG30+CH30+CI30) -> 0.066039848 | BL30: =B30 -> 2 | BM30: =CC30 -> 47705.7 | BN30: =+BU30/BM30 -> 3.0738121 | BO30: =CD30 -> 2499.72 | BP30: =+BU30/BO30 -> 58.661914 | BQ30: =CE30 -> 14000 | BR30: =+BU30/BQ30 -> 10.474169 | BS30: =BU30-BM30-BO30-BQ30-BY30-BZ30-CA30-CB30 -> 52486.94 | BT30: =+BU30/BS30 -> 2.7938066 | BU30: 146638.36 | BV30: =+BU30/BG30% -> 32.338125 | BW30: =SUM(BG30-BH30-BU30) -> 4433.99 | BX30: =+BW30/BG30% -> 0.97782683 | BY30: 10719 | BZ30: 8650 | CA30: 8907 | CB30: 1670 | CC30: 47705.7 | CD30: 2499.72 | CE30: 14000 | CF30: =BY30/BG30 -> 0.023638587 | CG30: =BZ30/BG30 -> 0.019075826 | CH30: =CA30/BG30 -> 0.019642587 | CI30: =CB30/BG30 -> 0.0036828473 | CJ30: =CC30/BG30 -> 0.10520527 | CK30: =+BW30*20% -> 886.798
A31: =A30+1 -> 24 | B31: 5 | C31: SAN CARLOS1 | G31: 40 | H31: =SUM(F31*G31) -> 0 | I31: 11174 | J31: 50 | K31: =J31*I31 -> 558700 | M31: 60 | N31: =M31*L31 -> 0 | O31: 4439 | P31: 12 | Q31: =O31*P31 -> 53268 | R31: 4685 | S31: 12 | T31: =R31*S31 -> 56220 | U31: 539 | V31: 8 | W31: =U31*V31 -> 4312 | X31: 624 | Y31: 12 | Z31: =X31*Y31 -> 7488 | AA31: 761 | AB31: 10 | AC31: =AA31*AB31 -> 7610 | AD31: 145 | AE31: 25 | AF31: =AD31*AE31 -> 3625 | AH31: 7.5 | AI31: =AG31*AH31 -> 0 | AK31: 15 | AL31: =AJ31*AK31 -> 0 | AM31: 212 | AN31: 10 | AO31: =AM31*AN31 -> 2120 | AP31: =R31+U31+X31+AA31+AD31+AG31+AM31 -> 6966 | AX31: 1178 | AZ31: =O31/(I31+F31+L31) -> 0.3972615 | BA31: =AP31/(I31+F31+L31) -> 0.62341149 | BB31: =AX31/O31 -> 0.26537508 | BC31: =H31+W31+Z31+AC31+AF31+T31+K31+N31 -> 637955 | BD31: =H31+AF31+T31+K31+N31 -> 618545 | BE31: =H31+W31+Z31+AC31+AF31+T31+K31+N31 -> 637955 | BF31: =H31+W31+Z31+AC31+AF31+AI31+T31+K31+N31 -> 637955 | BG31: 716363 | BH31: 477019.61 | BI31: =+BH31/BG31% -> 66.589091 | BJ31: =SUM(BY31+BZ31+CA31+CB31) -> 58059 | BK31: =SUM(CF31+CG31+CH31+CI31) -> 0.081046899 | BL31: =B31 -> 5 | BM31: =CC31 -> 76549.98 | BN31: =+BU31/BM31 -> 2.453618 | BO31: =CD31 -> 3462.48 | BP31: =+BU31/BO31 -> 54.24563 | BQ31: =CE31 -> 15000 | BR31: =+BU31/BQ31 -> 12.521627 | BS31: =BU31-BM31-BO31-BQ31-BY31-BZ31-CA31-CB31 -> 34752.95 | BT31: =+BU31/BS31 -> 5.4045602 | BU31: 187824.41 | BV31: =+BU31/BG31% -> 26.219167 | BW31: =SUM(BG31-BH31-BU31) -> 51518.98 | BX31: =+BW31/BG31% -> 7.1917422 | BY31: 22129 | BZ31: 15570 | CA31: 13320 | CB31: 7040 | CC31: 76549.98 | CD31: 3462.48 | CE31: 15000 | CF31: =BY31/BG31 -> 0.030890763 | CG31: =BZ31/BG31 -> 0.021734791 | CH31: =CA31/BG31 -> 0.018593925 | CI31: =CB31/BG31 -> 0.0098274199 | CJ31: =CC31/BG31 -> 0.1068592 | CK31: =+BW31*20% -> 10303.796
A32: =A31+1 -> 25 | B32: 6 | C32: SAN CARLOS2 | G32: 40 | H32: =SUM(F32*G32) -> 0 | I32: 13382 | J32: 50 | K32: =J32*I32 -> 669100 | M32: 60 | N32: =M32*L32 -> 0 | O32: 7809 | P32: 12 | Q32: =O32*P32 -> 93708 | R32: 3440 | S32: 12 | T32: =R32*S32 -> 41280 | U32: 839 | V32: 8 | W32: =U32*V32 -> 6712 | X32: 930 | Y32: 12 | Z32: =X32*Y32 -> 11160 | AA32: 1390 | AB32: 10 | AC32: =AA32*AB32 -> 13900 | AD32: 200 | AE32: 25 | AF32: =AD32*AE32 -> 5000 | AG32: 85 | AH32: 7.5 | AI32: =AG32*AH32 -> 637.5 | AK32: 15 | AL32: =AJ32*AK32 -> 0 | AM32: 247 | AN32: 10 | AO32: =AM32*AN32 -> 2470 | AP32: =R32+U32+X32+AA32+AD32+AG32+AM32 -> 7131 | AX32: 2874 | AZ32: =O32/(I32+F32+L32) -> 0.58354506 | BA32: =AP32/(I32+F32+L32) -> 0.53287999 | BB32: =AX32/O32 -> 0.36803688 | BC32: =H32+W32+Z32+AC32+AF32+T32+K32+N32 -> 747152 | BD32: =H32+AF32+T32+K32+N32 -> 715380 | BE32: =H32+W32+Z32+AC32+AF32+T32+K32+N32 -> 747152 | BF32: =H32+W32+Z32+AC32+AF32+AI32+T32+K32+N32 -> 747789.5 | BG32: 900413.5 | BH32: 593503.62 | BI32: =+BH32/BG32% -> 65.914563 | BJ32: =SUM(BY32+BZ32+CA32+CB32) -> 61999 | BK32: =SUM(CF32+CG32+CH32+CI32) -> 0.068856142 | BL32: =B32 -> 6 | BM32: =CC32 -> 98636.5 | BN32: =+BU32/BM32 -> 2.4609643 | BO32: =CD32 -> 7117.32 | BP32: =+BU32/BO32 -> 34.105662 | BQ32: =CE32 -> 9316.9 | BR32: =+BU32/BQ32 -> 26.053828 | BS32: =BU32-BM32-BO32-BQ32-BY32-BZ32-CA32-CB32 -> 65671.19 | BT32: =+BU32/BS32 -> 3.6963075 | BU32: 242740.91 | BV32: =+BU32/BG32% -> 26.958826 | BW32: =SUM(BG32-BH32-BU32) -> 64168.97 | BX32: =+BW32/BG32% -> 7.1266113 | BY32: 22133 | BZ32: 15570 | CA32: 18216 | CB32: 6080 | CC32: 98636.5 | CD32: 7117.32 | CE32: 9316.9 | CF32: =BY32/BG32 -> 0.024580929 | CG32: =BZ32/BG32 -> 0.017292055 | CH32: =CA32/BG32 -> 0.020230705 | CI32: =CB32/BG32 -> 0.0067524532 | CJ32: =CC32/BG32 -> 0.10954578 | CK32: =+BW32*20% -> 12833.794
A33: =A32+1 -> 26 | B33: 4 | C33: SAN CARLOS5 | G33: 40 | H33: =SUM(F33*G33) -> 0 | I33: 10252 | J33: 50 | K33: =J33*I33 -> 512600 | M33: 60 | N33: =M33*L33 -> 0 | O33: 3712 | P33: 12 | Q33: =O33*P33 -> 44544 | R33: 3657 | S33: 12 | T33: =R33*S33 -> 43884 | U33: 439 | V33: 8 | W33: =U33*V33 -> 3512 | X33: 671 | Y33: 12 | Z33: =X33*Y33 -> 8052 | AA33: 807 | AB33: 10 | AC33: =AA33*AB33 -> 8070 | AD33: 198 | AE33: 25 | AF33: =AD33*AE33 -> 4950 | AG33: 120 | AH33: 7.5 | AI33: =AG33*AH33 -> 900 | AK33: 15 | AL33: =AJ33*AK33 -> 0 | AM33: 189 | AN33: 10 | AO33: =AM33*AN33 -> 1890 | AP33: =R33+U33+X33+AA33+AD33+AG33+AM33 -> 6081 | AX33: 989 | AZ33: =O33/(I33+F33+L33) -> 0.36207569 | BA33: =AP33/(I33+F33+L33) -> 0.59315256 | BB33: =AX33/O33 -> 0.26643319 | BC33: =H33+W33+Z33+AC33+AF33+T33+K33+N33 -> 581068 | BD33: =H33+AF33+T33+K33+N33 -> 561434 | BE33: =H33+W33+Z33+AC33+AF33+T33+K33+N33 -> 581068 | BF33: =H33+W33+Z33+AC33+AF33+AI33+T33+K33+N33 -> 581968 | BG33: 647507 | BH33: 433072.03 | BI33: =+BH33/BG33% -> 66.882988 | BJ33: =SUM(BY33+BZ33+CA33+CB33) -> 47539 | BK33: =SUM(CF33+CG33+CH33+CI33) -> 0.073418511 | BL33: =B33 -> 4 | BM33: =CC33 -> 63800.78 | BN33: =+BU33/BM33 -> 2.8160629 | BO33: =CD33 -> 3398.36 | BP33: =+BU33/BO33 -> 52.86874 | BQ33: =CE33 -> 30000 | BR33: =+BU33/BQ33 -> 5.9889003 | BS33: =BU33-BM33-BO33-BQ33-BY33-BZ33-CA33-CB33 -> 34928.87 | BT33: =+BU33/BS33 -> 5.1437968 | BU33: 179667.01 | BV33: =+BU33/BG33% -> 27.747501 | BW33: =SUM(BG33-BH33-BU33) -> 34767.96 | BX33: =+BW33/BG33% -> 5.3695111 | BY33: 18426 | BZ33: 12110 | CA33: 12203 | CB33: 4800 | CC33: 63800.78 | CD33: 3398.36 | CE33: 30000 | CF33: =BY33/BG33 -> 0.028456835 | CG33: =BZ33/BG33 -> 0.018702501 | CH33: =CA33/BG33 -> 0.018846128 | CI33: =CB33/BG33 -> 0.0074130473 | CJ33: =CC33/BG33 -> 0.098532958 | CK33: =+BW33*20% -> 6953.592
A34: =A33+1 -> 27 | B34: 4 | C34: SAN CARLOS7 | G34: 40 | H34: =SUM(F34*G34) -> 0 | I34: 9962 | J34: 50 | K34: =J34*I34 -> 498100 | M34: 60 | N34: =M34*L34 -> 0 | O34: 4438 | P34: 12 | Q34: =O34*P34 -> 53256 | R34: 4531 | S34: 12 | T34: =R34*S34 -> 54372 | U34: 621 | V34: 8 | W34: =U34*V34 -> 4968 | X34: 775 | Y34: 12 | Z34: =X34*Y34 -> 9300 | AA34: 896 | AB34: 10 | AC34: =AA34*AB34 -> 8960 | AD34: 134 | AE34: 25 | AF34: =AD34*AE34 -> 3350 | AG34: 206 | AH34: 7.5 | AI34: =AG34*AH34 -> 1545 | AK34: 15 | AL34: =AJ34*AK34 -> 0 | AM34: 230 | AN34: 10 | AO34: =AM34*AN34 -> 2300 | AP34: =R34+U34+X34+AA34+AD34+AG34+AM34 -> 7393 | AX34: 1744 | AZ34: =O34/(I34+F34+L34) -> 0.44549287 | BA34: =AP34/(I34+F34+L34) -> 0.74212006 | BB34: =AX34/O34 -> 0.39296981 | BC34: =H34+W34+Z34+AC34+AF34+T34+K34+N34 -> 579050 | BD34: =H34+AF34+T34+K34+N34 -> 555822 | BE34: =H34+W34+Z34+AC34+AF34+T34+K34+N34 -> 579050 | BF34: =H34+W34+Z34+AC34+AF34+AI34+T34+K34+N34 -> 580595 | BG34: 670061 | BH34: 443869.26 | BI34: =+BH34/BG34% -> 66.243112 | BJ34: =SUM(BY34+BZ34+CA34+CB34) -> 51447 | BK34: =SUM(CF34+CG34+CH34+CI34) -> 0.076779577 | BL34: =B34 -> 4 | BM34: =CC34 -> 63906.72 | BN34: =+BU34/BM34 -> 2.8867017 | BO34: =CD34 -> 2308.32 | BP34: =+BU34/BO34 -> 79.919439 | BQ34: =CE34 -> 20000 | BR34: =+BU34/BQ34 -> 9.223982 | BS34: =BU34-BM34-BO34-BQ34-BY34-BZ34-CA34-CB34 -> 46817.6 | BT34: =+BU34/BS34 -> 3.9403908 | BU34: 184479.64 | BV34: =+BU34/BG34% -> 27.531768 | BW34: =SUM(BG34-BH34-BU34) -> 41712.1 | BX34: =+BW34/BG34% -> 6.2251198 | BY34: 22133 | BZ34: 12110 | CA34: 10854 | CB34: 6350 | CC34: 63906.72 | CD34: 2308.32 | CE34: 20000 | CF34: =BY34/BG34 -> 0.033031321 | CG34: =BZ34/BG34 -> 0.018072981 | CH34: =CA34/BG34 -> 0.016198525 | CI34: =CB34/BG34 -> 0.0094767491 | CJ34: =CC34/BG34 -> 0.095374481 | CK34: =+BW34*20% -> 8342.42
A35: =A34+1 -> 28 | B35: 2 | C35: SANTANDER | G35: 40 | H35: =SUM(F35*G35) -> 0 | I35: 3753 | J35: 50 | K35: =J35*I35 -> 187650 | M35: 60 | N35: =M35*L35 -> 0 | O35: 1739 | P35: 12 | Q35: =O35*P35 -> 20868 | R35: 870 | S35: 12 | T35: =R35*S35 -> 10440 | U35: 828 | V35: 8 | W35: =U35*V35 -> 6624 | X35: 725 | Y35: 12 | Z35: =X35*Y35 -> 8700 | AA35: 844 | AB35: 10 | AC35: =AA35*AB35 -> 8440 | AD35: 392 | AE35: 25 | AF35: =AD35*AE35 -> 9800 | AG35: 473 | AH35: 7.5 | AI35: =AG35*AH35 -> 3547.5 | AK35: 15 | AL35: =AJ35*AK35 -> 0 | AN35: 10 | AO35: =AM35*AN35 -> 0 | AP35: =R35+U35+X35+AA35+AD35+AG35+AM35 -> 4132 | AX35: 895 | AZ35: =O35/(I35+F35+L35) -> 0.46336264 | BA35: =AP35/(I35+F35+L35) -> 1.1009859 | BB35: =AX35/O35 -> 0.5146636 | BC35: =H35+W35+Z35+AC35+AF35+T35+K35+N35 -> 231654 | BD35: =H35+AF35+T35+K35+N35 -> 207890 | BE35: =H35+W35+Z35+AC35+AF35+T35+K35+N35 -> 231654 | BF35: =H35+W35+Z35+AC35+AF35+AI35+T35+K35+N35 -> 235201.5 | BG35: 273920.5 | BH35: 182620.65 | BI35: =+BH35/BG35% -> 66.669216 | BJ35: =SUM(BY35+BZ35+CA35+CB35) -> 22314 | BK35: =SUM(CF35+CG35+CH35+CI35) -> 0.081461592 | BL35: =B35 -> 2 | BM35: =CC35 -> 32843 | BN35: =+BU35/BM35 -> 2.7271824 | BO35: =CD35 -> 1500 | BP35: =+BU35/BO35 -> 59.712567 | BQ35: =CE35 -> 12000 | BR35: =+BU35/BQ35 -> 7.4640708 | BS35: =BU35-BM35-BO35-BQ35-BY35-BZ35-CA35-CB35 -> 20911.85 | BT35: =+BU35/BS35 -> 4.2831624 | BU35: 89568.85 | BV35: =+BU35/BG35% -> 32.698849 | BW35: =SUM(BG35-BH35-BU35) -> 1731 | BX35: =+BW35/BG35% -> 0.63193518 | BY35: 9082 | BZ35: 6364 | CA35: 5248 | CB35: 1620 | CC35: 32843 | CD35: 1500 | CE35: 12000 | CF35: =BY35/BG35 -> 0.033155605 | CG35: =BZ35/BG35 -> 0.023233018 | CH35: =CA35/BG35 -> 0.019158844 | CI35: =CB35/BG35 -> 0.0059141247 | CJ35: =CC35/BG35 -> 0.11989975 | CK35: =+BW35*20% -> 346.2
A36: =A35+1 -> 29 | B36: 2 | C36: STA.AGUEDA | G36: 40 | H36: =SUM(F36*G36) -> 0 | I36: 4280 | J36: 50 | K36: =J36*I36 -> 214000 | M36: 60 | N36: =M36*L36 -> 0 | O36: 1638 | P36: 12 | Q36: =O36*P36 -> 19656 | R36: 4040 | S36: 12 | T36: =R36*S36 -> 48480 | U36: 354 | V36: 8 | W36: =U36*V36 -> 2832 | X36: 239 | Y36: 12 | Z36: =X36*Y36 -> 2868 | AA36: 564 | AB36: 10 | AC36: =AA36*AB36 -> 5640 | AD36: 266 | AE36: 25 | AF36: =AD36*AE36 -> 6650 | AH36: 7.5 | AI36: =AG36*AH36 -> 0 | AK36: 15 | AL36: =AJ36*AK36 -> 0 | AN36: 10 | AO36: =AM36*AN36 -> 0 | AP36: =R36+U36+X36+AA36+AD36+AG36+AM36 -> 5463 | AX36: 476 | AZ36: =O36/(I36+F36+L36) -> 0.38271028 | BA36: =AP36/(I36+F36+L36) -> 1.2764019 | BB36: =AX36/O36 -> 0.29059829 | BC36: =H36+W36+Z36+AC36+AF36+T36+K36+N36 -> 280470 | BD36: =H36+AF36+T36+K36+N36 -> 269130 | BE36: =H36+W36+Z36+AC36+AF36+T36+K36+N36 -> 280470 | BF36: =H36+W36+Z36+AC36+AF36+AI36+T36+K36+N36 -> 280470 | BG36: 309718 | BH36: 204263.09 | BI36: =+BH36/BG36% -> 65.951314 | BJ36: =SUM(BY36+BZ36+CA36+CB36) -> 25554 | BK36: =SUM(CF36+CG36+CH36+CI36) -> 0.082507313 | BL36: =B36 -> 2 | BM36: =CC36 -> 32050 | BN36: =+BU36/BM36 -> 2.6980512 | BO36: =CD36 -> 1875 | BP36: =+BU36/BO36 -> 46.118688 | BQ36: =CE36 -> 10000 | BR36: =+BU36/BQ36 -> 8.647254 | BS36: =BU36-BM36-BO36-BQ36-BY36-BZ36-CA36-CB36 -> 16993.54 | BT36: =+BU36/BS36 -> 5.0885537 | BU36: 86472.54 | BV36: =+BU36/BG36% -> 27.919766 | BW36: =SUM(BG36-BH36-BU36) -> 18982.37 | BX36: =+BW36/BG36% -> 6.1289205 | BY36: 11010 | BZ36: 6364 | CA36: 6560 | CB36: 1620 | CC36: 32050 | CD36: 1875 | CE36: 10000 | CF36: =BY36/BG36 -> 0.035548467 | CG36: =BZ36/BG36 -> 0.020547724 | CH36: =CA36/BG36 -> 0.021180558 | CI36: =CB36/BG36 -> 0.0052305646 | CJ36: =CC36/BG36 -> 0.10348123 | CK36: =+BW36*20% -> 3796.474
A37: =A36+1 -> 30 | B37: 5 | C37: STA.ROSA | G37: 40 | H37: =SUM(F37*G37) -> 0 | I37: 9083 | J37: 50 | K37: =J37*I37 -> 454150 | M37: 60 | N37: =M37*L37 -> 0 | O37: 7994 | P37: 12 | Q37: =O37*P37 -> 95928 | R37: 8170 | S37: 12 | T37: =R37*S37 -> 98040 | U37: 539 | V37: 8 | W37: =U37*V37 -> 4312 | X37: 270 | Y37: 12 | Z37: =X37*Y37 -> 3240 | AA37: 722 | AB37: 10 | AC37: =AA37*AB37 -> 7220 | AD37: 350 | AE37: 25 | AF37: =AD37*AE37 -> 8750 | AG37: 890 | AH37: 7.5 | AI37: =AG37*AH37 -> 6675 | AK37: 15 | AL37: =AJ37*AK37 -> 0 | AM37: 406 | AN37: 10 | AO37: =AM37*AN37 -> 4060 | AP37: =R37+U37+X37+AA37+AD37+AG37+AM37 -> 11347 | AX37: 2856 | AZ37: =O37/(I37+F37+L37) -> 0.88010569 | BA37: =AP37/(I37+F37+L37) -> 1.2492569 | BB37: =AX37/O37 -> 0.35726795 | BC37: =H37+W37+Z37+AC37+AF37+T37+K37+N37 -> 575712 | BD37: =H37+AF37+T37+K37+N37 -> 560940 | BE37: =H37+W37+Z37+AC37+AF37+T37+K37+N37 -> 575712 | BF37: =H37+W37+Z37+AC37+AF37+AI37+T37+K37+N37 -> 582387 | BG37: 736294 | BH37: 487405.33 | BI37: =+BH37/BG37% -> 66.197107 | BJ37: =SUM(BY37+BZ37+CA37+CB37) -> 50581.5 | BK37: =SUM(CF37+CG37+CH37+CI37) -> 0.068697422 | BL37: =B37 -> 5 | BM37: =CC37 -> 64762.5 | BN37: =+BU37/BM37 -> 3.4637608 | BO37: =CD37 -> 4562.5 | BP37: =+BU37/BO37 -> 49.166424 | BQ37: =CE37 -> 44000 | BR37: =+BU37/BQ37 -> 5.098223 | BS37: =BU37-BM37-BO37-BQ37-BY37-BZ37-CA37-CB37 -> 60415.31 | BT37: =+BU37/BS37 -> 3.7129961 | BU37: 224321.81 | BV37: =+BU37/BG37% -> 30.466337 | BW37: =SUM(BG37-BH37-BU37) -> 24566.86 | BX37: =+BW37/BG37% -> 3.3365558 | BY37: 18532.5 | BZ37: 15910 | CA37: 13169 | CB37: 2970 | CC37: 64762.5 | CD37: 4562.5 | CE37: 44000 | CF37: =BY37/BG37 -> 0.025169973 | CG37: =BZ37/BG37 -> 0.021608216 | CH37: =CA37/BG37 -> 0.017885519 | CI37: =CB37/BG37 -> 0.0040337148 | CJ37: =CC37/BG37 -> 0.087957392 | CK37: =+BW37*20% -> 4913.372
