Workbook

Sheet checklist
A1: TO DO | B1: REMARKS
A2: Loans | B2: done
A3: Customer List | B3: done
A4: Customer Balance | B4: done
A5: Customer Payments | B5: done
A6: Expenses
A7: Assigned per collector | B7: done
A8: Payroll | B8: exclude

Sheet SUMMARY
A1: Member ID | B1: Full Name | C1: Gender | D1: Birthdate | E1: Contact No. | F1: Baranggay | G1: Complete Address | H1: Source of Income | I1: Date Joined | J1: Membership Status | K1: Collector Assigned | L1: Cycle | M1: Loan Amount
A2: AG00001 | B2: Jeniffer C. Navarro | C2: Female | D2: 32573 | E2: 9610328020 | F2: Alinguigan 3rd | G2: Alinguigan 3rd, City of Ilagan | H2: Salary/Furniture | I2: 45919 | J2: Active | K2: Ralph L. Lopez | L2: =VLOOKUP(A2,Sheet1!G:I,3,0) -> 1 | M2: ₱30,000.00
A3: AG00002 | B3: Rhealyn R. Malana | C3: Female | D3: 34496 | E3: 9752063588 | F3: Alinguigan 3rd | G3: Alinguigan 3rd, City of Ilagan | H3: Vendor | I3: 45924 | J3: Active | K3: Ralph L. Lopez | L3: =VLOOKUP(A3,Sheet1!G:I,3,0) -> 1 | M3: ₱10,000.00
A4: AG00003 | B4: Mary Ann A. Roqued | C4: Female | D4: 34380 | E4: 9671799266 | F4: Palacian | G4: Purok 5, Brgy. Palacian, San Agustin, Isabela | H4: Mini Talipapa/Rolling Vendor | I4: 45934 | J4: Active | K4: Jason Ian R. Contawe | L4: =VLOOKUP(A4,Sheet1!G:I,3,0) -> 1 | M4: ₱30,000.00
A5: AG00004 | B5: Jovilyn D. Patacsil | C5: Female | D5: 27381 | E5: 9531406143 | F5: Palacian | G5: Purok 7, Brgy. Palacian, San Agustin, Isabela | H5: Store/Banana | I5: 45934 | J5: Active | K5: Ralph L. Lopez | L5: =VLOOKUP(A5,Sheet1!G:I,3,0) -> 2 | M5: ₱30,000.00
A6: AG00005 | B6: Teresa Agustin | C6: Female | D6: 29923 | E6: 9979859147 | F6: Palacian | G6: Purok 7, Brgy. Palacian, San Agustin, Isabela | H6: Sari Sari Store | I6: 45934 | J6: Inactive | K6: Ralph L. Lopez | L6: =VLOOKUP(A6,Sheet1!G:I,3,0) -> 1 | M6: ₱30,000.00
A7: AG00006 | B7: Juliet Agpalza | C7: Female | D7: 29741 | E7: 9268959314 | F7: Palacian | G7: Purok 6, Brgy. Palacian, San Agustin, Isabela | H7: Piggery | I7: 45934 | J7: Active | K7: Ralph L. Lopez | L7: =VLOOKUP(A7,Sheet1!G:I,3,0) -> 2 | M7: ₱12,000.00
A8: AG00007 | B8: Juvy C. Acoba | C8: Female | D8: 23805 | E8: 9263425321 | F8: Palacian | G8: Purok 5, Brgy. Palacian, San Agustin, Isabela | H8: Sari Sari Store | I8: 45934 | J8: Active | K8: Ralph L. Lopez | L8: =VLOOKUP(A8,Sheet1!G:I,3,0) -> 3 | M8: ₱20,000.00
A9: AG00008 | B9: Arlene Mae T. Batarao | C9: Female | D9: 32997 | E9: 9365351339 | F9: Palacian | G9: Purok 5, Brgy. Palacian, San Agustin, Isabela | H9: Farming | I9: 45934 | J9: Active | K9: Ralph L. Lopez | L9: =VLOOKUP(A9,Sheet1!G:I,3,0) -> 2 | M9: ₱8,000.00
A10: AG00009 | B10: Babylyn M. Manuel | C10: Female | D10: 26433 | E10: 9758964284 | F10: Palacian | G10: Purok 4, Brgy. Palacian, San Agustin, Isabela | H10: Administrative Clerk | I10: 45941 | J10: Active | K10: Ralph L. Lopez | L10: =VLOOKUP(A10,Sheet1!G:I,3,0) -> 2 | M10: ₱15,000.00
A11: AG00010 | B11: Novelyn U. Garrote | C11: Female | D11: 27726 | E11: 9352707530 | F11: Palacian | G11: Purok 6, Brgy. Palacian, San Agustin, Isabela | H11: Farming | I11: 45941 | J11: Active | K11: Ralph L. Lopez | L11: =VLOOKUP(A11,Sheet1!G:I,3,0) -> 2 | M11: ₱15,000.00
A12: AG00011 | B12: Florita L. Dadiz | C12: Female | D12: 25610 | E12: 9369393039 | F12: Palacian | G12: Purok 6, Brgy. Palacian, San Agustin, Isabela | H12: Farming | I12: 45941 | J12: Active | K12: Ralph L. Lopez | L12: =VLOOKUP(A12,Sheet1!G:I,3,0) -> 2 | M12: ₱35,000.00
A13: AG00012 | B13: Rebylen R. Tumaneng | C13: Female | D13: 24863 | E13: 9365351339 | F13: Palacian | G13: Purok 5, Brgy. Palacian, San Agustin, Isabela | H13: Farming | I13: 45941 | J13: Active | K13: Jason Ian R. Contawe | L13: =VLOOKUP(A13,Sheet1!G:I,3,0) -> 1 | M13: ₱6,000.00
... A28: AG00027 | B28: Leonora G. Bugarin | C28: Female | D28: 23170 | E28: 9532997796 | F28: Masaya Centro | G28: Masaya Centro, San Agustin, Isabela | H28: Online Seller | I28: 45969 | J28: Active | K28: Jan Mark T. Pascual | L28: =VLOOKUP(A28,Sheet1!G:I,3,0) -> 2 | M28: ₱15,000.00
A29: AG00028 | B29: Noralyn Pascual | C29: Female | D29: 26798 | E29: 9672741699 | F29: Palacian | G29: Purok 4, Brgy. Palacian, San Agustin, Isabela | I29: 45969 | J29: Active | K29: Ralph L. Lopez | L29: =VLOOKUP(A29,Sheet1!G:I,3,0) -> 2 | M29: ₱25,000.00
A30: AG00029 | B30: Emylou P. Zuniega | C30: Female | D30: 32039 | E30: 9058075130 | F30: Salay | G30: Salay, San Agustin, Isabela | H30: Government Employee | I30: 45969 | J30: Active | K30: Jan Mark T. Pascual | L30: =VLOOKUP(A30,Sheet1!G:I,3,0) -> 2 | M30: ₱30,000.00
A31: AG00030 | B31: Vilma S. Lumot | C31: Female | D31: 25327 | E31: 9679554166 | F31: Palacian | G31: Purok 4, Brgy. Palacian, San Agustin, Isabela | H31: Sari Sari Store | I31: 45969 | J31: Active | K31: Ralph L. Lopez | L31: =VLOOKUP(A31,Sheet1!G:I,3,0) -> 2 | M31: ₱20,000.00
A32: AG00031 | B32: Angelita Pacag | C32: Female | D32: 27505 | E32: 9551231524 | F32: Masaya Sur | G32: Purok 6, Brgy. Masaya Sur, San Agustin, Isabela | H32: Vendor | I32: 45969 | J32: Active | K32: Jan Mark T. Pascual | L32: =VLOOKUP(A32,Sheet1!G:I,3,0) -> 2 | M32: ₱30,000.00
A33: AG00032 | B33: Alvie A. Pascual | C33: Female | D33: 35874 | E33: 9750668212 | F33: Santos | G33: Santos, San Agustin, Isabela | H33: Office Staff | I33: 45969 | J33: Inactive | K33: Ralph L. Lopez | L33: =VLOOKUP(A33,Sheet1!G:I,3,0) -> 1 | M33: ₱20,000.00
A34: AG00033 | B34: Renz Marion Q. Navarro | C34: Male | F34: Alinguigan 3rd | G34: Alinguigan 3rd, City of Ilagan | I34: 45969 | J34: Active | K34: Ralph L. Lopez | L34: =VLOOKUP(A34,Sheet1!G:I,3,0) -> 1 | M34: ₱20,000.00
A35: AG00034 | B35: Marie Fe Melad | C35: Female | F35: Ilagan | I35: 45975 | J35: Active | K35: Ralph L. Lopez | L35: =VLOOKUP(A35,Sheet1!G:I,3,0) -> 1 | M35: ₱20,000.00
A36: AG00035 | B36: Alma Jane Awayang | C36: Female | D36: 30441 | F36: San Dionisio | G36: San Dionisio 1, Maddela Quirino | H36: Hog Raiser | I36: 45975 | J36: Active | K36: Jason Ian R. Contawe | L36: =VLOOKUP(A36,Sheet1!G:I,3,0) -> 2 | M36: ₱22,000.00
A37: AG00036 | B37: Flordeliza Awayang | C37: Female | D37: 23893 | E37: 9068682290 | F37: San Dionisio | G37: San Dionisio 1, Maddela Quirino | H37: Sari Sari Store | I37: 45975 | J37: Active | K37: Jason Ian R. Contawe | L37: =VLOOKUP(A37,Sheet1!G:I,3,0) -> 2 | M37: ₱25,000.00
A38: AG00037 | B38: Rosemarie Andres | C38: Female | D38: 29797 | E38: 9068678369 | F38: San Dionisio | G38: San Dionisio 1, Maddela Quirino | H38: Sari Sari Store | I38: 45975 | J38: Active | K38: Jan Mark T. Pascual | L38: =VLOOKUP(A38,Sheet1!G:I,3,0) -> 2 | M38: ₱30,000.00
A39: AG00038 | B39: Gracielyn Pineda | C39: Female | D39: 28482 | F39: San Dionisio | G39: San Dionisio 1, Maddela Quirino | H39: Hog Raiser | I39: 45975 | J39: Active | K39: Jan Mark T. Pascual | L39: =VLOOKUP(A39,Sheet1!G:I,3,0) -> 1 | M39: ₱20,000.00
A40: AG00039 | B40: Jhona Flores | C40: Female | D40: 30931 | F40: San Dionisio | G40: San Dionisio 1, Maddela Quirino | H40: Hog Raiser/Ukay Ukay | I40: 45982 | J40: Active | K40: Jan Mark T. Pascual | L40: =VLOOKUP(A40,Sheet1!G:I,3,0) -> 2 | M40: ₱25,000.00
A41: AG00040 | B41: Mary Jane Flores | C41: Female | D41: 28954 | F41: San Dionisio | G41: San Dionisio 1, Maddela Quirino | H41: Hog Raiser/Ukay Ukay/Hallow Blocks | I41: 45982 | J41: Active | K41: Jan Mark T. Pascual | L41: =VLOOKUP(A41,Sheet1!G:I,3,0) -> 2 | M41: ₱25,000.00
A42: AG00041 | B42: JANETH ANDRES | C42: Female | D42: 29219 | F42: San Dionisio | G42: San Dionisio 1, Maddela Quirino | H42: Hog Raiser | I42: 45982 | J42: Active | K42: Jason Ian R. Contawe | L42: =VLOOKUP(A42,Sheet1!G:I,3,0) -> 2 | M42: ₱20,000.00
A43: AG00042 | B43: RONALYN A. FLORES | C43: Female | D43: 31467 | F43: San Dionisio | G43: San Dionisio 1, Maddela Quirino | H43: Laborer/Hog Raiser | I43: 45982 | J43: Active | K43: Jan Mark T. Pascual | L43: =VLOOKUP(A43,Sheet1!G:I,3,0) -> 2 | M43: ₱35,000.00
A44: AG00043 | B44: JULIETA C. FLORES | C44: Female | D44: 25038 | F44: San Dionisio | G44: San Dionisio 1, Maddela Quirino | H44: Food Processing/Walking Vendor | I44: 45982 | J44: Active | K44: Jan Mark T. Pascual | L44: =VLOOKUP(A44,Sheet1!G:I,3,0) -> 2 | M44: ₱30,000.00
A45: AG00044 | B45: CHERRY ANN D. FLORES | C45: Female | D45: 31305 | E45: 9603879549 | F45: San Dionisio | G45: San Dionisio 1, Maddela Quirino | H45: Hog Raiser/Laborer | I45: 45982 | J45: Active | K45: Jason Ian R. Contawe | L45: =VLOOKUP(A45,Sheet1!G:I,3,0) -> 2 | M45: ₱20,000.00
A46: AG00045 | B46: GINA V. DELA CRUZ | C46: Female | D46: 28856 | F46: San Dionisio | G46: San Dionisio 1, Maddela Quirino | H46: Hog Raiser | I46: 45982 | J46: Active | K46: Jason Ian R. Contawe | L46: =VLOOKUP(A46,Sheet1!G:I,3,0) -> 2 | M46: ₱20,000.00
A47: AG00046 | B47: CARMENCITA A. MALAB | C47: Female | D47: 22103 | E47: 9525633134 | F47: Palacian | G47: Purok 4, Palacian, San Agustin, Isabela | H47: Pastor | I47: 45982 | J47: Active | K47: Ralph L. Lopez | L47: =VLOOKUP(A47,Sheet1!G:I,3,0) -> 1 | M47: ₱20,000.00
A48: AG00047 | B48: JONALYN S. PINEDA | C48: Female | D48: 29063 | F48: San Dionisio | G48: San Dionisio 1, Maddela Quirino | I48: 45982 | J48: Active | K48: Jan Mark T. Pascual | L48: =VLOOKUP(A48,Sheet1!G:I,3,0) -> 2 | M48: ₱20,000.00
A49: AG00048 | B49: ARDIE P. PAJARA | C49: Female | D49: 36492 | E49: 9064589475 | F49: Salay | G49: Salay, San Agustin, Isabela | H49: Delivery Rider | I49: 45982 | J49: Active | K49: Jan Mark T. Pascual | L49: =VLOOKUP(A49,Sheet1!G:I,3,0) -> 2 | M49: ₱20,000.00
A50: AG00049 | B50: MARILYN S. DOMINGO | C50: Female | D50: 23867 | F50: San Dionisio | G50: San Dionisio 1, Maddela Quirino | I50: 45992 | J50: Active | K50: Jason Ian R. Contawe | L50: =VLOOKUP(A50,Sheet1!G:I,3,0) -> 2 | M50: ₱20,000.00
A51: AG00050 | B51: HANNY HAIZEL ALDA | C51: Female | D51: 34129 | F51: San Dionisio | G51: San Dionisio 1, Maddela Quirino | I51: 45992 | J51: Active | K51: Jan Mark T. Pascual | L51: =VLOOKUP(A51,Sheet1!G:I,3,0) -> 1 | M51: ₱25,000.00
A52: AG00051 | B52: BEATE APRIL U. GARROTE | C52: Female | D52: 35521 | E52: 9757684032 | F52: Palacian | G52: Purok 6, Palacian, San Agustin, Isabela | H52: Caregiver | I52: 45992 | J52: Active | K52: Jason Ian R. Contawe | L52: =VLOOKUP(A52,Sheet1!G:I,3,0) -> 1 | M52: ₱15,000.00
A53: AG00052 | B53: ANALYN BULLOS | C53: Female | D53: 28128 | E53: 9673052815 | F53: Masaya Centro | G53: Purok 3, Masaya Centro, San Agustin, Isabela | H53: Direct Seller | I53: 45992 | J53: Active | K53: Jason Ian R. Contawe | L53: =VLOOKUP(A53,Sheet1!G:I,3,0) -> 1 | M53: ₱15,000.00
A54: AG00053 | B54: MONICA L. ESTIFANIO | C54: Female | D54: 34315 | E54: 9756142964 | F54: Masaya Centro | G54: Purok 3, Masaya Centro, San Agustin, Isabela | H54: Online Business | I54: 45992 | J54: Active | K54: Jason Ian R. Contawe | L54: =VLOOKUP(A54,Sheet1!G:I,3,0) -> 1 | M54: ₱15,000.00
...

Sheet Sheet1
A1: AG00001 | B1: Jeniffer C. Navarro | D1: =VLOOKUP(A1,SUMMARY!A:I,9,0) -> 45919 | G1: Member ID | H1: Member Name | I1: Cycle ID | J1: Collector | K1: Barangay | L1: Loan Code | M1: Loan Amount
A2: AG00002 | B2: Rhealyn R. Malana | D2: =VLOOKUP(A2,SUMMARY!A:I,9,0) -> 45924 | G2: AG00001 | H2: Jeniffer C. Navarro | I2: 1 | J2: Collector 1 | K2: Alinguigan 3rd | L2: LC30K | M2: ₱30,000.00
A3: AG00003 | B3: Mary Ann A. Roqued | D3: =VLOOKUP(A3,SUMMARY!A:I,9,0) -> 45934 | G3: AG00002 | H3: Rhealyn R. Malana | I3: 1 | J3: Collector 1 | K3: Alinguigan 3rd | L3: LC10K | M3: ₱10,000.00
A4: AG00004 | B4: Jovilyn D. Patacsil | D4: =VLOOKUP(A4,SUMMARY!A:I,9,0) -> 45934 | G4: AG00003 | H4: Mary Ann A. Roqued | I4: 1 | J4: Collector 1 | K4: Palacian | L4: LC30K | M4: ₱30,000.00
A5: AG00005 | B5: Teresa Agustin | D5: =VLOOKUP(A5,SUMMARY!A:I,9,0) -> 45934 | G5: AG00004 | H5: Jovilyn D. Patacsil | I5: 2 | J5: Collector 1 | K5: Palacian | L5: LC30K | M5: ₱30,000.00
A6: AG00006 | B6: Juliet Agpalza | D6: =VLOOKUP(A6,SUMMARY!A:I,9,0) -> 45934 | G6: AG00005 | H6: Teresa Agustin | I6: 1 | J6: Collector 1 | K6: Palacian | L6: LC30K | M6: ₱30,000.00
A7: AG00007 | B7: Juvy C. Acoba | D7: =VLOOKUP(A7,SUMMARY!A:I,9,0) -> 45934 | G7: AG00006 | H7: Juliet Agpalza | I7: 2 | J7: Collector 1 | K7: Palacian | L7: LC12K | M7: ₱12,000.00
A8: AG00008 | B8: Arlene Mae T. Batarao | D8: =VLOOKUP(A8,SUMMARY!A:I,9,0) -> 45934 | G8: AG00007 | H8: Juvy C. Acoba | I8: 3 | J8: Collector 1 | K8: Palacian | L8: LC20K | M8: ₱20,000.00
A9: AG00009 | B9: Babylyn M. Manuel | D9: =VLOOKUP(A9,SUMMARY!A:I,9,0) -> 45941 | G9: AG00008 | H9: Arlene Mae T. Batarao | I9: 2 | J9: Collector 1 | K9: Palacian | L9: LC08K | M9: ₱8,000.00
A10: AG00010 | B10: Novelyn U. Garrote | D10: =VLOOKUP(A10,SUMMARY!A:I,9,0) -> 45941 | G10: AG00009 | H10: Babylyn M. Manuel | I10: 2 | J10: Collector 1 | K10: Palacian | L10: LC15K | M10: ₱15,000.00
A11: AG00011 | B11: Florita L. Dadiz | D11: =VLOOKUP(A11,SUMMARY!A:I,9,0) -> 45941 | G11: AG00010 | H11: Novelyn U. Garrote | I11: 2 | J11: Collector 1 | K11: Palacian | L11: LC15K | M11: ₱15,000.00
A12: AG00012 | B12: Rebylen R. Tumaneng | D12: =VLOOKUP(A12,SUMMARY!A:I,9,0) -> 45941 | G12: AG00011 | H12: Florita L. Dadiz | I12: 2 | J12: Collector 1 | K12: Palacian | L12: LC35K | M12: ₱35,000.00
A13: AG00013 | B13: Grace A. Agcaoili | D13: =VLOOKUP(A13,SUMMARY!A:I,9,0) -> 45941 | G13: AG00012 | H13: Rebylen R. Tumaneng | I13: 1 | J13: Collector 1 | K13: Palacian | L13: LC06K | M13: ₱6,000.00
... A151: AG00151 | B151: Kristele Mae P. Alili | D151: =VLOOKUP(A151,SUMMARY!A:I,9,0) -> 46035 | G151: AG00150 | H151: Anna Rose Fampo | I151: 1 | J151: Collector 1 | K151: Palacian | L151: LC15K | M151: ₱15,000.00
G152: AG00151 | H152: Kristele Mae P. Alili | I152: 1 | J152: Collector 1 | K152: Palacian | L152: LC15K | M152: ₱15,000.00
A153: AG00018 | B153: Julie A. Agcaoili | D153: =VLOOKUP(A153,SUMMARY!A:I,9,0) -> 45941
A154: AG00152 | B154: Adona Marie A. Esteban | D154: =VLOOKUP(A154,SUMMARY!A:I,9,0) -> 46043
A155: AG00153 | B155: Jemilyn Miguel Jereza | D155: =VLOOKUP(A155,SUMMARY!A:I,9,0) -> 46043 | G155: AG00152 | H155: Adona Marie A. Esteban | I155: 1 | J155: Collector 1 | K155: Masaya Sur | L155: LC07K | M155: ₱7,000.00
A156: AG00154 | B156: Reybie D. Tinaza | D156: =VLOOKUP(A156,SUMMARY!A:I,9,0) -> 46043 | G156: AG00153 | H156: Jemilyn Miguel Jereza | I156: 1 | J156: Collector 1 | K156: Masaya Sur | L156: LC07K | M156: ₱7,000.00
A157: AG00155 | B157: Diolylla M. Garcia | D157: =VLOOKUP(A157,SUMMARY!A:I,9,0) -> 46043 | G157: AG00154 | H157: Reybie D. Tinaza | I157: 1 | J157: Collector 1 | K157: Masaya Sur | L157: LC07K | M157: ₱7,000.00
A158: AG00156 | B158: Mark Lester R. Asuncion | D158: =VLOOKUP(A158,SUMMARY!A:I,9,0) -> 46043 | G158: AG00155 | H158: Diolylla M. Garcia | I158: 1 | J158: Collector 1 | K158: Palacian | L158: LC10K | M158: ₱10,000.00
A159: AG00157 | B159: Larie Jade T. Andres | D159: =VLOOKUP(A159,SUMMARY!A:I,9,0) -> 46043 | G159: AG00156 | H159: Mark Lester R. Asuncion | I159: 1 | J159: Collector 1 | K159: Palacian | L159: LC10K | M159: ₱10,000.00
A160: AG00158 | B160: Relegin A. Libunao | D160: =VLOOKUP(A160,SUMMARY!A:I,9,0) -> 46043 | G160: AG00157 | H160: Larie Jade T. Andres | I160: 1 | J160: Collector 1 | K160: San Dionisio | L160: LC15K | M160: ₱15,000.00
A161: AG00159 | B161: Hanielyn Badua | D161: =VLOOKUP(A161,SUMMARY!A:I,9,0) -> 46043 | G161: AG00158 | H161: Relegin A. Libunao | I161: 2 | J161: Collector 1 | K161: San Dionisio | L161: LC20K | M161: ₱20,000.00
A162: AG00160 | B162: Grace R. Daguro | D162: =VLOOKUP(A162,SUMMARY!A:I,9,0) -> 46043 | G162: AG00159 | H162: Hanielyn Badua | I162: 1 | J162: Collector 1 | K162: San Dionisio | L162: LC15K | M162: ₱15,000.00
A163: AG00161 | B163: Kenneth James C. Alejo | D163: =VLOOKUP(A163,SUMMARY!A:I,9,0) -> 46043 | G163: AG00160 | H163: Grace R. Daguro | I163: 1 | J163: Collector 1 | K163: Dabubu Grande | L163: LC18K | M163: ₱18,000.00
A164: AG00162 | B164: Christopher F. Rayos | D164: =VLOOKUP(A164,SUMMARY!A:I,9,0) -> 46043 | G164: AG00161 | H164: Kenneth James C. Alejo | I164: 2 | J164: Collector 1 | K164: Sinaoangan Norte | L164: LC12K | M164: ₱12,000.00
A165: AG00163 | B165: Dorothy D. Domingo | D165: =VLOOKUP(A165,SUMMARY!A:I,9,0) -> 46043 | G165: AG00162 | H165: Christopher F. Rayos | I165: 2 | J165: Collector 1 | K165: Echague | L165: LC35K | M165: ₱35,000.00
A166: AG00164 | B166: Rocky Pascual | D166: =VLOOKUP(A166,SUMMARY!A:I,9,0) -> 46049 | G166: AG00163 | H166: Dorothy D. Domingo | I166: 1 | J166: Collector 1 | K166: San Dionisio | L166: LC18K | M166: ₱18,000.00
... A199: AG00197 | B199: Helen Joy P. Bulusan | D199: =VLOOKUP(A199,SUMMARY!A:I,9,0) -> 46057 | G199: AG00196 | H199: Jennifer Malab | I199: 2 | J199: Collector 1 | K199: Palacian | L199: LC18K | M199: ₱18,000.00
G200: AG00197 | H200: Helen Joy P. Bulusan | I200: 1 | J200: Collector 1 | K200: Masaya Sur | L200: LC15K | M200: ₱15,000.00
A201: AG00198 | B201: Margie P. Juan | D201: =VLOOKUP(A201,SUMMARY!A:I,9,0) -> 46064
A202: AG00199 | B202: Mary Jane D. Baluna | D202: =VLOOKUP(A202,SUMMARY!A:I,9,0) -> 46064 | G202: AG00198 | H202: Margie P. Juan | I202: 2 | J202: Collector 1 | K202: Bautista | L202: LC25K | M202: ₱25,000.00
A203: AG00200 | B203: Hanz A. Payadon | D203: =VLOOKUP(A203,SUMMARY!A:I,9,0) -> 46064 | G203: AG00199 | H203: Mary Jane D. Baluna | I203: 1 | J203: Collector 1 | K203: Bautista | L203: LC10K | M203: ₱10,000.00
A204: AG00201 | B204: Gloria D. Abe | D204: =VLOOKUP(A204,SUMMARY!A:I,9,0) -> 46064 | G204: AG00200 | H204: Hanz A. Payadon | I204: 1 | J204: Collector 1 | K204: Bautista | L204: LC10K | M204: ₱10,000.00
A205: AG00202 | B205: Marilou E. Biagan | D205: =VLOOKUP(A205,SUMMARY!A:I,9,0) -> 46064 | G205: AG00201 | H205: Gloria D. Abe | I205: 1 | J205: Collector 1 | K205: Masaya Sur | L205: LC10K | M205: ₱10,000.00
A206: AG00203 | B206: Eddie M. Gallardo | D206: =VLOOKUP(A206,SUMMARY!A:I,9,0) -> 46064 | G206: AG00202 | H206: Marilou E. Biagan | I206: 2 | J206: Collector 1 | K206: Quimalabasa Sur | L206: LC20K | M206: ₱20,000.00
A207: AG00204 | B207: Fredelita R. Magaoay | D207: =VLOOKUP(A207,SUMMARY!A:I,9,0) -> 46064 | G207: AG00203 | H207: Eddie M. Gallardo | I207: 1 | J207: Collector 1 | K207: Quimalabasa Sur | L207: LC08K | M207: ₱8,000.00
A208: AG00205 | B208: Joy A. Manuel | D208: =VLOOKUP(A208,SUMMARY!A:I,9,0) -> 46064 | G208: AG00204 | H208: Fredelita R. Magaoay | I208: 1 | J208: Collector 1 | K208: Quimalabasa Sur | L208: LC07K | M208: ₱7,000.00
A209: AG00206 | B209: Myrna Aguinaldo | D209: =VLOOKUP(A209,SUMMARY!A:I,9,0) -> 46064 | G209: AG00205 | H209: Joy A. Manuel | I209: 1 | J209: Collector 1 | K209: Quimalabasa Sur | L209: LC05K | M209: ₱5,000.00
...
